Workbook

Sheet Diario
A1: Línea 22 Megatron · consumo de energía activa diario (kWh)
A2: Fuente: Informe de eficiencia energética, W. Paniquita, julio 2026, págs. 40-48 (gráficos Ixon).
A4: Fecha | B4: Día | C4: Mes | D4: Semana del informe | E4: kWh | F4: Calidad del dato | G4: Incluir en análisis | H4: Nota
A5: 46048 | B5: lunes | C5: =MONTH(A5) | D5: Ene S4 | E5: 72.09 | F5: leído | G5: Sí
A6: 46049 | B6: martes | C6: =MONTH(A6) | D6: Ene S4 | E6: 106.38 | F6: leído | G6: Sí
A7: 46050 | B7: miércoles | C7: =MONTH(A7) | D7: Ene S4 | E7: 108.457 | F7: leído | G7: Sí
A8: 46051 | B8: jueves | C8: =MONTH(A8) | D8: Ene S4 | E8: 105.679 | F8: leído | G8: Sí
A9: 46052 | B9: viernes | C9: =MONTH(A9) | D9: Ene S4 | E9: 74.386 | F9: leído | G9: Sí
A10: 46053 | B10: sábado | C10: =MONTH(A10) | D10: Ene S4 | E10: 27.264 | F10: leído | G10: Sí
A11: 46055 | B11: lunes | C11: =MONTH(A11) | D11: Feb S1 | E11: 111.162 | F11: leído | G11: Sí
A12: 46056 | B12: martes | C12: =MONTH(A12) | D12: Feb S1 | E12: 115.302 | F12: leído | G12: Sí
A13: 46057 | B13: miércoles | C13: =MONTH(A13) | D13: Feb S1 | E13: 101.299 | F13: leído | G13: Sí
A14: 46058 | B14: jueves | C14: =MONTH(A14) | D14: Feb S1 | E14: 113.098 | F14: leído | G14: Sí
A15: 46059 | B15: viernes | C15: =MONTH(A15) | D15: Feb S1 | E15: 113.937 | F15: leído | G15: Sí
A16: 46060 | B16: sábado | C16: =MONTH(A16) | D16: Feb S1 | E16: 731.716 | F16: atípico | G16: No | H16: Valor 6,5 veces mayor que lo normal; probable error del medidor o acumulado de varios días. Excluido.
A17: 46062 | B17: lunes | C17: =MONTH(A17) | D17: Feb S2 | E17: 75.192 | F17: leído | G17: Sí
A18: 46063 | B18: martes | C18: =MONTH(A18) | D18: Feb S2 | E18: 82.366 | F18: leído | G18: Sí
A19: 46064 | B19: miércoles | C19: =MONTH(A19) | D19: Feb S2 | E19: 84.545 | F19: leído | G19: Sí
A20: 46065 | B20: jueves | C20: =MONTH(A20) | D20: Feb S2 | E20: 77.089 | F20: leído | G20: Sí
A21: 46066 | B21: viernes | C21: =MONTH(A21) | D21: Feb S2 | E21: 72.666 | F21: leído | G21: Sí
A22: 46067 | B22: sábado | C22: =MONTH(A22) | D22: Feb S2 | E22: 49.787 | F22: leído | G22: Sí
A23: 46069 | B23: lunes | C23: =MONTH(A23) | D23: Feb S3 | E23: 102.391 | F23: leído | G23: Sí
A24: 46070 | B24: martes | C24: =MONTH(A24) | D24: Feb S3 | E24: 117.13 | F24: leído | G24: Sí
A25: 46071 | B25: miércoles | C25: =MONTH(A25) | D25: Feb S3 | E25: 119.866 | F25: leído | G25: Sí
A26: 46072 | B26: jueves | C26: =MONTH(A26) | D26: Feb S3 | E26: 81.335 | F26: leído | G26: Sí
A27: 46073 | B27: viernes | C27: =MONTH(A27) | D27: Feb S3 | E27: 109.95 | F27: leído | G27: Sí
A28: 46074 | B28: sábado | C28: =MONTH(A28) | D28: Feb S3 | E28: 89.113 | F28: leído | G28: Sí
... A58: 46113 | B58: miércoles | C58: =MONTH(A58) | D58: Abr S1 | E58: 112.608 | F58: leído | G58: Sí
A59: 46114 | B59: jueves | C59: =MONTH(A59) | D59: Abr S1 | E59: 0 | F59: cero | G59: No | H59: Jueves y Viernes Santo (festivos). Línea sin consumo. Excluido del promedio.
A60: 46115 | B60: viernes | C60: =MONTH(A60) | D60: Abr S1 | E60: 0 | F60: cero | G60: No | H60: Jueves y Viernes Santo (festivos). Línea sin consumo. Excluido del promedio.
A61: 46116 | B61: sábado | C61: =MONTH(A61) | D61: Abr S1 | E61: 102.321 | F61: leído | G61: Sí
A62: 46118 | B62: lunes | C62: =MONTH(A62) | D62: Abr S2 | E62: 69.107 | F62: leído | G62: Sí
A63: 46119 | B63: martes | C63: =MONTH(A63) | D63: Abr S2 | E63: 78.193 | F63: leído | G63: Sí
A64: 46120 | B64: miércoles | C64: =MONTH(A64) | D64: Abr S2 | E64: 88.541 | F64: leído | G64: Sí
A65: 46121 | B65: jueves | C65: =MONTH(A65) | D65: Abr S2 | E65: 85.529 | F65: leído | G65: Sí
A66: 46122 | B66: viernes | C66: =MONTH(A66) | D66: Abr S2 | E66: 73.75 | F66: leído | G66: Sí
A67: 46123 | B67: sábado | C67: =MONTH(A67) | D67: Abr S2 | E67: 73.471 | F67: leído | G67: Sí
A68: 46125 | B68: lunes | C68: =MONTH(A68) | D68: Abr S3 | E68: 107.514 | F68: leído | G68: Sí
A69: 46126 | B69: martes | C69: =MONTH(A69) | D69: Abr S3 | E69: 50.84 | F69: leído | G69: Sí
A70: 46127 | B70: miércoles | C70: =MONTH(A70) | D70: Abr S3 | E70: 52.928 | F70: leído | G70: Sí
...

Sheet Resumen
A1: Resumen de consumo · Línea 22
A2: Calculado solo con días marcados 'Sí' en la hoja Diario (excluye atípico, festivos en cero y día parcial).
A4: Indicador | B4: Valor | C4: Unidad
A5: Días con dato válido | B5: =COUNTIFS(Diario!$G$5:$G$100,"Sí") | C5: días
A6: Consumo total medido (días válidos) | B6: =SUMIFS(Diario!$E$5:$E$100,Diario!$G$5:$G$100,"Sí") | C6: kWh
A7: Consumo promedio diario | B7: =IFERROR(B6/B5,0) | C7: kWh/día
A8: Promedio lunes a viernes | B8: =IFERROR(AVERAGEIFS(Diario!$E$5:$E$100,Diario!$G$5:$G$100,"Sí",Diario!$B$5:$B$100,"<>sábado"),0) | C8: kWh/día
A9: Promedio sábados | B9: =IFERROR(AVERAGEIFS(Diario!$E$5:$E$100,Diario!$G$5:$G$100,"Sí",Diario!$B$5:$B$100,"sábado"),0) | C9: kWh/día
A10: Consumo semanal típico (5 × L-V + sábado) | B10: =B8*5+B9 | C10: kWh/semana
A11: Consumo mensual estimado (×52/12) | B11: =B10*52/12 | C11: kWh/mes
A12: Consumo anual estimado | B12: =B10*52 | C12: kWh/año
A13: Participación del aire comprimido (dato del informe, planta) | B13: 0.2382 | C13: % | D13: El informe da 23,82% para el conjunto de líneas; no reporta el aire de la L22 por separado.
A14: Consumo anual estimado incluyendo aire comprimido | B14: =IFERROR(B12/(1-B13),0) | C14: kWh/año
A17: Mes | B17: Días válidos | C17: kWh | D17: Promedio kWh/día
A18: Enero (solo S4) | B18: =COUNTIFS(Diario!$C$5:$C$100,1,Diario!$G$5:$G$100,"Sí") | C18: =SUMIFS(Diario!$E$5:$E$100,Diario!$C$5:$C$100,1,Diario!$G$5:$G$100,"Sí") | D18: =IFERROR(C18/B18,0)
A19: Febrero | B19: =COUNTIFS(Diario!$C$5:$C$100,2,Diario!$G$5:$G$100,"Sí") | C19: =SUMIFS(Diario!$E$5:$E$100,Diario!$C$5:$C$100,2,Diario!$G$5:$G$100,"Sí") | D19: =IFERROR(C19/B19,0)
A20: Marzo | B20: =COUNTIFS(Diario!$C$5:$C$100,3,Diario!$G$5:$G$100,"Sí") | C20: =SUMIFS(Diario!$E$5:$E$100,Diario!$C$5:$C$100,3,Diario!$G$5:$G$100,"Sí") | D20: =IFERROR(C20/B20,0)
A21: Abril | B21: =COUNTIFS(Diario!$C$5:$C$100,4,Diario!$G$5:$G$100,"Sí") | C21: =SUMIFS(Diario!$E$5:$E$100,Diario!$C$5:$C$100,4,Diario!$G$5:$G$100,"Sí") | D21: =IFERROR(C21/B21,0)
A22: Mayo (sin S1) | B22: =COUNTIFS(Diario!$C$5:$C$100,5,Diario!$G$5:$G$100,"Sí") | C22: =SUMIFS(Diario!$E$5:$E$100,Diario!$C$5:$C$100,5,Diario!$G$5:$G$100,"Sí") | D22: =IFERROR(C22/B22,0)
A23: Junio (solo S1) | B23: =COUNTIFS(Diario!$C$5:$C$100,6,Diario!$G$5:$G$100,"Sí") | C23: =SUMIFS(Diario!$E$5:$E$100,Diario!$C$5:$C$100,6,Diario!$G$5:$G$100,"Sí") | D23: =IFERROR(C23/B23,0)
A24: Total | B24: =SUM(B18:B23) | C24: =SUM(C18:C23) | D24: =IFERROR(C24/B24,0)
A27: Semana | B27: Días válidos | C27: kWh | D27: Promedio kWh/día
A28: Ene S4 | B28: =COUNTIFS(Diario!$D$5:$D$100,A28,Diario!$G$5:$G$100,"Sí") | C28: =SUMIFS(Diario!$E$5:$E$100,Diario!$D$5:$D$100,A28,Diario!$G$5:$G$100,"Sí") | D28: =IFERROR(C28/B28,0)
A29: Feb S1 | B29: =COUNTIFS(Diario!$D$5:$D$100,A29,Diario!$G$5:$G$100,"Sí") | C29: =SUMIFS(Diario!$E$5:$E$100,Diario!$D$5:$D$100,A29,Diario!$G$5:$G$100,"Sí") | D29: =IFERROR(C29/B29,0)
A30: Feb S2 | B30: =COUNTIFS(Diario!$D$5:$D$100,A30,Diario!$G$5:$G$100,"Sí") | C30: =SUMIFS(Diario!$E$5:$E$100,Diario!$D$5:$D$100,A30,Diario!$G$5:$G$100,"Sí") | D30: =IFERROR(C30/B30,0)
A31: Feb S3 | B31: =COUNTIFS(Diario!$D$5:$D$100,A31,Diario!$G$5:$G$100,"Sí") | C31: =SUMIFS(Diario!$E$5:$E$100,Diario!$D$5:$D$100,A31,Diario!$G$5:$G$100,"Sí") | D31: =IFERROR(C31/B31,0)
A32: Feb S4 | B32: =COUNTIFS(Diario!$D$5:$D$100,A32,Diario!$G$5:$G$100,"Sí") | C32: =SUMIFS(Diario!$E$5:$E$100,Diario!$D$5:$D$100,A32,Diario!$G$5:$G$100,"Sí") | D32: =IFERROR(C32/B32,0)
A33: Mar S1 | B33: =COUNTIFS(Diario!$D$5:$D$100,A33,Diario!$G$5:$G$100,"Sí") | C33: =SUMIFS(Diario!$E$5:$E$100,Diario!$D$5:$D$100,A33,Diario!$G$5:$G$100,"Sí") | D33: =IFERROR(C33/B33,0)
A34: Mar S2 | B34: =COUNTIFS(Diario!$D$5:$D$100,A34,Diario!$G$5:$G$100,"Sí") | C34: =SUMIFS(Diario!$E$5:$E$100,Diario!$D$5:$D$100,A34,Diario!$G$5:$G$100,"Sí") | D34: =IFERROR(C34/B34,0)
A35: Mar S3 | B35: =COUNTIFS(Diario!$D$5:$D$100,A35,Diario!$G$5:$G$100,"Sí") | C35: =SUMIFS(Diario!$E$5:$E$100,Diario!$D$5:$D$100,A35,Diario!$G$5:$G$100,"Sí") | D35: =IFERROR(C35/B35,0)
A36: Mar S4 | B36: =COUNTIFS(Diario!$D$5:$D$100,A36,Diario!$G$5:$G$100,"Sí") | C36: =SUMIFS(Diario!$E$5:$E$100,Diario!$D$5:$D$100,A36,Diario!$G$5:$G$100,"Sí") | D36: =IFERROR(C36/B36,0)
A37: Abr S1 | B37: =COUNTIFS(Diario!$D$5:$D$100,A37,Diario!$G$5:$G$100,"Sí") | C37: =SUMIFS(Diario!$E$5:$E$100,Diario!$D$5:$D$100,A37,Diario!$G$5:$G$100,"Sí") | D37: =IFERROR(C37/B37,0)
A38: Abr S2 | B38: =COUNTIFS(Diario!$D$5:$D$100,A38,Diario!$G$5:$G$100,"Sí") | C38: =SUMIFS(Diario!$E$5:$E$100,Diario!$D$5:$D$100,A38,Diario!$G$5:$G$100,"Sí") | D38: =IFERROR(C38/B38,0)
A39: Abr S3 | B39: =COUNTIFS(Diario!$D$5:$D$100,A39,Diario!$G$5:$G$100,"Sí") | C39: =SUMIFS(Diario!$E$5:$E$100,Diario!$D$5:$D$100,A39,Diario!$G$5:$G$100,"Sí") | D39: =IFERROR(C39/B39,0)
... A44: Jun S1 | B44: =COUNTIFS(Diario!$D$5:$D$100,A44,Diario!$G$5:$G$100,"Sí") | C44: =SUMIFS(Diario!$E$5:$E$100,Diario!$D$5:$D$100,A44,Diario!$G$5:$G$100,"Sí") | D44: =IFERROR(C44/B44,0)

Sheet ICE
A1: Índice de consumo energético (ICE) · Línea 22
A2: Fuente: págs. 78-86. kWh (electricidad + aire) por tonelada. Solo hay ICE de marzo y semana 2 de abril.
A4: Fecha | B4: ICE (kWh/t) | C4: Nivel según informe
A5: 46083 | B5: 5.701 | C5: =IF(B5<6,"Muy eficiente",IF(B5<12,"Intermedio",IF(B5<20,"Baja eficiencia","Ineficiente")))
A6: 46084 | B6: 6.165 | C6: =IF(B6<6,"Muy eficiente",IF(B6<12,"Intermedio",IF(B6<20,"Baja eficiencia","Ineficiente")))
A7: 46085 | B7: 9 | C7: =IF(B7<6,"Muy eficiente",IF(B7<12,"Intermedio",IF(B7<20,"Baja eficiencia","Ineficiente")))
A8: 46086 | B8: 11.109 | C8: =IF(B8<6,"Muy eficiente",IF(B8<12,"Intermedio",IF(B8<20,"Baja eficiencia","Ineficiente")))
A9: 46087 | B9: 11.975 | C9: =IF(B9<6,"Muy eficiente",IF(B9<12,"Intermedio",IF(B9<20,"Baja eficiencia","Ineficiente")))
A10: 46088 | B10: 10.754 | C10: =IF(B10<6,"Muy eficiente",IF(B10<12,"Intermedio",IF(B10<20,"Baja eficiencia","Ineficiente")))
A11: 46090 | B11: 12.023 | C11: =IF(B11<6,"Muy eficiente",IF(B11<12,"Intermedio",IF(B11<20,"Baja eficiencia","Ineficiente")))
A12: 46093 | B12: 28.89 | C12: =IF(B12<6,"Muy eficiente",IF(B12<12,"Intermedio",IF(B12<20,"Baja eficiencia","Ineficiente")))
A13: 46094 | B13: 18.94 | C13: =IF(B13<6,"Muy eficiente",IF(B13<12,"Intermedio",IF(B13<20,"Baja eficiencia","Ineficiente")))
A14: 46095 | B14: 31.95 | C14: =IF(B14<6,"Muy eficiente",IF(B14<12,"Intermedio",IF(B14<20,"Baja eficiencia","Ineficiente")))
A15: 46097 | B15: 16.45 | C15: =IF(B15<6,"Muy eficiente",IF(B15<12,"Intermedio",IF(B15<20,"Baja eficiencia","Ineficiente")))
A16: 46098 | B16: 16.01 | C16: =IF(B16<6,"Muy eficiente",IF(B16<12,"Intermedio",IF(B16<20,"Baja eficiencia","Ineficiente")))
... A30: 46123 | B30: 15.435 | C30: =IF(B30<6,"Muy eficiente",IF(B30<12,"Intermedio",IF(B30<20,"Baja eficiencia","Ineficiente")))
A31: Promedio | B31: =AVERAGE(B5:B30) | C31: =IF(B31<6,"Muy eficiente",IF(B31<12,"Intermedio",IF(B31<20,"Baja eficiencia","Ineficiente")))
A32: Días ≥ 12 | B32: =COUNTIF(B5:B30,">=12")
