Workbook

Sheet Dashboard
B1: DASHBOARD DE PARADAS NO PLANEADAS · MANTENIMIENTO 2026
B2: Meses: Enero, Mayo, Junio y Julio · Fuente: IMPACTOS.xlsx · Todo se calcula con fórmulas sobre la hoja Datos
B4: Minutos parados | E4: Horas paradas | H4: N° de paradas | K4: Promedio por parada (min) | N4: Parada más larga (min) | Q4: Registros a revisar
B5: =SUM(Datos!$M$2:$M$319) -> 11998 | E5: =SUM(Datos!$M$2:$M$319)/60 -> 199.96667 | H5: =COUNTA(Datos!$B$2:$B$319) -> 318 | K5: =AVERAGE(Datos!$M$2:$M$319) -> 37.72956 | N5: =MAX(Datos!$M$2:$M$319) -> 480 | Q5: =COUNTA('Calidad de datos'!C5:C42) -> 38
B8: Minutos por mes
B9: Mes | C9: Paradas | D9: Minutos | E9: Horas
B10: Enero | C10: =COUNTIFS(Datos!$A$2:$A$319,B10) -> 78 | D10: =SUMIFS(Datos!$M$2:$M$319,Datos!$A$2:$A$319,B10) -> 2782 | E10: =D10/60 -> 46.366667
B11: Mayo | C11: =COUNTIFS(Datos!$A$2:$A$319,B11) -> 112 | D11: =SUMIFS(Datos!$M$2:$M$319,Datos!$A$2:$A$319,B11) -> 4534 | E11: =D11/60 -> 75.566667
B12: Junio | C12: =COUNTIFS(Datos!$A$2:$A$319,B12) -> 73 | D12: =SUMIFS(Datos!$M$2:$M$319,Datos!$A$2:$A$319,B12) -> 2908 | E12: =D12/60 -> 48.466667
B13: Julio | C13: =COUNTIFS(Datos!$A$2:$A$319,B13) -> 55 | D13: =SUMIFS(Datos!$M$2:$M$319,Datos!$A$2:$A$319,B13) -> 1774 | E13: =D13/60 -> 29.566667
B24: Minutos por línea
B25: Línea | C25: Enero | D25: Mayo | E25: Junio | F25: Julio | G25: Total
B26: LINEA 16 | C26: =SUMIFS(Datos!$M$2:$M$319,Datos!$D$2:$D$319,$B26,Datos!$A$2:$A$319,"Enero") -> 6 | D26: =SUMIFS(Datos!$M$2:$M$319,Datos!$D$2:$D$319,$B26,Datos!$A$2:$A$319,"Mayo") -> 2458 | E26: =SUMIFS(Datos!$M$2:$M$319,Datos!$D$2:$D$319,$B26,Datos!$A$2:$A$319,"Junio") -> 774 | F26: =SUMIFS(Datos!$M$2:$M$319,Datos!$D$2:$D$319,$B26,Datos!$A$2:$A$319,"Julio") -> 100 | G26: =SUM(C26:F26) -> 3338
B27: LINEA 02 | C27: =SUMIFS(Datos!$M$2:$M$319,Datos!$D$2:$D$319,$B27,Datos!$A$2:$A$319,"Enero") -> 0 | D27: =SUMIFS(Datos!$M$2:$M$319,Datos!$D$2:$D$319,$B27,Datos!$A$2:$A$319,"Mayo") -> 692 | E27: =SUMIFS(Datos!$M$2:$M$319,Datos!$D$2:$D$319,$B27,Datos!$A$2:$A$319,"Junio") -> 483 | F27: =SUMIFS(Datos!$M$2:$M$319,Datos!$D$2:$D$319,$B27,Datos!$A$2:$A$319,"Julio") -> 398 | G27: =SUM(C27:F27) -> 1573
B28: LINEA 18 | C28: =SUMIFS(Datos!$M$2:$M$319,Datos!$D$2:$D$319,$B28,Datos!$A$2:$A$319,"Enero") -> 945 | D28: =SUMIFS(Datos!$M$2:$M$319,Datos!$D$2:$D$319,$B28,Datos!$A$2:$A$319,"Mayo") -> 210 | E28: =SUMIFS(Datos!$M$2:$M$319,Datos!$D$2:$D$319,$B28,Datos!$A$2:$A$319,"Junio") -> 164 | F28: =SUMIFS(Datos!$M$2:$M$319,Datos!$D$2:$D$319,$B28,Datos!$A$2:$A$319,"Julio") -> 152 | G28: =SUM(C28:F28) -> 1471
B29: LINEA 10 | C29: =SUMIFS(Datos!$M$2:$M$319,Datos!$D$2:$D$319,$B29,Datos!$A$2:$A$319,"Enero") -> 228 | D29: =SUMIFS(Datos!$M$2:$M$319,Datos!$D$2:$D$319,$B29,Datos!$A$2:$A$319,"Mayo") -> 549 | E29: =SUMIFS(Datos!$M$2:$M$319,Datos!$D$2:$D$319,$B29,Datos!$A$2:$A$319,"Junio") -> 498 | F29: =SUMIFS(Datos!$M$2:$M$319,Datos!$D$2:$D$319,$B29,Datos!$A$2:$A$319,"Julio") -> 90 | G29: =SUM(C29:F29) -> 1365
B30: LINEA 14 | C30: =SUMIFS(Datos!$M$2:$M$319,Datos!$D$2:$D$319,$B30,Datos!$A$2:$A$319,"Enero") -> 599 | D30: =SUMIFS(Datos!$M$2:$M$319,Datos!$D$2:$D$319,$B30,Datos!$A$2:$A$319,"Mayo") -> 111 | E30: =SUMIFS(Datos!$M$2:$M$319,Datos!$D$2:$D$319,$B30,Datos!$A$2:$A$319,"Junio") -> 45 | F30: =SUMIFS(Datos!$M$2:$M$319,Datos!$D$2:$D$319,$B30,Datos!$A$2:$A$319,"Julio") -> 438 | G30: =SUM(C30:F30) -> 1193
B31: LINEA 22 | C31: =SUMIFS(Datos!$M$2:$M$319,Datos!$D$2:$D$319,$B31,Datos!$A$2:$A$319,"Enero") -> 489 | D31: =SUMIFS(Datos!$M$2:$M$319,Datos!$D$2:$D$319,$B31,Datos!$A$2:$A$319,"Mayo") -> 76 | E31: =SUMIFS(Datos!$M$2:$M$319,Datos!$D$2:$D$319,$B31,Datos!$A$2:$A$319,"Junio") -> 125 | F31: =SUMIFS(Datos!$M$2:$M$319,Datos!$D$2:$D$319,$B31,Datos!$A$2:$A$319,"Julio") -> 183 | G31: =SUM(C31:F31) -> 873
B32: LINEA 20 | C32: =SUMIFS(Datos!$M$2:$M$319,Datos!$D$2:$D$319,$B32,Datos!$A$2:$A$319,"Enero") -> 154 | D32: =SUMIFS(Datos!$M$2:$M$319,Datos!$D$2:$D$319,$B32,Datos!$A$2:$A$319,"Mayo") -> 26 | E32: =SUMIFS(Datos!$M$2:$M$319,Datos!$D$2:$D$319,$B32,Datos!$A$2:$A$319,"Junio") -> 270 | F32: =SUMIFS(Datos!$M$2:$M$319,Datos!$D$2:$D$319,$B32,Datos!$A$2:$A$319,"Julio") -> 312 | G32: =SUM(C32:F32) -> 762
B33: LINEA 19 | C33: =SUMIFS(Datos!$M$2:$M$319,Datos!$D$2:$D$319,$B33,Datos!$A$2:$A$319,"Enero") -> 334 | D33: =SUMIFS(Datos!$M$2:$M$319,Datos!$D$2:$D$319,$B33,Datos!$A$2:$A$319,"Mayo") -> 0 | E33: =SUMIFS(Datos!$M$2:$M$319,Datos!$D$2:$D$319,$B33,Datos!$A$2:$A$319,"Junio") -> 241 | F33: =SUMIFS(Datos!$M$2:$M$319,Datos!$D$2:$D$319,$B33,Datos!$A$2:$A$319,"Julio") -> 76 | G33: =SUM(C33:F33) -> 651
B34: LINEA 11 | C34: =SUMIFS(Datos!$M$2:$M$319,Datos!$D$2:$D$319,$B34,Datos!$A$2:$A$319,"Enero") -> 15 | D34: =SUMIFS(Datos!$M$2:$M$319,Datos!$D$2:$D$319,$B34,Datos!$A$2:$A$319,"Mayo") -> 334 | E34: =SUMIFS(Datos!$M$2:$M$319,Datos!$D$2:$D$319,$B34,Datos!$A$2:$A$319,"Junio") -> 21 | F34: =SUMIFS(Datos!$M$2:$M$319,Datos!$D$2:$D$319,$B34,Datos!$A$2:$A$319,"Julio") -> 25 | G34: =SUM(C34:F34) -> 395
B35: LINEA 03 | C35: =SUMIFS(Datos!$M$2:$M$319,Datos!$D$2:$D$319,$B35,Datos!$A$2:$A$319,"Enero") -> 12 | D35: =SUMIFS(Datos!$M$2:$M$319,Datos!$D$2:$D$319,$B35,Datos!$A$2:$A$319,"Mayo") -> 78 | E35: =SUMIFS(Datos!$M$2:$M$319,Datos!$D$2:$D$319,$B35,Datos!$A$2:$A$319,"Junio") -> 245 | F35: =SUMIFS(Datos!$M$2:$M$319,Datos!$D$2:$D$319,$B35,Datos!$A$2:$A$319,"Julio") -> 0 | G35: =SUM(C35:F35) -> 335
B36: LINEA 07 | C36: =SUMIFS(Datos!$M$2:$M$319,Datos!$D$2:$D$319,$B36,Datos!$A$2:$A$319,"Enero") -> 0 | D36: =SUMIFS(Datos!$M$2:$M$319,Datos!$D$2:$D$319,$B36,Datos!$A$2:$A$319,"Mayo") -> 0 | E36: =SUMIFS(Datos!$M$2:$M$319,Datos!$D$2:$D$319,$B36,Datos!$A$2:$A$319,"Junio") -> 42 | F36: =SUMIFS(Datos!$M$2:$M$319,Datos!$D$2:$D$319,$B36,Datos!$A$2:$A$319,"Julio") -> 0 | G36: =SUM(C36:F36) -> 42
B40: Top 10 equipos (minutos)
B41: Equipo | D41: Paradas | E41: Minutos | F41: % total
B42: LLENADORA | D42: =COUNTIFS(Datos!$H$2:$H$319,B42) -> 124 | E42: =SUMIFS(Datos!$M$2:$M$319,Datos!$H$2:$H$319,B42) -> 4798 | F42: =E42/SUM(Datos!$M$2:$M$319) -> 0.39989998
B43: SERVO MOTOR | D43: =COUNTIFS(Datos!$H$2:$H$319,B43) -> 28 | E43: =SUMIFS(Datos!$M$2:$M$319,Datos!$H$2:$H$319,B43) -> 1417 | F43: =E43/SUM(Datos!$M$2:$M$319) -> 0.11810302
B44: BANDA TRANSPORTADORA | D44: =COUNTIFS(Datos!$H$2:$H$319,B44) -> 15 | E44: =SUMIFS(Datos!$M$2:$M$319,Datos!$H$2:$H$319,B44) -> 772 | F44: =E44/SUM(Datos!$M$2:$M$319) -> 0.064344057
B45: ENCINTADORA | D45: =COUNTIFS(Datos!$H$2:$H$319,B45) -> 12 | E45: =SUMIFS(Datos!$M$2:$M$319,Datos!$H$2:$H$319,B45) -> 581 | F45: =E45/SUM(Datos!$M$2:$M$319) -> 0.048424737
B46: TIJERA | D46: =COUNTIFS(Datos!$H$2:$H$319,B46) -> 11 | E46: =SUMIFS(Datos!$M$2:$M$319,Datos!$H$2:$H$319,B46) -> 537 | F46: =E46/SUM(Datos!$M$2:$M$319) -> 0.04475746
B47: MORDAZA SUPERIOR | D47: =COUNTIFS(Datos!$H$2:$H$319,B47) -> 15 | E47: =SUMIFS(Datos!$M$2:$M$319,Datos!$H$2:$H$319,B47) -> 486 | F47: =E47/SUM(Datos!$M$2:$M$319) -> 0.040506751
B48: ENCAJADORA | D48: =COUNTIFS(Datos!$H$2:$H$319,B48) -> 13 | E48: =SUMIFS(Datos!$M$2:$M$319,Datos!$H$2:$H$319,B48) -> 363 | F48: =E48/SUM(Datos!$M$2:$M$319) -> 0.030255043
B49: SISTEMA SUCCION - OGA | D49: =COUNTIFS(Datos!$H$2:$H$319,B49) -> 8 | E49: =SUMIFS(Datos!$M$2:$M$319,Datos!$H$2:$H$319,B49) -> 324 | F49: =E49/SUM(Datos!$M$2:$M$319) -> 0.027004501
B50: FECHADOR | D50: =COUNTIFS(Datos!$H$2:$H$319,B50) -> 10 | E50: =SUMIFS(Datos!$M$2:$M$319,Datos!$H$2:$H$319,B50) -> 307 | F50: =E50/SUM(Datos!$M$2:$M$319) -> 0.025587598
B51: DESBOBINADOR | D51: =COUNTIFS(Datos!$H$2:$H$319,B51) -> 12 | E51: =SUMIFS(Datos!$M$2:$M$319,Datos!$H$2:$H$319,B51) -> 269 | F51: =E51/SUM(Datos!$M$2:$M$319) -> 0.022420403
B57: Las 3 paradas más largas de cada mes (eventos agrupados)
B58: Mes | C58: # | D58: Fecha | E58: Línea | F58: Equipo | H58: Minutos | I58: Qué pasó
B59: Enero | C59: ='Top 3 por mes'!B6 -> 1 | D59: ='Top 3 por mes'!C6 -> 46035 | E59: ='Top 3 por mes'!D6 -> LINEA 18 | F59: ='Top 3 por mes'!E6 -> LLENADORA | H59: ='Top 3 por mes'!G6 -> 480 | I59: ='Top 3 por mes'!J6 -> Arranque con acompañamiento de proyectos
C60: ='Top 3 por mes'!B7 -> 2 | D60: ='Top 3 por mes'!C7 -> 46048 | E60: ='Top 3 por mes'!D7 -> LINEA 22 | F60: ='Top 3 por mes'!E7 -> MORDAZA VERTICAL | H60: ='Top 3 por mes'!G7 -> 200 | I60: ='Top 3 por mes'!J7 -> Daño en motor de placa mordazas / Daño en tarjeta motos correccion de placa mordazas / Daño tarjeta correccion placa mordazas
C61: ='Top 3 por mes'!B8 -> 3 | D61: ='Top 3 por mes'!C8 -> 46024 | E61: ='Top 3 por mes'!D8 -> LINEA 22 | F61: ='Top 3 por mes'!E8 -> ENCINTADORA | H61: ='Top 3 por mes'!G8 -> 180 | I61: ='Top 3 por mes'!J8 -> Cambio de moto reductor banda entrada encintadora
...

Sheet Fallas repetitivas
B1: FALLAS QUE MÁS SE REPITEN
B2: Cada registro se clasificó en un tipo de falla según su observación (columna S de Datos). Ordenado por número de veces que se repite.
B4: # | C4: Tipo de falla | D4: Veces | E4: Minutos | F4: Horas | G4: Prom. min/vez | H4: Días con la falla | I4: Líneas afectadas (veces) | J4: Meses | K4: Equipos
B5: 1 | C5: Servo de arrastre / encoder (falla de arrastre) | D5: =COUNTIFS(Datos!$S$2:$S$319,C5) -> 54 | E5: =SUMIFS(Datos!$M$2:$M$319,Datos!$S$2:$S$319,C5) -> 2844 | F5: =E5/60 -> 47.4 | G5: =IFERROR(E5/D5,0) -> 52.666667 | H5: 15 | I5: L16 (50), L19 (2), L18 (1), L02 (1) | J5: Enero, Mayo, Junio, Julio | K5: Llenadora, Servo Motor, Banda Transportadora
B6: 2 | C6: Bandas, correas y cadenas (se frenan / descarrilan) | D6: =COUNTIFS(Datos!$S$2:$S$319,C6) -> 30 | E6: =SUMIFS(Datos!$M$2:$M$319,Datos!$S$2:$S$319,C6) -> 1593 | F6: =E6/60 -> 26.55 | G6: =IFERROR(E6/D6,0) -> 53.1 | H6: 18 | I6: L10 (8), L22 (6), L19 (5), L02 (5), L20 (4), L14 (2) | J6: Enero, Mayo, Junio, Julio | K6: Banda Transportadora, Encintadora, Alimentador Tapa
B7: 3 | C7: Boquillas de llenado (goteo, fugas, conos) | D7: =COUNTIFS(Datos!$S$2:$S$319,C7) -> 23 | E7: =SUMIFS(Datos!$M$2:$M$319,Datos!$S$2:$S$319,C7) -> 533 | F7: =E7/60 -> 8.8833333 | G7: =IFERROR(E7/D7,0) -> 23.173913 | H7: 14 | I7: L02 (10), L18 (6), L03 (5), L19 (1), L22 (1) | J7: Enero, Mayo, Junio, Julio | K7: Llenadora, Perdida De Velocidad
B8: 4 | C8: PLC, programa, drives y tarjetas electrónicas | D8: =COUNTIFS(Datos!$S$2:$S$319,C8) -> 20 | E8: =SUMIFS(Datos!$M$2:$M$319,Datos!$S$2:$S$319,C8) -> 472 | F8: =E8/60 -> 7.8666667 | G8: =IFERROR(E8/D8,0) -> 23.6 | H8: 8 | I8: L10 (4), L02 (4), L20 (4), L14 (3), L22 (3), L11 (1), L18 (1) | J8: Enero, Mayo, Junio, Julio | K8: Llenadora, Mordaza Vertical, Tapadora
B9: 5 | C9: Tornillos, pines y piezas partidas | D9: =COUNTIFS(Datos!$S$2:$S$319,C9) -> 19 | E9: =SUMIFS(Datos!$M$2:$M$319,Datos!$S$2:$S$319,C9) -> 610 | F9: =E9/60 -> 10.166667 | G9: =IFERROR(E9/D9,0) -> 32.105263 | H9: 14 | I9: L02 (5), L20 (3), L14 (3), L16 (2), L10 (2), L11 (1), L18 (1), L19 (1), L07 (1) | J9: Enero, Mayo, Junio, Julio | K9: Llenadora, Mordaza Superior, Servo Motor
B10: 6 | C10: Resistencias / temperatura de mordazas | D10: =COUNTIFS(Datos!$S$2:$S$319,C10) -> 17 | E10: =SUMIFS(Datos!$M$2:$M$319,Datos!$S$2:$S$319,C10) -> 492 | F10: =E10/60 -> 8.2 | G10: =IFERROR(E10/D10,0) -> 28.941176 | H10: 9 | I10: L14 (10), L18 (6), L16 (1) | J10: Enero, Mayo, Junio | K10: Mordaza Superior, Mordazas
B11: 7 | C11: Fotoceldas y sensores | D11: =COUNTIFS(Datos!$S$2:$S$319,C11) -> 16 | E11: =SUMIFS(Datos!$M$2:$M$319,Datos!$S$2:$S$319,C11) -> 406 | F11: =E11/60 -> 6.7666667 | G11: =IFERROR(E11/D11,0) -> 25.375 | H11: 8 | I11: L18 (9), L03 (3), L16 (2), L19 (1), L02 (1) | J11: Enero, Mayo, Junio, Julio | K11: Llenadora, Fotocelula, Encajadora
B12: 8 | C12: Ristras rotas / sello de laminado | D12: =COUNTIFS(Datos!$S$2:$S$319,C12) -> 12 | E12: =SUMIFS(Datos!$M$2:$M$319,Datos!$S$2:$S$319,C12) -> 285 | F12: =E12/60 -> 4.75 | G12: =IFERROR(E12/D12,0) -> 23.75 | H12: 7 | I12: L16 (6), L18 (5), L20 (1) | J12: Enero, Mayo, Junio | K12: Servo Motor, Desbobinador, Llenadora
B13: 9 | C13: Electroválvulas, racores y fugas de aire | D13: =COUNTIFS(Datos!$S$2:$S$319,C13) -> 11 | E13: =SUMIFS(Datos!$M$2:$M$319,Datos!$S$2:$S$319,C13) -> 275 | F13: =E13/60 -> 4.5833333 | G13: =IFERROR(E13/D13,0) -> 25 | H13: 9 | I13: L18 (4), L14 (2), L10 (2), L02 (1), L03 (1), L22 (1) | J13: Mayo, Junio, Julio | K13: Llenadora, Encajadora, Mordaza Superior
B14: 10 | C14: Tijera y cuchillas (cambio / calibración) | D14: =COUNTIFS(Datos!$S$2:$S$319,C14) -> 10 | E14: =SUMIFS(Datos!$M$2:$M$319,Datos!$S$2:$S$319,C14) -> 487 | F14: =E14/60 -> 8.1166667 | G14: =IFERROR(E14/D14,0) -> 48.7 | H14: 8 | I14: L22 (4), L19 (3), L14 (2), L20 (1) | J14: Enero, Mayo, Junio, Julio | K14: Tijera
B15: 11 | C15: Codificador / fechador | D15: =COUNTIFS(Datos!$S$2:$S$319,C15) -> 10 | E15: =SUMIFS(Datos!$M$2:$M$319,Datos!$S$2:$S$319,C15) -> 307 | F15: =E15/60 -> 5.1166667 | G15: =IFERROR(E15/D15,0) -> 30.7 | H15: 7 | I15: L03 (2), L10 (2), L02 (2), L20 (1), L19 (1), L18 (1), L22 (1) | J15: Enero, Mayo, Junio | K15: Fechador
B16: 12 | C16: Clapet del tapón | D16: =COUNTIFS(Datos!$S$2:$S$319,C16) -> 9 | E16: =SUMIFS(Datos!$M$2:$M$319,Datos!$S$2:$S$319,C16) -> 349 | F16: =E16/60 -> 5.8166667 | G16: =IFERROR(E16/D16,0) -> 38.777778 | H16: 4 | I16: L14 (7), L22 (1), L19 (1) | J16: Julio | K16: Llenadora, Alimentador Tapon, Alimentador Tapa
... B30: 26 | C30: Espera de permiso EHS (trabajo en caliente) | D30: =COUNTIFS(Datos!$S$2:$S$319,C30) -> 2 | E30: =SUMIFS(Datos!$M$2:$M$319,Datos!$S$2:$S$319,C30) -> 90 | F30: =E30/60 -> 1.5 | G30: =IFERROR(E30/D30,0) -> 45 | H30: 1 | I30: L02 (2) | J30: Julio | K30: Ehs
C31: Sin observación | D31: =COUNTIFS(Datos!$S$2:$S$319,C31) -> 9 | E31: =SUMIFS(Datos!$M$2:$M$319,Datos!$S$2:$S$319,C31) -> 297 | F31: =E31/60 -> 4.95 | G31: =IFERROR(E31/D31,0) -> 33
C32: Otras fallas | D32: =COUNTIFS(Datos!$S$2:$S$319,C32) -> 16 | E32: =SUMIFS(Datos!$M$2:$M$319,Datos!$S$2:$S$319,C32) -> 803 | F32: =E32/60 -> 13.383333 | G32: =IFERROR(E32/D32,0) -> 50.1875
C33: TOTAL | D33: =SUM(D5:D32) -> 318 | E33: =SUM(E5:E32) -> 11998 | F33: =E33/60 -> 199.96667
B34: Las 5 filas resaltadas son las fallas más repetitivas. "Días con la falla", líneas, meses y equipos se calcularon al crear el archivo.
B36: Veces por mes (para ver si la falla es constante)
C37: Tipo de falla | D37: Enero | E37: Mayo | F37: Junio | G37: Julio | H37: Total
C38: =C5 -> Servo de arrastre / encoder (falla de arrastre) | D38: =COUNTIFS(Datos!$S$2:$S$319,$C38,Datos!$A$2:$A$319,"Enero") -> 3 | E38: =COUNTIFS(Datos!$S$2:$S$319,$C38,Datos!$A$2:$A$319,"Mayo") -> 35 | F38: =COUNTIFS(Datos!$S$2:$S$319,$C38,Datos!$A$2:$A$319,"Junio") -> 15 | G38: =COUNTIFS(Datos!$S$2:$S$319,$C38,Datos!$A$2:$A$319,"Julio") -> 1 | H38: =SUM(D38:G38) -> 54
C39: =C6 -> Bandas, correas y cadenas (se frenan / descarrilan) | D39: =COUNTIFS(Datos!$S$2:$S$319,$C39,Datos!$A$2:$A$319,"Enero") -> 13 | E39: =COUNTIFS(Datos!$S$2:$S$319,$C39,Datos!$A$2:$A$319,"Mayo") -> 5 | F39: =COUNTIFS(Datos!$S$2:$S$319,$C39,Datos!$A$2:$A$319,"Junio") -> 4 | G39: =COUNTIFS(Datos!$S$2:$S$319,$C39,Datos!$A$2:$A$319,"Julio") -> 8 | H39: =SUM(D39:G39) -> 30
C40: =C7 -> Boquillas de llenado (goteo, fugas, conos) | D40: =COUNTIFS(Datos!$S$2:$S$319,$C40,Datos!$A$2:$A$319,"Enero") -> 6 | E40: =COUNTIFS(Datos!$S$2:$S$319,$C40,Datos!$A$2:$A$319,"Mayo") -> 6 | F40: =COUNTIFS(Datos!$S$2:$S$319,$C40,Datos!$A$2:$A$319,"Junio") -> 9 | G40: =COUNTIFS(Datos!$S$2:$S$319,$C40,Datos!$A$2:$A$319,"Julio") -> 2 | H40: =SUM(D40:G40) -> 23
C41: =C8 -> PLC, programa, drives y tarjetas electrónicas | D41: =COUNTIFS(Datos!$S$2:$S$319,$C41,Datos!$A$2:$A$319,"Enero") -> 8 | E41: =COUNTIFS(Datos!$S$2:$S$319,$C41,Datos!$A$2:$A$319,"Mayo") -> 1 | F41: =COUNTIFS(Datos!$S$2:$S$319,$C41,Datos!$A$2:$A$319,"Junio") -> 8 | G41: =COUNTIFS(Datos!$S$2:$S$319,$C41,Datos!$A$2:$A$319,"Julio") -> 3 | H41: =SUM(D41:G41) -> 20
C42: =C9 -> Tornillos, pines y piezas partidas | D42: =COUNTIFS(Datos!$S$2:$S$319,$C42,Datos!$A$2:$A$319,"Enero") -> 2 | E42: =COUNTIFS(Datos!$S$2:$S$319,$C42,Datos!$A$2:$A$319,"Mayo") -> 9 | F42: =COUNTIFS(Datos!$S$2:$S$319,$C42,Datos!$A$2:$A$319,"Junio") -> 6 | G42: =COUNTIFS(Datos!$S$2:$S$319,$C42,Datos!$A$2:$A$319,"Julio") -> 2 | H42: =SUM(D42:G42) -> 19
C43: =C10 -> Resistencias / temperatura de mordazas | D43: =COUNTIFS(Datos!$S$2:$S$319,$C43,Datos!$A$2:$A$319,"Enero") -> 9 | E43: =COUNTIFS(Datos!$S$2:$S$319,$C43,Datos!$A$2:$A$319,"Mayo") -> 7 | F43: =COUNTIFS(Datos!$S$2:$S$319,$C43,Datos!$A$2:$A$319,"Junio") -> 1 | G43: =COUNTIFS(Datos!$S$2:$S$319,$C43,Datos!$A$2:$A$319,"Julio") -> 0 | H43: =SUM(D43:G43) -> 17
C44: =C11 -> Fotoceldas y sensores | D44: =COUNTIFS(Datos!$S$2:$S$319,$C44,Datos!$A$2:$A$319,"Enero") -> 9 | E44: =COUNTIFS(Datos!$S$2:$S$319,$C44,Datos!$A$2:$A$319,"Mayo") -> 1 | F44: =COUNTIFS(Datos!$S$2:$S$319,$C44,Datos!$A$2:$A$319,"Junio") -> 3 | G44: =COUNTIFS(Datos!$S$2:$S$319,$C44,Datos!$A$2:$A$319,"Julio") -> 3 | H44: =SUM(D44:G44) -> 16
C45: =C12 -> Ristras rotas / sello de laminado | D45: =COUNTIFS(Datos!$S$2:$S$319,$C45,Datos!$A$2:$A$319,"Enero") -> 5 | E45: =COUNTIFS(Datos!$S$2:$S$319,$C45,Datos!$A$2:$A$319,"Mayo") -> 6 | F45: =COUNTIFS(Datos!$S$2:$S$319,$C45,Datos!$A$2:$A$319,"Junio") -> 1 | G45: =COUNTIFS(Datos!$S$2:$S$319,$C45,Datos!$A$2:$A$319,"Julio") -> 0 | H45: =SUM(D45:G45) -> 12
C46: =C13 -> Electroválvulas, racores y fugas de aire | D46: =COUNTIFS(Datos!$S$2:$S$319,$C46,Datos!$A$2:$A$319,"Enero") -> 0 | E46: =COUNTIFS(Datos!$S$2:$S$319,$C46,Datos!$A$2:$A$319,"Mayo") -> 3 | F46: =COUNTIFS(Datos!$S$2:$S$319,$C46,Datos!$A$2:$A$319,"Junio") -> 4 | G46: =COUNTIFS(Datos!$S$2:$S$319,$C46,Datos!$A$2:$A$319,"Julio") -> 4 | H46: =SUM(D46:G46) -> 11
C47: =C14 -> Tijera y cuchillas (cambio / calibración) | D47: =COUNTIFS(Datos!$S$2:$S$319,$C47,Datos!$A$2:$A$319,"Enero") -> 2 | E47: =COUNTIFS(Datos!$S$2:$S$319,$C47,Datos!$A$2:$A$319,"Mayo") -> 2 | F47: =COUNTIFS(Datos!$S$2:$S$319,$C47,Datos!$A$2:$A$319,"Junio") -> 4 | G47: =COUNTIFS(Datos!$S$2:$S$319,$C47,Datos!$A$2:$A$319,"Julio") -> 2 | H47: =SUM(D47:G47) -> 10
C48: =C15 -> Codificador / fechador | D48: =COUNTIFS(Datos!$S$2:$S$319,$C48,Datos!$A$2:$A$319,"Enero") -> 2 | E48: =COUNTIFS(Datos!$S$2:$S$319,$C48,Datos!$A$2:$A$319,"Mayo") -> 5 | F48: =COUNTIFS(Datos!$S$2:$S$319,$C48,Datos!$A$2:$A$319,"Junio") -> 3 | G48: =COUNTIFS(Datos!$S$2:$S$319,$C48,Datos!$A$2:$A$319,"Julio") -> 0 | H48: =SUM(D48:G48) -> 10
C49: =C16 -> Clapet del tapón | D49: =COUNTIFS(Datos!$S$2:$S$319,$C49,Datos!$A$2:$A$319,"Enero") -> 0 | E49: =COUNTIFS(Datos!$S$2:$S$319,$C49,Datos!$A$2:$A$319,"Mayo") -> 0 | F49: =COUNTIFS(Datos!$S$2:$S$319,$C49,Datos!$A$2:$A$319,"Junio") -> 0 | G49: =COUNTIFS(Datos!$S$2:$S$319,$C49,Datos!$A$2:$A$319,"Julio") -> 9 | H49: =SUM(D49:G49) -> 9
... C63: =C30 -> Espera de permiso EHS (trabajo en caliente) | D63: =COUNTIFS(Datos!$S$2:$S$319,$C63,Datos!$A$2:$A$319,"Enero") -> 0 | E63: =COUNTIFS(Datos!$S$2:$S$319,$C63,Datos!$A$2:$A$319,"Mayo") -> 0 | F63: =COUNTIFS(Datos!$S$2:$S$319,$C63,Datos!$A$2:$A$319,"Junio") -> 0 | G63: =COUNTIFS(Datos!$S$2:$S$319,$C63,Datos!$A$2:$A$319,"Julio") -> 2 | H63: =SUM(D63:G63) -> 2
B65: Fallas crónicas: misma falla repetida en la misma línea (top 10)
B66: # | C66: Tipo de falla | D66: Veces | E66: Minutos | F66: Horas | G66: Días | H66: Línea | I66: Meses | J66: Ejemplo de observación
B67: 1 | C67: Servo de arrastre / encoder (falla de arrastre) | D67: =COUNTIFS(Datos!$S$2:$S$319,C67,Datos!$D$2:$D$319,H67) -> 50 | E67: =SUMIFS(Datos!$M$2:$M$319,Datos!$S$2:$S$319,C67,Datos!$D$2:$D$319,H67) -> 2722 | F67: =E67/60 -> 45.366667 | G67: 11 | H67: LINEA 16 | I67: Mayo, Junio | J67: Falla de arrastre
B68: 2 | C68: Resistencias / temperatura de mordazas | D68: =COUNTIFS(Datos!$S$2:$S$319,C68,Datos!$D$2:$D$319,H68) -> 10 | E68: =SUMIFS(Datos!$M$2:$M$319,Datos!$S$2:$S$319,C68,Datos!$D$2:$D$319,H68) -> 356 | F68: =E68/60 -> 5.9333333 | G68: 5 | H68: LINEA 14 | I68: Enero, Mayo | J68: Hace corto seristencia quemando esta
B69: 3 | C69: Boquillas de llenado (goteo, fugas, conos) | D69: =COUNTIFS(Datos!$S$2:$S$319,C69,Datos!$D$2:$D$319,H69) -> 10 | E69: =SUMIFS(Datos!$M$2:$M$319,Datos!$S$2:$S$319,C69,Datos!$D$2:$D$319,H69) -> 269 | F69: =E69/60 -> 4.4833333 | G69: 6 | H69: LINEA 02 | I69: Mayo, Junio, Julio | J69: Se interviene la boquilla 6 por fuga de betun
...

Sheet Datos
A1: MES | B1: Id | C1: FECHA | D1: LINEA | E1: TURNO | F1: SKU | G1: DESCRIPCION | H1: PARADA | I1: STOPPAGE CODE | J1: CLUSTER | K1: INICIO | L1: FIN | M1: TIEMPO PARADA | N1: MIN SEGUN HORARIO | O1: DIFERENCIA | P1: OBSERVACION PARADA | Q1: USUARIO | R1: Justificacion | S1: TIPO DE FALLA
A2: Enero | B2: 34081 | C2: 46027 | D2: LINEA 19 | E2: 1 | F2: 3251821 | G2: VANSH,CO,800ML WHITEX12 | H2: ENCINTADORA | I2: MS | J2: Adjustment + Breakdown | K2: 07:10 | L2: 08:00 | M2: 50 | N2: 50 | O2: =M2-N2 -> 0 | P2: se suelta dado del sin fin de las bandas de la selladora electrica | Q2: u suario | R2: No | S2: Bandas, correas y cadenas (se frenan / descarrilan)
A3: Enero | B3: 34114 | C3: 46027 | D3: LINEA 11 | E3: 1 | F3: 3317524 | G3: VANSH,AR,BLANCO TARRO 450GRX12 | H3: TAPADORA | I3: MT | J3: Adjustment + Breakdown | K3: 13:00 | L3: 13:15 | M3: 15 | N3: 15 | O3: =M3-N3 -> 0 | P3: se fractura cable conexion electrica potenciometro rodillos tapadora | Q3: Jhonier Rincon | R3: No | S3: PLC, programa, drives y tarjetas electrónicas
A4: Enero | B4: 34166 | C4: 46028 | D4: LINEA 20 | E4: 1 | F4: 3303200 | G4: VANSH,CO,POLVO BLANCO 100GRX24 | H4: LLENADORA | I4: ML | J4: Adjustment + Breakdown | K4: 07:50 | L4: 08:00 | M4: 10 | N4: 10 | O4: =M4-N4 -> 0 | P4: daño banda de salida de la llenadora | Q4: Marcos Saez | R4: No | S4: Bandas, correas y cadenas (se frenan / descarrilan)
A5: Enero | B5: 34167 | C5: 46028 | D5: LINEA 20 | E5: 1 | F5: 3303200 | G5: VANSH,CO,POLVO BLANCO 100GRX24 | H5: LLENADORA | I5: ML | J5: Adjustment + Breakdown | K5: 08:00 | L5: 08:25 | M5: 25 | N5: 25 | O5: =M5-N5 -> 0 | P5: daño banda de salida de la llenadora | Q5: Marcos Saez | R5: No | S5: Bandas, correas y cadenas (se frenan / descarrilan)
A6: Enero | B6: 34171 | C6: 46028 | D6: LINEA 20 | E6: 1 | F6: 3303200 | G6: VANSH,CO,POLVO BLANCO 100GRX24 | H6: LLENADORA | I6: ML | J6: Adjustment + Breakdown | K6: 09:10 | L6: 09:45 | M6: 35 | N6: 35 | O6: =M6-N6 -> 0 | P6: cambio de seguidor | Q6: Marcos Saez | R6: No | S6: Tornillos, pines y piezas partidas
A7: Enero | B7: 34318 | C7: 46030 | D7: LINEA 19 | E7: 1 | F7: 3251821 | G7: VANSH,CO,800ML WHITEX12 | H7: CARRO MOVIL | I7: MCM | J7: Adjustment + Breakdown | K7: 09:24 | L7: 09:50 | M7: 26 | N7: 26 | O7: =M7-N7 -> 0 | P7: cambio de pinza frontal por desgaste y se pide en almacen silicona para pinza. | Q7: Jordan Dawkins | R7: No | S7: Otras fallas
A8: Enero | B8: 34529 | C8: 46035 | D8: LINEA 14 | E8: 1 | F8: 3251825 | G8: VANSH,CO,300ML PINKX48 | H8: MORDAZA SUPERIOR | I8: MOS | J8: Adjustment + Breakdown | K8: 09:25 | L8: 10:00 | M8: 35 | N8: 35 | O8: =M8-N8 -> 0 | P8: hace corto seristencia quemando esta | Q8: Cristian Santacruz | R8: No | S8: Resistencias / temperatura de mordazas
A9: Enero | B9: 34530 | C9: 46035 | D9: LINEA 14 | E9: 1 | F9: 3251825 | G9: VANSH,CO,300ML PINKX48 | H9: MORDAZA SUPERIOR | I9: MOS | J9: Adjustment + Breakdown | K9: 10:00 | L9: 11:00 | M9: 60 | N9: 60 | O9: =M9-N9 -> 0 | P9: cambio de resistencias | Q9: Cristian Santacruz | R9: No | S9: Resistencias / temperatura de mordazas
A10: Enero | B10: 34533 | C10: 46035 | D10: LINEA 14 | E10: 1 | F10: 3251825 | G10: VANSH,CO,300ML PINKX48 | H10: MORDAZA SUPERIOR | I10: MOS | J10: Adjustment + Breakdown | K10: 12:00 | L10: 13:00 | M10: 60 | N10: 60 | O10: =M10-N10 -> 0 | P10: se hace cambio de resistencias | Q10: Cristian Santacruz | R10: No | S10: Resistencias / temperatura de mordazas
A11: Enero | B11: 34538 | C11: 46035 | D11: LINEA 20 | E11: 1 | F11: 3303201 | G11: VANSH,CO,POLVO ROSA 100GRX24 | H11: PARADA MENOR | I11: PM | J11: Minor Stops | K11: 10:00 | L11: 10:04 | M11: 4 | N11: 4 | O11: =M11-N11 -> 0 | P11: LUBRICACION DE LEVAS CON OKS | Q11: Andrés Escobar | R11: No | S11: Otras fallas
A12: Enero | B12: 34582 | C12: 46036 | D12: LINEA 18 | E12: 1 | F12: 3097733 | G12: VANSH,CR,GEL PINK 100ML CAM | H12: LLENADORA | I12: ML | J12: Adjustment + Breakdown | K12: 07:35 | L12: 07:45 | M12: 10 | N12: 10 | O12: =M12-N12 -> 0 | P12: continuas paradas por filtracion ristra 3 y 4 | Q12: Adriana Vasquez | R12: No | S12: Ristras rotas / sello de laminado
A13: Enero | B13: 34597 | C13: 46036 | D13: LINEA 18 | E13: 1 | F13: 3097733 | G13: VANSH,CR,GEL PINK 100ML CAM | H13: LLENADORA | I13: ML | J13: Adjustment + Breakdown | K13: 08:24 | L13: 08:44 | M13: 20 | N13: 20 | O13: =M13-N13 -> 0 | P13: filtracion en boquilla 3 y 4 generando continuas paradas | Q13: Adriana Vasquez | R13: No | S13: Boquillas de llenado (goteo, fugas, conos)
... A38: Enero | B38: 34876 | C38: 46039 | D38: LINEA 19 | E38: 1 | F38: 3153282 | G38: SANPC,CO,2000ML X 6 VAINILLA | H38: ENCINTADORA | I38: MS | J38: Adjustment + Breakdown | K38: 08:15 | L38: 09:00 | M38: 45 | N38: 45 | O38: =M38-N38 -> 0 | P38: falla en correas laterales se cambian | Q38: Jordan Dawkins | R38: No | S38: Bandas, correas y cadenas (se frenan / descarrilan)
A39: Enero | B39: 34877 | C39: 46039 | D39: LINEA 19 | E39: 1 | F39: 3153282 | G39: SANPC,CO,2000ML X 6 VAINILLA | H39: ENCINTADORA | I39: MS | J39: Adjustment + Breakdown | K39: 09:00 | L39: 09:25 | M39: 25 | N39: 25 | O39: =M39-N39 -> 0 | Q39: Jordan Dawkins | R39: No | S39: Sin observación
A40: Enero | B40: 34931 | C40: 46024 | D40: LINEA 22 | E40: 1 | F40: 3251824 | G40: VANSH,CO,450ML WHITEX24 | H40: ENCINTADORA | I40: MS | J40: Adjustment + Breakdown | K40: 07:00 | L40: 10:00 | M40: 180 | N40: 180 | O40: =M40-N40 -> 0 | P40: Cambio de moto reductor banda entrada encintadora | Q40: u suario | R40: No | S40: Bandas, correas y cadenas (se frenan / descarrilan)
A41: Enero | B41: 34947 | C41: 46041 | D41: LINEA 20 | E41: 1 | F41: 3303107 | G41: VANSH,AR,POLVO BLANCO 120GRX24 | H41: FECHADOR | I41: MK | J41: Adjustment + Breakdown | K41: 07:00 | L41: 07:10 | M41: 10 | N41: 10 | O41: =M41-N41 -> 0 | P41: falla de copilo solo imprime la mitad | Q41: Marcos Saez | R41: No | S41: Codificador / fechador
A42: Enero | B42: 34991 | C42: 46041 | D42: LINEA 18 | E42: 1 | F42: 3065105 | G42: VANSH,CO,100MLX72 PINK GOLD | H42: FOTOCELULA | I42: FT | J42: Adjustment + Breakdown | K42: 13:50 | L42: 14:00 | M42: 10 | N42: 10 | O42: =M42-N42 -> 0 | P42: continuas paradas por fallo en la fotocelda del desbobinador | Q42: Adriana Vasquez | R42: No | S42: Fotoceldas y sensores
A43: Enero | B43: 35023 | C43: 46041 | D43: LINEA 10 | E43: 2 | F43: 3295333 | G43: VANISH WHITE GALÓN X4 | H43: BANDA TRANSPORTADORA | I43: MD | J43: Adjustment + Breakdown | K43: 15:00 | L43: 16:00 | M43: 60 | N43: 60 | O43: =M43-N43 -> 0 | P43: espera entega de mtto banda ttransporte tapa wollite hacia tapadora | Q43: Hector Valencia | R43: No | S43: Bandas, correas y cadenas (se frenan / descarrilan)
A44: Enero | B44: 35024 | C44: 46041 | D44: LINEA 10 | E44: 2 | F44: 3295333 | G44: VANISH WHITE GALÓN X4 | H44: BANDA TRANSPORTADORA | I44: MD | J44: Adjustment + Breakdown | K44: 16:00 | L44: 17:00 | M44: 60 | N44: 60 | O44: =M44-N44 -> 0 | P44: mtto ajusyta banda para empezar proceso | Q44: Hector Valencia | R44: No | S44: Bandas, correas y cadenas (se frenan / descarrilan)
A45: Enero | B45: 35026 | C45: 46041 | D45: LINEA 10 | E45: 2 | F45: 3295333 | G45: VANISH WHITE GALÓN X4 | H45: BANDA TRANSPORTADORA | I45: MD | J45: Adjustment + Breakdown | K45: 17:15 | L45: 17:30 | M45: 15 | N45: 15 | O45: =M45-N45 -> 0 | P45: cambio de direccion banda elevador de tapa | Q45: Hector Valencia | R45: No | S45: Bandas, correas y cadenas (se frenan / descarrilan)
A46: Enero | B46: 35027 | C46: 46040 | D46: LINEA 14 | E46: 3 | F46: 21138 | G46: ESYOF,CO,QTG,DP,LIM,EXP,500ML | H46: ENCINTADORA | I46: MS | J46: Adjustment + Breakdown | K46: 06:00 | L46: 07:00 | M46: 60 | N46: 60 | O46: =M46-N46 -> 0 | P46: Se pone motor cabezal superior | Q46: u suario | R46: No | S46: Motores y motorreductores
A47: Enero | B47: 35028 | C47: 46041 | D47: LINEA 10 | E47: 2 | F47: 3295333 | G47: VANISH WHITE GALÓN X4 | H47: BANDA TRANSPORTADORA | I47: MD | J47: Adjustment + Breakdown | K47: 17:30 | L47: 17:50 | M47: 20 | N47: 20 | O47: =M47-N47 -> 0 | P47: ajuste en traslape paso banda salida de llenadora | Q47: Hector Valencia | R47: No | S47: Bandas, correas y cadenas (se frenan / descarrilan)
A48: Enero | B48: 35052 | C48: 46042 | D48: LINEA 20 | E48: 1 | F48: 3303107 | G48: VANSH,AR,POLVO BLANCO 120GRX24 | H48: LLENADORA | I48: ML | J48: Adjustment + Breakdown | K48: 07:00 | L48: 07:10 | M48: 10 | N48: 10 | O48: =M48-N48 -> 0 | P48: maquina con temperaturas apagadas | Q48: Marcos Saez | R48: No | S48: Máquina / mordazas apagadas (espera de calentamiento)
A49: Enero | B49: 35084 | C49: 46042 | D49: LINEA 16 | E49: 1 | F49: 3303199 | G49: VANISH POL PINK SAC 144X30GM | H49: MORDAZAS | I49: MO | J49: Adjustment + Breakdown | K49: 07:00 | L49: 07:06 | M49: 6 | N49: 6 | O49: =M49-N49 -> 0 | P49: mordazas apagadas | Q49: Cristian Santacruz | R49: No | S49: Máquina / mordazas apagadas (espera de calentamiento)
A50: Enero | B50: 35125 | C50: 46042 | D50: LINEA 22 | E50: 2 | F50: 3251827 | G50: VANSH,CO,130 ML WHITE X64 | H50: VENTOSAS | I50: VE | J50: Adjustment + Breakdown | K50: 17:10 | L50: 17:30 | M50: 20 | N50: 20 | O50: =M50-N50 -> 0 | P50: se ajusta desde la parte mecanica de apertura del sobre | Q50: Diego Garcia | R50: Sí | S50: Otras fallas
A51: Enero | B51: 35176 | C51: 46043 | D51: LINEA 10 | E51: 1 | F51: 3295333 | G51: VANISH WHITE GALÓN X4 | H51: ENCINTADORA | I51: MS | J51: Adjustment + Breakdown | K51: 08:07 | L51: 08:30 | M51: 23 | N51: 23 | O51: =M51-N51 -> 0 | P51: falla en brazo encintadora | Q51: Jordan Dawkins | R51: No | S51: Otras fallas
... A58: Enero | B58: 35407 | C58: 46045 | D58: LINEA 14 | E58: 1 | F58: 20382 | G58: MANSN,CO,DOYPACK TCOLOR500ML | H58: PARADA MENOR | I58: PM | J58: Minor Stops | K58: 10:43 | L58: 10:49 | M58: 6 | N58: 6 | O58: =M58-N58 -> 0 | P58: falta aire comprimido | Q58: Jhonier Rincon | R58: No | S58: Falta de servicios (vapor / aire)
A59: Enero | B59: 35408 | C59: 46045 | D59: LINEA 14 | E59: 1 | F59: 20382 | G59: MANSN,CO,DOYPACK TCOLOR500ML | H59: MORDAZA SUPERIOR | I59: MOS | J59: Adjustment + Breakdown | K59: 09:40 | L59: 10:00 | M59: 20 | N59: 20 | O59: =M59-N59 -> 0 | Q59: Jhonier Rincon | R59: Sí | S59: Resistencias / temperatura de mordazas
A60: Enero | B60: 35409 | C60: 46045 | D60: LINEA 14 | E60: 1 | F60: 20382 | G60: MANSN,CO,DOYPACK TCOLOR500ML | H60: MORDAZA SUPERIOR | I60: MOS | J60: Adjustment + Breakdown | K60: 10:00 | L60: 10:36 | M60: 36 | N60: 36 | O60: =M60-N60 -> 0 | Q60: Jhonier Rincon | R60: Sí | S60: Resistencias / temperatura de mordazas
A61: Enero | B61: 35422 | C61: 46045 | D61: LINEA 18 | E61: 1 | F61: 3097734 | G61: VANSH,CR,GEL BLANCO 100ML CAM | H61: FALTA DE AIRE COMPRIMIDO | I61: SD | J61: Lack of Resources | K61: 10:38 | L61: 10:43 | M61: 5 | N61: 5 | O61: =M61-N61 -> 0 | Q61: Adriana Vasquez | R61: No | S61: Falta de servicios (vapor / aire)
A62: Enero | B62: 35451 | C62: 46045 | D62: LINEA 14 | E62: 1 | F62: 3058645 | G62: SANPC,CO,HERBAL DP 445 ML | H62: MORDAZA SUPERIOR | I62: MOS | J62: Adjustment + Breakdown | K62: 14:30 | L62: 15:00 | M62: 30 | N62: 30 | O62: =M62-N62 -> 0 | P62: falla resistencia superio trasera | Q62: Jhonier Rincon | R62: No | S62: Resistencias / temperatura de mordazas
A63: Enero | B63: 35483 | C63: 46045 | D63: LINEA 10 | E63: 2 | F63: 3058100 | G63: LYSOL,CR,LAVENDER GALLON X 4 | H63: ALIMENTADOR TAPA | I63: MR | J63: Adjustment + Breakdown | K63: 22:10 | L63: 23:00 | M63: 50 | N63: 50 | O63: =M63-N63 -> 0 | P63: a las 22.10 mtto recibe maquina para instalacion de motor tolva alimentadora de tapa | Q63: Hector Valencia | R63: No | S63: Tolva tapada / ajuste de tolva
A64: Enero | B64: 35500 | C64: 46046 | D64: LINEA 19 | E64: 1 | F64: 3282079 | G64: VANSH,CO, 1800ML BLANCO X6 DP | H64: FECHADOR | I64: MK | J64: Adjustment + Breakdown | K64: 06:30 | L64: 06:52 | M64: 22 | N64: 22 | O64: =M64-N64 -> 0 | P64: falla en copilot se pega sticker manual | Q64: Jordan Dawkins | R64: No | S64: Codificador / fechador
A65: Enero | B65: 35503 | C65: 46046 | D65: LINEA 19 | E65: 1 | F65: 3282079 | G65: VANSH,CO, 1800ML BLANCO X6 DP | H65: BANDA TRANSPORTADORA | I65: MD | J65: Adjustment + Breakdown | K65: 07:20 | L65: 07:40 | M65: 20 | N65: 20 | O65: =M65-N65 -> 0 | P65: falla arrastre cadena banda azul entrada selladora | Q65: Jordan Dawkins | R65: No | S65: Servo de arrastre / encoder (falla de arrastre)
A66: Enero | B66: 35574 | C66: 46048 | D66: LINEA 22 | E66: 1 | F66: 3251828 | G66: VANSH,CO,130 ML PINK X64 | H66: MORDAZA VERTICAL | I66: MOV | J66: Adjustment + Breakdown | K66: 07:00 | L66: 09:00 | M66: 120 | N66: 120 | O66: =M66-N66 -> 0 | P66: Daño en motor de placa mordazas | Q66: Diego Garcia | R66: No | S66: Motores y motorreductores
A67: Enero | B67: 35576 | C67: 46048 | D67: LINEA 22 | E67: 1 | F67: 3251828 | G67: VANSH,CO,130 ML PINK X64 | H67: MORDAZA VERTICAL | I67: MOV | J67: Adjustment + Breakdown | K67: 09:10 | L67: 10:00 | M67: 50 | N67: 50 | O67: =M67-N67 -> 0 | P67: Daño en tarjeta motos correccion de placa mordazas | Q67: Diego Garcia | R67: No | S67: PLC, programa, drives y tarjetas electrónicas
A68: Enero | B68: 35586 | C68: 46048 | D68: LINEA 22 | E68: 1 | F68: 3251828 | G68: VANSH,CO,130 ML PINK X64 | H68: MORDAZA VERTICAL | I68: MOV | J68: Adjustment + Breakdown | K68: 11:00 | L68: 11:30 | M68: 30 | N68: 30 | O68: =M68-N68 -> 0 | P68: Daño tarjeta correccion placa mordazas | Q68: Diego Garcia | R68: No | S68: PLC, programa, drives y tarjetas electrónicas
A69: Enero | B69: 35629 | C69: 46048 | D69: LINEA 22 | E69: 2 | F69: 3251823 | G69: VANSH,CO,450ML PINKX24 | H69: DESBOBINADOR | I69: DSB | J69: Adjustment + Breakdown | K69: 16:00 | L69: 16:30 | M69: 30 | N69: 30 | O69: =M69-N69 -> 0 | P69: problema tarjeta triangulo formador | Q69: Jose Reina | R69: No | S69: PLC, programa, drives y tarjetas electrónicas
A70: Enero | B70: 35633 | C70: 46048 | D70: LINEA 22 | E70: 2 | F70: 3251823 | G70: VANSH,CO,450ML PINKX24 | H70: TIJERA | I70: TJ | J70: Adjustment + Breakdown | K70: 18:00 | L70: 18:40 | M70: 40 | N70: 40 | O70: =M70-N70 -> 0 | P70: cambio de cuchillas | Q70: Jose Reina | R70: No | S70: Tijera y cuchillas (cambio / calibración)
...

Sheet Eventos
B1: Eventos de parada agrupados
B2: Junta los registros del mismo día, la misma línea y el mismo equipo (fallas largas registradas hora por hora). Los minutos se calculan con SUMIFS sobre la hoja Datos.
B4: Mes | C4: Ranking en el mes | D4: Fecha | E4: Línea | F4: Equipo | G4: Turno | H4: Registros | I4: Minutos | J4: Horas | K4: Inicio | L4: Fin | M4: Qué pasó (observaciones)
B5: Enero | C5: 1 | D5: 46035 | E5: LINEA 18 | F5: LLENADORA | G5: 1 | H5: =COUNTIFS(Datos!$C$2:$C$319,D5,Datos!$D$2:$D$319,E5,Datos!$H$2:$H$319,F5) -> 1 | I5: =SUMIFS(Datos!$M$2:$M$319,Datos!$C$2:$C$319,D5,Datos!$D$2:$D$319,E5,Datos!$H$2:$H$319,F5) -> 480 | J5: =I5/60 -> 8 | K5: 07:00 | L5: 15:00 | M5: Arranque con acompañamiento de proyectos
B6: Enero | C6: 2 | D6: 46048 | E6: LINEA 22 | F6: MORDAZA VERTICAL | G6: 1 | H6: =COUNTIFS(Datos!$C$2:$C$319,D6,Datos!$D$2:$D$319,E6,Datos!$H$2:$H$319,F6) -> 3 | I6: =SUMIFS(Datos!$M$2:$M$319,Datos!$C$2:$C$319,D6,Datos!$D$2:$D$319,E6,Datos!$H$2:$H$319,F6) -> 200 | J6: =I6/60 -> 3.3333333 | K6: 07:00 | L6: 11:30 | M6: Daño en motor de placa mordazas / Daño en tarjeta motos correccion de placa mordazas / Daño tarjeta correccion placa mordazas
B7: Enero | C7: 3 | D7: 46024 | E7: LINEA 22 | F7: ENCINTADORA | G7: 1 | H7: =COUNTIFS(Datos!$C$2:$C$319,D7,Datos!$D$2:$D$319,E7,Datos!$H$2:$H$319,F7) -> 1 | I7: =SUMIFS(Datos!$M$2:$M$319,Datos!$C$2:$C$319,D7,Datos!$D$2:$D$319,E7,Datos!$H$2:$H$319,F7) -> 180 | J7: =I7/60 -> 3 | K7: 07:00 | L7: 10:00 | M7: Cambio de moto reductor banda entrada encintadora
B8: Enero | C8: 4 | D8: 46037 | E8: LINEA 18 | F8: FOTOCELULA | G8: 1 | H8: =COUNTIFS(Datos!$C$2:$C$319,D8,Datos!$D$2:$D$319,E8,Datos!$H$2:$H$319,F8) -> 5 | I8: =SUMIFS(Datos!$M$2:$M$319,Datos!$C$2:$C$319,D8,Datos!$D$2:$D$319,E8,Datos!$H$2:$H$319,F8) -> 177 | J8: =I8/60 -> 2.95 | K8: 09:39 | L8: 14:18 | M8: se calibra fotocelda de desbobinador / continuas paradas realizando ajustes en parametros de fotocelda de desbobinador / error en fotocelda de desbobinador / runion para reaizar plan para eliminar fallo en fotocelda de desbobinador / los tecnicos hacen ajusts en el servo
B9: Enero | C9: 5 | D9: 46035 | E9: LINEA 14 | F9: MORDAZA SUPERIOR | G9: 1 | H9: =COUNTIFS(Datos!$C$2:$C$319,D9,Datos!$D$2:$D$319,E9,Datos!$H$2:$H$319,F9) -> 3 | I9: =SUMIFS(Datos!$M$2:$M$319,Datos!$C$2:$C$319,D9,Datos!$D$2:$D$319,E9,Datos!$H$2:$H$319,F9) -> 155 | J9: =I9/60 -> 2.5833333 | K9: 09:25 | L9: 13:00 | M9: hace corto seristencia quemando esta / cambio de resistencias / se hace cambio de resistencias
B10: Enero | C10: 5 | D10: 46041 | E10: LINEA 10 | F10: BANDA TRANSPORTADORA | G10: 2 | H10: =COUNTIFS(Datos!$C$2:$C$319,D10,Datos!$D$2:$D$319,E10,Datos!$H$2:$H$319,F10) -> 4 | I10: =SUMIFS(Datos!$M$2:$M$319,Datos!$C$2:$C$319,D10,Datos!$D$2:$D$319,E10,Datos!$H$2:$H$319,F10) -> 155 | J10: =I10/60 -> 2.5833333 | K10: 15:00 | L10: 17:50 | M10: espera entega de mtto banda ttransporte tapa wollite hacia tapadora / mtto ajusyta banda para empezar proceso / cambio de direccion banda elevador de tapa / ajuste en traslape paso banda salida de llenadora
B11: Enero | C11: 7 | D11: 46044 | E11: LINEA 14 | F11: LLENADORA | G11: 1 | H11: =COUNTIFS(Datos!$C$2:$C$319,D11,Datos!$D$2:$D$319,E11,Datos!$H$2:$H$319,F11) -> 3 | I11: =SUMIFS(Datos!$M$2:$M$319,Datos!$C$2:$C$319,D11,Datos!$D$2:$D$319,E11,Datos!$H$2:$H$319,F11) -> 86 | J11: =I11/60 -> 1.4333333 | K11: 08:40 | L11: 11:12 | M11: personal de mtto realiza intervencion en maquina por falla en programacion para operacion de maquina con jog
B12: Enero | C12: 7 | D12: 46045 | E12: LINEA 14 | F12: MORDAZA SUPERIOR | G12: 1 | H12: =COUNTIFS(Datos!$C$2:$C$319,D12,Datos!$D$2:$D$319,E12,Datos!$H$2:$H$319,F12) -> 3 | I12: =SUMIFS(Datos!$M$2:$M$319,Datos!$C$2:$C$319,D12,Datos!$D$2:$D$319,E12,Datos!$H$2:$H$319,F12) -> 86 | J12: =I12/60 -> 1.4333333 | K12: 09:40 | L12: 15:00 | M12: falla resistencia superio trasera
B13: Enero | C13: 9 | D13: 46038 | E13: LINEA 18 | F13: LLENADORA | G13: 1 | H13: =COUNTIFS(Datos!$C$2:$C$319,D13,Datos!$D$2:$D$319,E13,Datos!$H$2:$H$319,F13) -> 4 | I13: =SUMIFS(Datos!$M$2:$M$319,Datos!$C$2:$C$319,D13,Datos!$D$2:$D$319,E13,Datos!$H$2:$H$319,F13) -> 76 | J13: =I13/60 -> 1.2666667 | K13: 08:52 | L13: 14:47 | M13: paradas por falla en el drive de boquilla se hace seguimiento / falla de variador drive boquilas, se hacen ajustes / continuas paradas por falla en el drive de boquillas de llenado / continuas paradas por falla en el drive de boquillas
B14: Enero | C14: 10 | D14: 46049 | E14: LINEA 19 | F14: ENCINTADORA | G14: 1 | H14: =COUNTIFS(Datos!$C$2:$C$319,D14,Datos!$D$2:$D$319,E14,Datos!$H$2:$H$319,F14) -> 2 | I14: =SUMIFS(Datos!$M$2:$M$319,Datos!$C$2:$C$319,D14,Datos!$D$2:$D$319,E14,Datos!$H$2:$H$319,F14) -> 75 | J14: =I14/60 -> 1.25 | K14: 11:07 | L14: 12:52 | M14: se revienta correa lateral encintadora. / cambio de correa encintadora
B15: Enero | C15: 11 | D15: 46036 | E15: LINEA 18 | F15: DESBOBINADOR | G15: 1 | H15: =COUNTIFS(Datos!$C$2:$C$319,D15,Datos!$D$2:$D$319,E15,Datos!$H$2:$H$319,F15) -> 3 | I15: =SUMIFS(Datos!$M$2:$M$319,Datos!$C$2:$C$319,D15,Datos!$D$2:$D$319,E15,Datos!$H$2:$H$319,F15) -> 74 | J15: =I15/60 -> 1.2333333 | K15: 11:32 | L15: 13:30 | M15: continuas paradas por falla en el deslizamineto de laminado desbobinador
B16: Enero | C16: 12 | D16: 46028 | E16: LINEA 20 | F16: LLENADORA | G16: 1 | H16: =COUNTIFS(Datos!$C$2:$C$319,D16,Datos!$D$2:$D$319,E16,Datos!$H$2:$H$319,F16) -> 3 | I16: =SUMIFS(Datos!$M$2:$M$319,Datos!$C$2:$C$319,D16,Datos!$D$2:$D$319,E16,Datos!$H$2:$H$319,F16) -> 70 | J16: =I16/60 -> 1.1666667 | K16: 07:50 | L16: 09:45 | M16: daño banda de salida de la llenadora / cambio de seguidor
... B189: Julio | C189: 40 | D189: 46232 | E189: LINEA 22 | F189: BANDA TRANSPORTADORA | G189: 1 | H189: =COUNTIFS(Datos!$C$2:$C$319,D189,Datos!$D$2:$D$319,E189,Datos!$H$2:$H$319,F189) -> 1 | I189: =SUMIFS(Datos!$M$2:$M$319,Datos!$C$2:$C$319,D189,Datos!$D$2:$D$319,E189,Datos!$H$2:$H$319,F189) -> 4 | J189: =I189/60 -> 0.066666667 | K189: 12:43 | L189: 12:47 | M189: Se frena banda de salida llenadora

Sheet Top 3 por mes
B1: Las 3 paradas más largas de cada mes
B2: Eventos agrupados (mismo día, línea y equipo). En julio hay empate en el 3er lugar (90 min), por eso aparecen 4.
B4: ENERO
B5: # | C5: Fecha | D5: Línea | E5: Equipo | F5: Registros | G5: Minutos | H5: Horas | I5: % del mes | J5: Qué pasó
B6: 1 | C6: 46035 | D6: LINEA 18 | E6: LLENADORA | F6: =COUNTIFS(Datos!$C$2:$C$319,C6,Datos!$D$2:$D$319,D6,Datos!$H$2:$H$319,E6) -> 1 | G6: =SUMIFS(Datos!$M$2:$M$319,Datos!$C$2:$C$319,C6,Datos!$D$2:$D$319,D6,Datos!$H$2:$H$319,E6) -> 480 | H6: =G6/60 -> 8 | I6: =G6/SUMIFS(Datos!$M$2:$M$319,Datos!$A$2:$A$319,"Enero") -> 0.17253774 | J6: Arranque con acompañamiento de proyectos
B7: 2 | C7: 46048 | D7: LINEA 22 | E7: MORDAZA VERTICAL | F7: =COUNTIFS(Datos!$C$2:$C$319,C7,Datos!$D$2:$D$319,D7,Datos!$H$2:$H$319,E7) -> 3 | G7: =SUMIFS(Datos!$M$2:$M$319,Datos!$C$2:$C$319,C7,Datos!$D$2:$D$319,D7,Datos!$H$2:$H$319,E7) -> 200 | H7: =G7/60 -> 3.3333333 | I7: =G7/SUMIFS(Datos!$M$2:$M$319,Datos!$A$2:$A$319,"Enero") -> 0.071890726 | J7: Daño en motor de placa mordazas / Daño en tarjeta motos correccion de placa mordazas / Daño tarjeta correccion placa mordazas
B8: 3 | C8: 46024 | D8: LINEA 22 | E8: ENCINTADORA | F8: =COUNTIFS(Datos!$C$2:$C$319,C8,Datos!$D$2:$D$319,D8,Datos!$H$2:$H$319,E8) -> 1 | G8: =SUMIFS(Datos!$M$2:$M$319,Datos!$C$2:$C$319,C8,Datos!$D$2:$D$319,D8,Datos!$H$2:$H$319,E8) -> 180 | H8: =G8/60 -> 3 | I8: =G8/SUMIFS(Datos!$M$2:$M$319,Datos!$A$2:$A$319,"Enero") -> 0.064701653 | J8: Cambio de moto reductor banda entrada encintadora
B10: MAYO
B11: # | C11: Fecha | D11: Línea | E11: Equipo | F11: Registros | G11: Minutos | H11: Horas | I11: % del mes | J11: Qué pasó
B12: 1 | C12: 46164 | D12: LINEA 16 | E12: SERVO MOTOR | F12: =COUNTIFS(Datos!$C$2:$C$319,C12,Datos!$D$2:$D$319,D12,Datos!$H$2:$H$319,E12) -> 8 | G12: =SUMIFS(Datos!$M$2:$M$319,Datos!$C$2:$C$319,C12,Datos!$D$2:$D$319,D12,Datos!$H$2:$H$319,E12) -> 420 | H12: =G12/60 -> 7 | I12: =G12/SUMIFS(Datos!$M$2:$M$319,Datos!$A$2:$A$319,"Mayo") -> 0.092633436 | J12: (sin observación)
B13: 2 | C13: 46165 | D13: LINEA 16 | E13: SERVO MOTOR | F13: =COUNTIFS(Datos!$C$2:$C$319,C13,Datos!$D$2:$D$319,D13,Datos!$H$2:$H$319,E13) -> 1 | G13: =SUMIFS(Datos!$M$2:$M$319,Datos!$C$2:$C$319,C13,Datos!$D$2:$D$319,D13,Datos!$H$2:$H$319,E13) -> 400 | H13: =G13/60 -> 6.6666667 | I13: =G13/SUMIFS(Datos!$M$2:$M$319,Datos!$A$2:$A$319,"Mayo") -> 0.08822232 | J13: falla en servo
B14: 3 | C14: 46158 | D14: LINEA 16 | E14: LLENADORA | F14: =COUNTIFS(Datos!$C$2:$C$319,C14,Datos!$D$2:$D$319,D14,Datos!$H$2:$H$319,E14) -> 6 | G14: =SUMIFS(Datos!$M$2:$M$319,Datos!$C$2:$C$319,C14,Datos!$D$2:$D$319,D14,Datos!$H$2:$H$319,E14) -> 348 | H14: =G14/60 -> 5.8 | I14: =G14/SUMIFS(Datos!$M$2:$M$319,Datos!$A$2:$A$319,"Mayo") -> 0.076753419 | J14: falla encoder / encoder / ender
B16: JUNIO
B17: # | C17: Fecha | D17: Línea | E17: Equipo | F17: Registros | G17: Minutos | H17: Horas | I17: % del mes | J17: Qué pasó
B18: 1 | C18: 46184 | D18: LINEA 10 | E18: BANDA TRANSPORTADORA | F18: =COUNTIFS(Datos!$C$2:$C$319,C18,Datos!$D$2:$D$319,D18,Datos!$H$2:$H$319,E18) -> 1 | G18: =SUMIFS(Datos!$M$2:$M$319,Datos!$C$2:$C$319,C18,Datos!$D$2:$D$319,D18,Datos!$H$2:$H$319,E18) -> 440 | H18: =G18/60 -> 7.3333333 | I18: =G18/SUMIFS(Datos!$M$2:$M$319,Datos!$A$2:$A$319,"Junio") -> 0.15130674 | J18: intervencion bandas.
B19: 2 | C19: 46193 | D19: LINEA 16 | E19: LLENADORA | F19: =COUNTIFS(Datos!$C$2:$C$319,C19,Datos!$D$2:$D$319,D19,Datos!$H$2:$H$319,E19) -> 7 | G19: =SUMIFS(Datos!$M$2:$M$319,Datos!$C$2:$C$319,C19,Datos!$D$2:$D$319,D19,Datos!$H$2:$H$319,E19) -> 334 | H19: =G19/60 -> 5.5666667 | I19: =G19/SUMIFS(Datos!$M$2:$M$319,Datos!$A$2:$A$319,"Junio") -> 0.11485557 | J19: falla de arrastre / faklla de arrastre
B20: 3 | C20: 46198 | D20: LINEA 20 | E20: LLENADORA | F20: =COUNTIFS(Datos!$C$2:$C$319,C20,Datos!$D$2:$D$319,D20,Datos!$H$2:$H$319,E20) -> 7 | G20: =SUMIFS(Datos!$M$2:$M$319,Datos!$C$2:$C$319,C20,Datos!$D$2:$D$319,D20,Datos!$H$2:$H$319,E20) -> 230 | H20: =G20/60 -> 3.8333333 | I20: =G20/SUMIFS(Datos!$M$2:$M$319,Datos!$A$2:$A$319,"Junio") -> 0.07909216 | J20: falla electrica / ajuste de rif por falta de tencion en el laminado / falla variador desbobinador zipper / falla de varioador desbobinador zipper
B22: JULIO
B23: # | C23: Fecha | D23: Línea | E23: Equipo | F23: Registros | G23: Minutos | H23: Horas | I23: % del mes | J23: Qué pasó
B24: 1 | C24: 46231 | D24: LINEA 20 | E24: LLENADORA | F24: =COUNTIFS(Datos!$C$2:$C$319,C24,Datos!$D$2:$D$319,D24,Datos!$H$2:$H$319,E24) -> 4 | G24: =SUMIFS(Datos!$M$2:$M$319,Datos!$C$2:$C$319,C24,Datos!$D$2:$D$319,D24,Datos!$H$2:$H$319,E24) -> 270 | H24: =G24/60 -> 4.5 | I24: =G24/SUMIFS(Datos!$M$2:$M$319,Datos!$A$2:$A$319,"Julio") -> 0.15219842 | J24: Lado izquierdo de tolva tapado. / Lado izquierdo de tolva tapado
B25: 2 | C25: 46218 | D25: LINEA 14 | E25: LLENADORA | F25: =COUNTIFS(Datos!$C$2:$C$319,C25,Datos!$D$2:$D$319,D25,Datos!$H$2:$H$319,E25) -> 4 | G25: =SUMIFS(Datos!$M$2:$M$319,Datos!$C$2:$C$319,C25,Datos!$D$2:$D$319,D25,Datos!$H$2:$H$319,E25) -> 191 | H25: =G25/60 -> 3.1833333 | I25: =G25/SUMIFS(Datos!$M$2:$M$319,Datos!$A$2:$A$319,"Julio") -> 0.10766629 | J25: Falla en Clapet / Cambio de cilindro Clapet tapón
B26: 3 | C26: 46207 | D26: LINEA 02 | E26: EHS | F26: =COUNTIFS(Datos!$C$2:$C$319,C26,Datos!$D$2:$D$319,D26,Datos!$H$2:$H$319,E26) -> 2 | G26: =SUMIFS(Datos!$M$2:$M$319,Datos!$C$2:$C$319,C26,Datos!$D$2:$D$319,D26,Datos!$H$2:$H$319,E26) -> 90 | H26: =G26/60 -> 1.5 | I26: =G26/SUMIFS(Datos!$M$2:$M$319,Datos!$A$2:$A$319,"Julio") -> 0.050732807 | J26: se espera la siso para para protocolos de intervencion trabajo en caliente / intervencion en caliente
B27: 3 | C27: 46209 | D27: LINEA 14 | E27: ALIMENTADOR TAPON | F27: =COUNTIFS(Datos!$C$2:$C$319,C27,Datos!$D$2:$D$319,D27,Datos!$H$2:$H$319,E27) -> 2 | G27: =SUMIFS(Datos!$M$2:$M$319,Datos!$C$2:$C$319,C27,Datos!$D$2:$D$319,D27,Datos!$H$2:$H$319,E27) -> 90 | H27: =G27/60 -> 1.5 | I27: =G27/SUMIFS(Datos!$M$2:$M$319,Datos!$A$2:$A$319,"Julio") -> 0.050732807 | J27: se realiza montaje del clapet y ajuste de tiempos de sincronismo / se rectifica rosca de cilindro de la pinza de sujeccion tapon

Sheet Top 3 líneas
B1: Las 3 líneas con más tiempo parado por mes
B2: Con el equipo que más tiempo le quitó y lo que más se repitió.
B4: ENERO
B5: # | C5: Línea | D5: Paradas | E5: Minutos | F5: % del mes | G5: Equipo principal | H5: Min. equipo | I5: Causa más repetida
B6: 1 | C6: LINEA 18 | D6: =COUNTIFS(Datos!$A$2:$A$319,"Enero",Datos!$D$2:$D$319,C6) -> 23 | E6: =SUMIFS(Datos!$M$2:$M$319,Datos!$A$2:$A$319,"Enero",Datos!$D$2:$D$319,C6) -> 945 | F6: =E6/SUMIFS(Datos!$M$2:$M$319,Datos!$A$2:$A$319,"Enero") -> 0.33968368 | G6: LLENADORA | H6: =SUMIFS(Datos!$M$2:$M$319,Datos!$A$2:$A$319,"Enero",Datos!$D$2:$D$319,C6,Datos!$H$2:$H$319,G6) -> 624 | I6: Arranque con acompañamiento de proyectos
B7: 2 | C7: LINEA 14 | D7: =COUNTIFS(Datos!$A$2:$A$319,"Enero",Datos!$D$2:$D$319,C7) -> 18 | E7: =SUMIFS(Datos!$M$2:$M$319,Datos!$A$2:$A$319,"Enero",Datos!$D$2:$D$319,C7) -> 599 | F7: =E7/SUMIFS(Datos!$M$2:$M$319,Datos!$A$2:$A$319,"Enero") -> 0.21531272 | G7: MORDAZA SUPERIOR | H7: =SUMIFS(Datos!$M$2:$M$319,Datos!$A$2:$A$319,"Enero",Datos!$D$2:$D$319,C7,Datos!$H$2:$H$319,G7) -> 348 | I7: Cambio de resistencias
B8: 3 | C8: LINEA 22 | D8: =COUNTIFS(Datos!$A$2:$A$319,"Enero",Datos!$D$2:$D$319,C8) -> 9 | E8: =SUMIFS(Datos!$M$2:$M$319,Datos!$A$2:$A$319,"Enero",Datos!$D$2:$D$319,C8) -> 489 | F8: =E8/SUMIFS(Datos!$M$2:$M$319,Datos!$A$2:$A$319,"Enero") -> 0.17577283 | G8: MORDAZA VERTICAL | H8: =SUMIFS(Datos!$M$2:$M$319,Datos!$A$2:$A$319,"Enero",Datos!$D$2:$D$319,C8,Datos!$H$2:$H$319,G8) -> 200 | I8: Daño en motor de placa mordazas
B10: MAYO
B11: # | C11: Línea | D11: Paradas | E11: Minutos | F11: % del mes | G11: Equipo principal | H11: Min. equipo | I11: Causa más repetida
B12: 1 | C12: LINEA 16 | D12: =COUNTIFS(Datos!$A$2:$A$319,"Mayo",Datos!$D$2:$D$319,C12) -> 49 | E12: =SUMIFS(Datos!$M$2:$M$319,Datos!$A$2:$A$319,"Mayo",Datos!$D$2:$D$319,C12) -> 2458 | F12: =E12/SUMIFS(Datos!$M$2:$M$319,Datos!$A$2:$A$319,"Mayo") -> 0.54212616 | G12: SERVO MOTOR | H12: =SUMIFS(Datos!$M$2:$M$319,Datos!$A$2:$A$319,"Mayo",Datos!$D$2:$D$319,C12,Datos!$H$2:$H$319,G12) -> 1417 | I12: Falla de arrastre
B13: 2 | C13: LINEA 02 | D13: =COUNTIFS(Datos!$A$2:$A$319,"Mayo",Datos!$D$2:$D$319,C13) -> 15 | E13: =SUMIFS(Datos!$M$2:$M$319,Datos!$A$2:$A$319,"Mayo",Datos!$D$2:$D$319,C13) -> 692 | F13: =E13/SUMIFS(Datos!$M$2:$M$319,Datos!$A$2:$A$319,"Mayo") -> 0.15262461 | G13: LLENADORA | H13: =SUMIFS(Datos!$M$2:$M$319,Datos!$A$2:$A$319,"Mayo",Datos!$D$2:$D$319,C13,Datos!$H$2:$H$319,G13) -> 323 | I13: Se parte pin del introdutor
B14: 3 | C14: LINEA 10 | D14: =COUNTIFS(Datos!$A$2:$A$319,"Mayo",Datos!$D$2:$D$319,C14) -> 19 | E14: =SUMIFS(Datos!$M$2:$M$319,Datos!$A$2:$A$319,"Mayo",Datos!$D$2:$D$319,C14) -> 549 | F14: =E14/SUMIFS(Datos!$M$2:$M$319,Datos!$A$2:$A$319,"Mayo") -> 0.12108513 | G14: ENCAJADORA | H14: =SUMIFS(Datos!$M$2:$M$319,Datos!$A$2:$A$319,"Mayo",Datos!$D$2:$D$319,C14,Datos!$H$2:$H$319,G14) -> 217 | I14: Arreglo de pieza freno se cambioan ´piezas en taller.
B16: JUNIO
B17: # | C17: Línea | D17: Paradas | E17: Minutos | F17: % del mes | G17: Equipo principal | H17: Min. equipo | I17: Causa más repetida
B18: 1 | C18: LINEA 16 | D18: =COUNTIFS(Datos!$A$2:$A$319,"Junio",Datos!$D$2:$D$319,C18) -> 15 | E18: =SUMIFS(Datos!$M$2:$M$319,Datos!$A$2:$A$319,"Junio",Datos!$D$2:$D$319,C18) -> 774 | F18: =E18/SUMIFS(Datos!$M$2:$M$319,Datos!$A$2:$A$319,"Junio") -> 0.26616231 | G18: LLENADORA | H18: =SUMIFS(Datos!$M$2:$M$319,Datos!$A$2:$A$319,"Junio",Datos!$D$2:$D$319,C18,Datos!$H$2:$H$319,G18) -> 774 | I18: Falla de arrastre
B19: 2 | C19: LINEA 10 | D19: =COUNTIFS(Datos!$A$2:$A$319,"Junio",Datos!$D$2:$D$319,C19) -> 2 | E19: =SUMIFS(Datos!$M$2:$M$319,Datos!$A$2:$A$319,"Junio",Datos!$D$2:$D$319,C19) -> 498 | F19: =E19/SUMIFS(Datos!$M$2:$M$319,Datos!$A$2:$A$319,"Junio") -> 0.17125172 | G19: BANDA TRANSPORTADORA | H19: =SUMIFS(Datos!$M$2:$M$319,Datos!$A$2:$A$319,"Junio",Datos!$D$2:$D$319,C19,Datos!$H$2:$H$319,G19) -> 498 | I19: Intervencion bandas.
B20: 3 | C20: LINEA 02 | D20: =COUNTIFS(Datos!$A$2:$A$319,"Junio",Datos!$D$2:$D$319,C20) -> 16 | E20: =SUMIFS(Datos!$M$2:$M$319,Datos!$A$2:$A$319,"Junio",Datos!$D$2:$D$319,C20) -> 483 | F20: =E20/SUMIFS(Datos!$M$2:$M$319,Datos!$A$2:$A$319,"Junio") -> 0.16609354 | G20: LLENADORA | H20: =SUMIFS(Datos!$M$2:$M$319,Datos!$A$2:$A$319,"Junio",Datos!$D$2:$D$319,C20,Datos!$H$2:$H$319,G20) -> 218 | I20: Mal funcionamiento boquilla #4 por goteo, se baja la boquilla
B22: JULIO
B23: # | C23: Línea | D23: Paradas | E23: Minutos | F23: % del mes | G23: Equipo principal | H23: Min. equipo | I23: Causa más repetida
B24: 1 | C24: LINEA 14 | D24: =COUNTIFS(Datos!$A$2:$A$319,"Julio",Datos!$D$2:$D$319,C24) -> 11 | E24: =SUMIFS(Datos!$M$2:$M$319,Datos!$A$2:$A$319,"Julio",Datos!$D$2:$D$319,C24) -> 438 | F24: =E24/SUMIFS(Datos!$M$2:$M$319,Datos!$A$2:$A$319,"Julio") -> 0.24689966 | G24: LLENADORA | H24: =SUMIFS(Datos!$M$2:$M$319,Datos!$A$2:$A$319,"Julio",Datos!$D$2:$D$319,C24,Datos!$H$2:$H$319,G24) -> 191 | I24: Falla en clapet
B25: 2 | C25: LINEA 02 | D25: =COUNTIFS(Datos!$A$2:$A$319,"Julio",Datos!$D$2:$D$319,C25) -> 10 | E25: =SUMIFS(Datos!$M$2:$M$319,Datos!$A$2:$A$319,"Julio",Datos!$D$2:$D$319,C25) -> 398 | F25: =E25/SUMIFS(Datos!$M$2:$M$319,Datos!$A$2:$A$319,"Julio") -> 0.22435175 | G25: ENFAJADORA | H25: =SUMIFS(Datos!$M$2:$M$319,Datos!$A$2:$A$319,"Julio",Datos!$D$2:$D$319,C25,Datos!$H$2:$H$319,G25) -> 120 | I25: La enfajadora no funciona
B26: 3 | C26: LINEA 20 | D26: =COUNTIFS(Datos!$A$2:$A$319,"Julio",Datos!$D$2:$D$319,C26) -> 6 | E26: =SUMIFS(Datos!$M$2:$M$319,Datos!$A$2:$A$319,"Julio",Datos!$D$2:$D$319,C26) -> 312 | F26: =E26/SUMIFS(Datos!$M$2:$M$319,Datos!$A$2:$A$319,"Julio") -> 0.17587373 | G26: LLENADORA | H26: =SUMIFS(Datos!$M$2:$M$319,Datos!$A$2:$A$319,"Julio",Datos!$D$2:$D$319,C26,Datos!$H$2:$H$319,G26) -> 270 | I26: Lado izquierdo de tolva tapado

Sheet Calidad de datos
B1: Registros a revisar
B2: Filas donde el TIEMPO PARADA no coincide con INICIO–FIN, o que no tienen observación.
B4: Mes | C4: Id | D4: Fecha | E4: Línea | F4: Equipo | G4: Inicio | H4: Fin | I4: Tiempo registrado | J4: Min. según horario | K4: Problema
B5: Enero | C5: 34877 | D5: 46039 | E5: LINEA 19 | F5: ENCINTADORA | G5: 09:00 | H5: 09:25 | I5: 25 | J5: 25 | K5: Sin observación
B6: Enero | C6: 35408 | D6: 46045 | E6: LINEA 14 | F6: MORDAZA SUPERIOR | G6: 09:40 | H6: 10:00 | I6: 20 | J6: 20 | K6: Sin observación
B7: Enero | C7: 35409 | D7: 46045 | E7: LINEA 14 | F7: MORDAZA SUPERIOR | G7: 10:00 | H7: 10:36 | I7: 36 | J7: 36 | K7: Sin observación
B8: Enero | C8: 35422 | D8: 46045 | E8: LINEA 18 | F8: FALTA DE AIRE COMPRIMIDO | G8: 10:38 | H8: 10:43 | I8: 5 | J8: 5 | K8: Sin observación
B9: Enero | C9: 35748 | D9: 46050 | E9: LINEA 03 | F9: LLENADORA | G9: 10:00 | H9: 11:00 | I9: 12 | J9: 60 | K9: Tiempo no coincide con el horario
B10: Enero | C10: 35823 | D10: 46051 | E10: LINEA 14 | F10: ENCINTADORA | G10: 08:00 | H10: 08:44 | I10: 44 | J10: 44 | K10: Sin observación
B11: Enero | C11: 35912 | D11: 46052 | E11: LINEA 19 | F11: BANDA TRANSPORTADORA | G11: 13:00 | H11: 13:14 | I11: 14 | J11: 14 | K11: Sin observación
B12: Mayo | C12: 42962 | D12: 46146 | E12: LINEA 11 | F12: SISTEMA SUCCION - OGA | G12: 17:15 | H12: 17:27 | I12: 12 | J12: 12 | K12: Sin observación
B13: Mayo | C13: 42963 | D13: 46146 | E13: LINEA 11 | F13: SISTEMA SUCCION - OGA | G13: 22:00 | H13: 22:16 | I13: 16 | J13: 16 | K13: Sin observación
B14: Mayo | C14: 44137 | D14: 46157 | E14: LINEA 10 | F14: ENCAJADORA | G14: 08:21 | H14: 08:35 | I14: 14 | J14: 14 | K14: Sin observación
B15: Mayo | C15: 44405 | D15: 46161 | E15: LINEA 10 | F15: FALTA PERSONAL | G15: 09:40 | H15: 09:56 | I15: 16 | J15: 16 | K15: Sin observación
B16: Mayo | C16: 44458 | D16: 46161 | E16: LINEA 16 | F16: SERVO MOTOR | G16: 14:45 | H16: 15:00 | I16: 15 | J16: 15 | K16: Sin observación
... B42: Julio | C42: 50155 | D42: 46231 | E42: LINEA 20 | F42: LLENADORA | G42: 21:00 | H42: 21:30 | I42: 60 | J42: 30 | K42: Tiempo no coincide con el horario
