Workbook

Sheet Tablero
B1: Monitoreo de Energía
B2: Data Log de medidores de planta · horas en hora de Colombia (los medidores en UTC se corrigen −5 h)
B4: DÍA | D4: HORA DE CORTE 24 h | F4: MEDIDOR PARA LA GRÁFICA DE 15 MIN
B5: 46304 | D5: 0.45833333 | F5: Estación celda 1 | I5: =IFERROR(INDEX(Medidores!$A:$A,MATCH($F$5,Medidores!$B:$B,0)),"") -> 192.168.50.11
B7: CONSUMO DEL PERIODO (kWh) | D7: DEMANDA MEDIA TOTAL (kW) | G7: CONSUMO 24 h AL CORTE (kWh) | J7: FACTOR DE POTENCIA | M7: MEDIDORES CON AVISO
B8: =SUMPRODUCT(W12:W21,H12:H21) -> 1326.727 | D8: =SUMPRODUCT(W12:W21,K12:K21) -> 279.31095 | G8: =IF(COUNT(P12:P21)=0,"Falta el día anterior",SUMPRODUCT(X12:X21,P12:P21)) -> 4514.008 | J8: =IFERROR(SUMPRODUCT(W12:W21*ISNUMBER(L12:L21),H12:H21)/SUMPRODUCT(W12:W21*ISNUMBER(L12:L21),J12:J21),"") -> 0.91047696 | M8: =COUNTIF(D12:D21,"<>Normal")&" de "&COUNTA(C12:C21) -> 3 de 10
B11: Línea | C11: IP | D11: Estado | E11: Desde | F11: Hasta | G11: Lecturas | H11: kWh | I11: kVARh | J11: kVAh | K11: kW medio | L11: FP | M11: kVARh / kWh | N11: kW máx 15 min | O11: Hora kW máx | P11: kWh 24 h al corte | Q11: kW medio vs día anterior | R11: Última lectura kWh | S11: válidas | T11: en cero | U11: con kVAh | V11: kW medio día ant. | W11: suma periodo | X11: suma 24 h
B12: =Medidores!B2 -> L50 | C12: =Medidores!A2 -> 192.168.50.3 | D12: =IF(S12<2,"Sin datos",IF(T12>0,"Lectura en cero",IF(U12<2,"Falta kVAh",IF(H12<=0.001,"Sin consumo",IF(AND(ISNUMBER(M12),M12>0.5),"Reactiva > 50 %","Normal"))))) -> Normal | E12: =IF(S12<2,"",_xlfn.MINIFS(Datos!$G:$G,Datos!$B:$B,$C12,Datos!$A:$A,$B$5,Datos!$D:$D,">0")/1440) -> 0.375 | F12: =IF(S12<2,"",_xlfn.MAXIFS(Datos!$G:$G,Datos!$B:$B,$C12,Datos!$A:$A,$B$5,Datos!$D:$D,">0")/1440) -> 0.57291667 | G12: =COUNTIFS(Datos!$B:$B,$C12,Datos!$A:$A,$B$5) -> 20 | H12: =IF(S12<2,"",_xlfn.MAXIFS(Datos!$D:$D,Datos!$B:$B,$C12,Datos!$A:$A,$B$5,Datos!$D:$D,">0")-_xlfn.MINIFS(Datos!$D:$D,Datos!$B:$B,$C12,Datos!$A:$A,$B$5,Datos!$D:$D,">0")) -> 2.965 | I12: =IF(S12<2,"",_xlfn.MAXIFS(Datos!$E:$E,Datos!$B:$B,$C12,Datos!$A:$A,$B$5,Datos!$D:$D,">0")-_xlfn.MINIFS(Datos!$E:$E,Datos!$B:$B,$C12,Datos!$A:$A,$B$5,Datos!$D:$D,">0")) -> 0 | J12: =IF(U12<2,"",_xlfn.MAXIFS(Datos!$F:$F,Datos!$B:$B,$C12,Datos!$A:$A,$B$5,Datos!$F:$F,">0")-_xlfn.MINIFS(Datos!$F:$F,Datos!$B:$B,$C12,Datos!$A:$A,$B$5,Datos!$F:$F,">0")) -> 3.082 | K12: =IF(H12="","",IF(F12>E12,H12/((F12-E12)*24),"")) -> 0.62421053 | L12: =IF(OR(H12="",J12=""),"",IF(J12>0,H12/J12,"")) -> 0.96203764 | M12: =IF(OR(H12="",I12=""),"",IF(H12>0,I12/H12,"")) -> 0 | N12: =IF(S12<2,"",_xlfn.MAXIFS(Datos!$H:$H,Datos!$B:$B,$C12,Datos!$A:$A,$B$5)) -> 0.628 | O12: =IF(N12="","",_xlfn.MINIFS(Datos!$G:$G,Datos!$B:$B,$C12,Datos!$A:$A,$B$5,Datos!$H:$H,N12)/1440) -> 0.44791667 | P12: =IF(OR(COUNTIFS(Datos!$B:$B,$C12,Datos!$A:$A,$B$5,Datos!$D:$D,">0",Datos!$G:$G,(HOUR($D$5)*60+MINUTE($D$5)))=0,COUNTIFS(Datos!$B:$B,$C12,Datos!$A:$A,$B$5-1,Datos!$D:$D,">0",Datos!$G:$G,(HOUR($D$5)*60+MINUTE($D$5)))=0),"",SUMIFS(Datos!$D:$D,Datos!$B:$B,$C12,Datos!$A:$A,$B$5,Datos!$D:$D,">0",Datos!$G:$G,(HOUR($D$5)*60+MINUTE($D$5)))-SUMIFS(Datos!$D:$D,Datos!$B:$B,$C12,Datos!$A:$A,$B$5-1,Datos!$D:$D,">0",Datos!$G:$G,(HOUR($D$5)*60+MINUTE($D$5)))) -> 31.341 | Q12: =IF(OR(K12="",V12=""),"",IF(V12>0,K12/V12-1,"")) -> -0.068781407 | R12: =IF(S12=0,"",_xlfn.MAXIFS(Datos!$D:$D,Datos!$B:$B,$C12,Datos!$A:$A,$B$5,Datos!$D:$D,">0")) -> 8766.844 | S12: =COUNTIFS(Datos!$B:$B,$C12,Datos!$A:$A,$B$5,Datos!$D:$D,">0") -> 20 | T12: =COUNTIFS(Datos!$B:$B,$C12,Datos!$A:$A,$B$5,Datos!$D:$D,0) -> 0 | U12: =COUNTIFS(Datos!$B:$B,$C12,Datos!$A:$A,$B$5,Datos!$F:$F,">0") -> 20 | V12: =IF(COUNTIFS(Datos!$B:$B,$C12,Datos!$A:$A,$B$5-1,Datos!$D:$D,">0")<2,"",IFERROR((_xlfn.MAXIFS(Datos!$D:$D,Datos!$B:$B,$C12,Datos!$A:$A,$B$5-1,Datos!$D:$D,">0")-_xlfn.MINIFS(Datos!$D:$D,Datos!$B:$B,$C12,Datos!$A:$A,$B$5-1,Datos!$D:$D,">0"))/((_xlfn.MAXIFS(Datos!$G:$G,Datos!$B:$B,$C12,Datos!$A:$A,$B$5-1,Datos!$D:$D,">0")-_xlfn.MINIFS(Datos!$G:$G,Datos!$B:$B,$C12,Datos!$A:$A,$B$5-1,Datos!$D:$D,">0"))/60),"")) -> 0.67031579 | W12: =IF(Medidores!C2="",1,IFERROR(IF(INDEX($H$12:$H$21,MATCH(Medidores!C2,$C$12:$C$21,0))="",1,0),1)) -> 0 | X12: =IF(Medidores!C2="",1,IFERROR(IF(INDEX($P$12:$P$21,MATCH(Medidores!C2,$C$12:$C$21,0))="",1,0),1)) -> 0
B13: =Medidores!B3 -> L21 | C13: =Medidores!A3 -> 192.168.50.4 | D13: =IF(S13<2,"Sin datos",IF(T13>0,"Lectura en cero",IF(U13<2,"Falta kVAh",IF(H13<=0.001,"Sin consumo",IF(AND(ISNUMBER(M13),M13>0.5),"Reactiva > 50 %","Normal"))))) -> Normal | E13: =IF(S13<2,"",_xlfn.MINIFS(Datos!$G:$G,Datos!$B:$B,$C13,Datos!$A:$A,$B$5,Datos!$D:$D,">0")/1440) -> 0.38541667 | F13: =IF(S13<2,"",_xlfn.MAXIFS(Datos!$G:$G,Datos!$B:$B,$C13,Datos!$A:$A,$B$5,Datos!$D:$D,">0")/1440) -> 0.58333333 | G13: =COUNTIFS(Datos!$B:$B,$C13,Datos!$A:$A,$B$5) -> 20 | H13: =IF(S13<2,"",_xlfn.MAXIFS(Datos!$D:$D,Datos!$B:$B,$C13,Datos!$A:$A,$B$5,Datos!$D:$D,">0")-_xlfn.MINIFS(Datos!$D:$D,Datos!$B:$B,$C13,Datos!$A:$A,$B$5,Datos!$D:$D,">0")) -> 2.958 | I13: =IF(S13<2,"",_xlfn.MAXIFS(Datos!$E:$E,Datos!$B:$B,$C13,Datos!$A:$A,$B$5,Datos!$D:$D,">0")-_xlfn.MINIFS(Datos!$E:$E,Datos!$B:$B,$C13,Datos!$A:$A,$B$5,Datos!$D:$D,">0")) -> 0 | J13: =IF(U13<2,"",_xlfn.MAXIFS(Datos!$F:$F,Datos!$B:$B,$C13,Datos!$A:$A,$B$5,Datos!$F:$F,">0")-_xlfn.MINIFS(Datos!$F:$F,Datos!$B:$B,$C13,Datos!$A:$A,$B$5,Datos!$F:$F,">0")) -> 3.003 | K13: =IF(H13="","",IF(F13>E13,H13/((F13-E13)*24),"")) -> 0.62273684 | L13: =IF(OR(H13="",J13=""),"",IF(J13>0,H13/J13,"")) -> 0.98501499 | M13: =IF(OR(H13="",I13=""),"",IF(H13>0,I13/H13,"")) -> 0 | N13: =IF(S13<2,"",_xlfn.MAXIFS(Datos!$H:$H,Datos!$B:$B,$C13,Datos!$A:$A,$B$5)) -> 0.68 | O13: =IF(N13="","",_xlfn.MINIFS(Datos!$G:$G,Datos!$B:$B,$C13,Datos!$A:$A,$B$5,Datos!$H:$H,N13)/1440) -> 0.58333333 | P13: =IF(OR(COUNTIFS(Datos!$B:$B,$C13,Datos!$A:$A,$B$5,Datos!$D:$D,">0",Datos!$G:$G,(HOUR($D$5)*60+MINUTE($D$5)))=0,COUNTIFS(Datos!$B:$B,$C13,Datos!$A:$A,$B$5-1,Datos!$D:$D,">0",Datos!$G:$G,(HOUR($D$5)*60+MINUTE($D$5)))=0),"",SUMIFS(Datos!$D:$D,Datos!$B:$B,$C13,Datos!$A:$A,$B$5,Datos!$D:$D,">0",Datos!$G:$G,(HOUR($D$5)*60+MINUTE($D$5)))-SUMIFS(Datos!$D:$D,Datos!$B:$B,$C13,Datos!$A:$A,$B$5-1,Datos!$D:$D,">0",Datos!$G:$G,(HOUR($D$5)*60+MINUTE($D$5)))) -> 40.641 | Q13: =IF(OR(K13="",V13=""),"",IF(V13>0,K13/V13-1,"")) -> -0.42056807 | R13: =IF(S13=0,"",_xlfn.MAXIFS(Datos!$D:$D,Datos!$B:$B,$C13,Datos!$A:$A,$B$5,Datos!$D:$D,">0")) -> 9961.256 | S13: =COUNTIFS(Datos!$B:$B,$C13,Datos!$A:$A,$B$5,Datos!$D:$D,">0") -> 20 | T13: =COUNTIFS(Datos!$B:$B,$C13,Datos!$A:$A,$B$5,Datos!$D:$D,0) -> 0 | U13: =COUNTIFS(Datos!$B:$B,$C13,Datos!$A:$A,$B$5,Datos!$F:$F,">0") -> 20 | V13: =IF(COUNTIFS(Datos!$B:$B,$C13,Datos!$A:$A,$B$5-1,Datos!$D:$D,">0")<2,"",IFERROR((_xlfn.MAXIFS(Datos!$D:$D,Datos!$B:$B,$C13,Datos!$A:$A,$B$5-1,Datos!$D:$D,">0")-_xlfn.MINIFS(Datos!$D:$D,Datos!$B:$B,$C13,Datos!$A:$A,$B$5-1,Datos!$D:$D,">0"))/((_xlfn.MAXIFS(Datos!$G:$G,Datos!$B:$B,$C13,Datos!$A:$A,$B$5-1,Datos!$D:$D,">0")-_xlfn.MINIFS(Datos!$G:$G,Datos!$B:$B,$C13,Datos!$A:$A,$B$5-1,Datos!$D:$D,">0"))/60),"")) -> 1.0747368 | W13: =IF(Medidores!C3="",1,IFERROR(IF(INDEX($H$12:$H$21,MATCH(Medidores!C3,$C$12:$C$21,0))="",1,0),1)) -> 0 | X13: =IF(Medidores!C3="",1,IFERROR(IF(INDEX($P$12:$P$21,MATCH(Medidores!C3,$C$12:$C$21,0))="",1,0),1)) -> 0
B14: =Medidores!B4 -> L14 | C14: =Medidores!A4 -> 192.168.50.5 | D14: =IF(S14<2,"Sin datos",IF(T14>0,"Lectura en cero",IF(U14<2,"Falta kVAh",IF(H14<=0.001,"Sin consumo",IF(AND(ISNUMBER(M14),M14>0.5),"Reactiva > 50 %","Normal"))))) -> Reactiva > 50 % | E14: =IF(S14<2,"",_xlfn.MINIFS(Datos!$G:$G,Datos!$B:$B,$C14,Datos!$A:$A,$B$5,Datos!$D:$D,">0")/1440) -> 0.38541667 | F14: =IF(S14<2,"",_xlfn.MAXIFS(Datos!$G:$G,Datos!$B:$B,$C14,Datos!$A:$A,$B$5,Datos!$D:$D,">0")/1440) -> 0.58333333 | G14: =COUNTIFS(Datos!$B:$B,$C14,Datos!$A:$A,$B$5) -> 20 | H14: =IF(S14<2,"",_xlfn.MAXIFS(Datos!$D:$D,Datos!$B:$B,$C14,Datos!$A:$A,$B$5,Datos!$D:$D,">0")-_xlfn.MINIFS(Datos!$D:$D,Datos!$B:$B,$C14,Datos!$A:$A,$B$5,Datos!$D:$D,">0")) -> 17.416 | I14: =IF(S14<2,"",_xlfn.MAXIFS(Datos!$E:$E,Datos!$B:$B,$C14,Datos!$A:$A,$B$5,Datos!$D:$D,">0")-_xlfn.MINIFS(Datos!$E:$E,Datos!$B:$B,$C14,Datos!$A:$A,$B$5,Datos!$D:$D,">0")) -> 9.014 | J14: =IF(U14<2,"",_xlfn.MAXIFS(Datos!$F:$F,Datos!$B:$B,$C14,Datos!$A:$A,$B$5,Datos!$F:$F,">0")-_xlfn.MINIFS(Datos!$F:$F,Datos!$B:$B,$C14,Datos!$A:$A,$B$5,Datos!$F:$F,">0")) -> 19.679 | K14: =IF(H14="","",IF(F14>E14,H14/((F14-E14)*24),"")) -> 3.6665263 | L14: =IF(OR(H14="",J14=""),"",IF(J14>0,H14/J14,"")) -> 0.88500432 | M14: =IF(OR(H14="",I14=""),"",IF(H14>0,I14/H14,"")) -> 0.51757005 | N14: =IF(S14<2,"",_xlfn.MAXIFS(Datos!$H:$H,Datos!$B:$B,$C14,Datos!$A:$A,$B$5)) -> 4.244 | O14: =IF(N14="","",_xlfn.MINIFS(Datos!$G:$G,Datos!$B:$B,$C14,Datos!$A:$A,$B$5,Datos!$H:$H,N14)/1440) -> 0.47916667 | P14: =IF(OR(COUNTIFS(Datos!$B:$B,$C14,Datos!$A:$A,$B$5,Datos!$D:$D,">0",Datos!$G:$G,(HOUR($D$5)*60+MINUTE($D$5)))=0,COUNTIFS(Datos!$B:$B,$C14,Datos!$A:$A,$B$5-1,Datos!$D:$D,">0",Datos!$G:$G,(HOUR($D$5)*60+MINUTE($D$5)))=0),"",SUMIFS(Datos!$D:$D,Datos!$B:$B,$C14,Datos!$A:$A,$B$5,Datos!$D:$D,">0",Datos!$G:$G,(HOUR($D$5)*60+MINUTE($D$5)))-SUMIFS(Datos!$D:$D,Datos!$B:$B,$C14,Datos!$A:$A,$B$5-1,Datos!$D:$D,">0",Datos!$G:$G,(HOUR($D$5)*60+MINUTE($D$5)))) -> 58.982 | Q14: =IF(OR(K14="",V14=""),"",IF(V14>0,K14/V14-1,"")) -> -0.015989604 | R14: =IF(S14=0,"",_xlfn.MAXIFS(Datos!$D:$D,Datos!$B:$B,$C14,Datos!$A:$A,$B$5,Datos!$D:$D,">0")) -> 10579.974 | S14: =COUNTIFS(Datos!$B:$B,$C14,Datos!$A:$A,$B$5,Datos!$D:$D,">0") -> 20 | T14: =COUNTIFS(Datos!$B:$B,$C14,Datos!$A:$A,$B$5,Datos!$D:$D,0) -> 0 | U14: =COUNTIFS(Datos!$B:$B,$C14,Datos!$A:$A,$B$5,Datos!$F:$F,">0") -> 20 | V14: =IF(COUNTIFS(Datos!$B:$B,$C14,Datos!$A:$A,$B$5-1,Datos!$D:$D,">0")<2,"",IFERROR((_xlfn.MAXIFS(Datos!$D:$D,Datos!$B:$B,$C14,Datos!$A:$A,$B$5-1,Datos!$D:$D,">0")-_xlfn.MINIFS(Datos!$D:$D,Datos!$B:$B,$C14,Datos!$A:$A,$B$5-1,Datos!$D:$D,">0"))/((_xlfn.MAXIFS(Datos!$G:$G,Datos!$B:$B,$C14,Datos!$A:$A,$B$5-1,Datos!$D:$D,">0")-_xlfn.MINIFS(Datos!$G:$G,Datos!$B:$B,$C14,Datos!$A:$A,$B$5-1,Datos!$D:$D,">0"))/60),"")) -> 3.7261053 | W14: =IF(Medidores!C4="",1,IFERROR(IF(INDEX($H$12:$H$21,MATCH(Medidores!C4,$C$12:$C$21,0))="",1,0),1)) -> 0 | X14: =IF(Medidores!C4="",1,IFERROR(IF(INDEX($P$12:$P$21,MATCH(Medidores!C4,$C$12:$C$21,0))="",1,0),1)) -> 0
B15: =Medidores!B5 -> L20 | C15: =Medidores!A5 -> 192.168.50.6 | D15: =IF(S15<2,"Sin datos",IF(T15>0,"Lectura en cero",IF(U15<2,"Falta kVAh",IF(H15<=0.001,"Sin consumo",IF(AND(ISNUMBER(M15),M15>0.5),"Reactiva > 50 %","Normal"))))) -> Reactiva > 50 % | E15: =IF(S15<2,"",_xlfn.MINIFS(Datos!$G:$G,Datos!$B:$B,$C15,Datos!$A:$A,$B$5,Datos!$D:$D,">0")/1440) -> 0.375 | F15: =IF(S15<2,"",_xlfn.MAXIFS(Datos!$G:$G,Datos!$B:$B,$C15,Datos!$A:$A,$B$5,Datos!$D:$D,">0")/1440) -> 0.57291667 | G15: =COUNTIFS(Datos!$B:$B,$C15,Datos!$A:$A,$B$5) -> 20 | H15: =IF(S15<2,"",_xlfn.MAXIFS(Datos!$D:$D,Datos!$B:$B,$C15,Datos!$A:$A,$B$5,Datos!$D:$D,">0")-_xlfn.MINIFS(Datos!$D:$D,Datos!$B:$B,$C15,Datos!$A:$A,$B$5,Datos!$D:$D,">0")) -> 16.199 | I15: =IF(S15<2,"",_xlfn.MAXIFS(Datos!$E:$E,Datos!$B:$B,$C15,Datos!$A:$A,$B$5,Datos!$D:$D,">0")-_xlfn.MINIFS(Datos!$E:$E,Datos!$B:$B,$C15,Datos!$A:$A,$B$5,Datos!$D:$D,">0")) -> 12.25 | J15: =IF(U15<2,"",_xlfn.MAXIFS(Datos!$F:$F,Datos!$B:$B,$C15,Datos!$A:$A,$B$5,Datos!$F:$F,">0")-_xlfn.MINIFS(Datos!$F:$F,Datos!$B:$B,$C15,Datos!$A:$A,$B$5,Datos!$F:$F,">0")) -> 20.383 | K15: =IF(H15="","",IF(F15>E15,H15/((F15-E15)*24),"")) -> 3.4103158 | L15: =IF(OR(H15="",J15=""),"",IF(J15>0,H15/J15,"")) -> 0.7947309 | M15: =IF(OR(H15="",I15=""),"",IF(H15>0,I15/H15,"")) -> 0.75621952 | N15: =IF(S15<2,"",_xlfn.MAXIFS(Datos!$H:$H,Datos!$B:$B,$C15,Datos!$A:$A,$B$5)) -> 4.084 | O15: =IF(N15="","",_xlfn.MINIFS(Datos!$G:$G,Datos!$B:$B,$C15,Datos!$A:$A,$B$5,Datos!$H:$H,N15)/1440) -> 0.48958333 | P15: =IF(OR(COUNTIFS(Datos!$B:$B,$C15,Datos!$A:$A,$B$5,Datos!$D:$D,">0",Datos!$G:$G,(HOUR($D$5)*60+MINUTE($D$5)))=0,COUNTIFS(Datos!$B:$B,$C15,Datos!$A:$A,$B$5-1,Datos!$D:$D,">0",Datos!$G:$G,(HOUR($D$5)*60+MINUTE($D$5)))=0),"",SUMIFS(Datos!$D:$D,Datos!$B:$B,$C15,Datos!$A:$A,$B$5,Datos!$D:$D,">0",Datos!$G:$G,(HOUR($D$5)*60+MINUTE($D$5)))-SUMIFS(Datos!$D:$D,Datos!$B:$B,$C15,Datos!$A:$A,$B$5-1,Datos!$D:$D,">0",Datos!$G:$G,(HOUR($D$5)*60+MINUTE($D$5)))) -> 57.596 | Q15: =IF(OR(K15="",V15=""),"",IF(V15>0,K15/V15-1,"")) -> -0.0027088592 | R15: =IF(S15=0,"",_xlfn.MAXIFS(Datos!$D:$D,Datos!$B:$B,$C15,Datos!$A:$A,$B$5,Datos!$D:$D,">0")) -> 13652.201 | S15: =COUNTIFS(Datos!$B:$B,$C15,Datos!$A:$A,$B$5,Datos!$D:$D,">0") -> 20 | T15: =COUNTIFS(Datos!$B:$B,$C15,Datos!$A:$A,$B$5,Datos!$D:$D,0) -> 0 | U15: =COUNTIFS(Datos!$B:$B,$C15,Datos!$A:$A,$B$5,Datos!$F:$F,">0") -> 20 | V15: =IF(COUNTIFS(Datos!$B:$B,$C15,Datos!$A:$A,$B$5-1,Datos!$D:$D,">0")<2,"",IFERROR((_xlfn.MAXIFS(Datos!$D:$D,Datos!$B:$B,$C15,Datos!$A:$A,$B$5-1,Datos!$D:$D,">0")-_xlfn.MINIFS(Datos!$D:$D,Datos!$B:$B,$C15,Datos!$A:$A,$B$5-1,Datos!$D:$D,">0"))/((_xlfn.MAXIFS(Datos!$G:$G,Datos!$B:$B,$C15,Datos!$A:$A,$B$5-1,Datos!$D:$D,">0")-_xlfn.MINIFS(Datos!$G:$G,Datos!$B:$B,$C15,Datos!$A:$A,$B$5-1,Datos!$D:$D,">0"))/60),"")) -> 3.4195789 | W15: =IF(Medidores!C5="",1,IFERROR(IF(INDEX($H$12:$H$21,MATCH(Medidores!C5,$C$12:$C$21,0))="",1,0),1)) -> 0 | X15: =IF(Medidores!C5="",1,IFERROR(IF(INDEX($P$12:$P$21,MATCH(Medidores!C5,$C$12:$C$21,0))="",1,0),1)) -> 0
B16: =Medidores!B6 -> L16 | C16: =Medidores!A6 -> 192.168.50.7 | D16: =IF(S16<2,"Sin datos",IF(T16>0,"Lectura en cero",IF(U16<2,"Falta kVAh",IF(H16<=0.001,"Sin consumo",IF(AND(ISNUMBER(M16),M16>0.5),"Reactiva > 50 %","Normal"))))) -> Normal | E16: =IF(S16<2,"",_xlfn.MINIFS(Datos!$G:$G,Datos!$B:$B,$C16,Datos!$A:$A,$B$5,Datos!$D:$D,">0")/1440) -> 0.38541667 | F16: =IF(S16<2,"",_xlfn.MAXIFS(Datos!$G:$G,Datos!$B:$B,$C16,Datos!$A:$A,$B$5,Datos!$D:$D,">0")/1440) -> 0.58333333 | G16: =COUNTIFS(Datos!$B:$B,$C16,Datos!$A:$A,$B$5) -> 20 | H16: =IF(S16<2,"",_xlfn.MAXIFS(Datos!$D:$D,Datos!$B:$B,$C16,Datos!$A:$A,$B$5,Datos!$D:$D,">0")-_xlfn.MINIFS(Datos!$D:$D,Datos!$B:$B,$C16,Datos!$A:$A,$B$5,Datos!$D:$D,">0")) -> 0.745 | I16: =IF(S16<2,"",_xlfn.MAXIFS(Datos!$E:$E,Datos!$B:$B,$C16,Datos!$A:$A,$B$5,Datos!$D:$D,">0")-_xlfn.MINIFS(Datos!$E:$E,Datos!$B:$B,$C16,Datos!$A:$A,$B$5,Datos!$D:$D,">0")) -> 0 | J16: =IF(U16<2,"",_xlfn.MAXIFS(Datos!$F:$F,Datos!$B:$B,$C16,Datos!$A:$A,$B$5,Datos!$F:$F,">0")-_xlfn.MINIFS(Datos!$F:$F,Datos!$B:$B,$C16,Datos!$A:$A,$B$5,Datos!$F:$F,">0")) -> 2.017 | K16: =IF(H16="","",IF(F16>E16,H16/((F16-E16)*24),"")) -> 0.15684211 | L16: =IF(OR(H16="",J16=""),"",IF(J16>0,H16/J16,"")) -> 0.36936044 | M16: =IF(OR(H16="",I16=""),"",IF(H16>0,I16/H16,"")) -> 0 | N16: =IF(S16<2,"",_xlfn.MAXIFS(Datos!$H:$H,Datos!$B:$B,$C16,Datos!$A:$A,$B$5)) -> 0.16 | O16: =IF(N16="","",_xlfn.MINIFS(Datos!$G:$G,Datos!$B:$B,$C16,Datos!$A:$A,$B$5,Datos!$H:$H,N16)/1440) -> 0.39583333 | P16: =IF(OR(COUNTIFS(Datos!$B:$B,$C16,Datos!$A:$A,$B$5,Datos!$D:$D,">0",Datos!$G:$G,(HOUR($D$5)*60+MINUTE($D$5)))=0,COUNTIFS(Datos!$B:$B,$C16,Datos!$A:$A,$B$5-1,Datos!$D:$D,">0",Datos!$G:$G,(HOUR($D$5)*60+MINUTE($D$5)))=0),"",SUMIFS(Datos!$D:$D,Datos!$B:$B,$C16,Datos!$A:$A,$B$5,Datos!$D:$D,">0",Datos!$G:$G,(HOUR($D$5)*60+MINUTE($D$5)))-SUMIFS(Datos!$D:$D,Datos!$B:$B,$C16,Datos!$A:$A,$B$5-1,Datos!$D:$D,">0",Datos!$G:$G,(HOUR($D$5)*60+MINUTE($D$5)))) -> 3.768 | Q16: =IF(OR(K16="",V16=""),"",IF(V16>0,K16/V16-1,"")) -> 0.0053981107 | R16: =IF(S16=0,"",_xlfn.MAXIFS(Datos!$D:$D,Datos!$B:$B,$C16,Datos!$A:$A,$B$5,Datos!$D:$D,">0")) -> 6628.975 | S16: =COUNTIFS(Datos!$B:$B,$C16,Datos!$A:$A,$B$5,Datos!$D:$D,">0") -> 20 | T16: =COUNTIFS(Datos!$B:$B,$C16,Datos!$A:$A,$B$5,Datos!$D:$D,0) -> 0 | U16: =COUNTIFS(Datos!$B:$B,$C16,Datos!$A:$A,$B$5,Datos!$F:$F,">0") -> 20 | V16: =IF(COUNTIFS(Datos!$B:$B,$C16,Datos!$A:$A,$B$5-1,Datos!$D:$D,">0")<2,"",IFERROR((_xlfn.MAXIFS(Datos!$D:$D,Datos!$B:$B,$C16,Datos!$A:$A,$B$5-1,Datos!$D:$D,">0")-_xlfn.MINIFS(Datos!$D:$D,Datos!$B:$B,$C16,Datos!$A:$A,$B$5-1,Datos!$D:$D,">0"))/((_xlfn.MAXIFS(Datos!$G:$G,Datos!$B:$B,$C16,Datos!$A:$A,$B$5-1,Datos!$D:$D,">0")-_xlfn.MINIFS(Datos!$G:$G,Datos!$B:$B,$C16,Datos!$A:$A,$B$5-1,Datos!$D:$D,">0"))/60),"")) -> 0.156 | W16: =IF(Medidores!C6="",1,IFERROR(IF(INDEX($H$12:$H$21,MATCH(Medidores!C6,$C$12:$C$21,0))="",1,0),1)) -> 0 | X16: =IF(Medidores!C6="",1,IFERROR(IF(INDEX($P$12:$P$21,MATCH(Medidores!C6,$C$12:$C$21,0))="",1,0),1)) -> 0
B17: =Medidores!B7 -> L22 | C17: =Medidores!A7 -> 192.168.1.168 | D17: =IF(S17<2,"Sin datos",IF(T17>0,"Lectura en cero",IF(U17<2,"Falta kVAh",IF(H17<=0.001,"Sin consumo",IF(AND(ISNUMBER(M17),M17>0.5),"Reactiva > 50 %","Normal"))))) -> Normal | E17: =IF(S17<2,"",_xlfn.MINIFS(Datos!$G:$G,Datos!$B:$B,$C17,Datos!$A:$A,$B$5,Datos!$D:$D,">0")/1440) -> 0.38541667 | F17: =IF(S17<2,"",_xlfn.MAXIFS(Datos!$G:$G,Datos!$B:$B,$C17,Datos!$A:$A,$B$5,Datos!$D:$D,">0")/1440) -> 0.58333333 | G17: =COUNTIFS(Datos!$B:$B,$C17,Datos!$A:$A,$B$5) -> 20 | H17: =IF(S17<2,"",_xlfn.MAXIFS(Datos!$D:$D,Datos!$B:$B,$C17,Datos!$A:$A,$B$5,Datos!$D:$D,">0")-_xlfn.MINIFS(Datos!$D:$D,Datos!$B:$B,$C17,Datos!$A:$A,$B$5,Datos!$D:$D,">0")) -> 27.758 | I17: =IF(S17<2,"",_xlfn.MAXIFS(Datos!$E:$E,Datos!$B:$B,$C17,Datos!$A:$A,$B$5,Datos!$D:$D,">0")-_xlfn.MINIFS(Datos!$E:$E,Datos!$B:$B,$C17,Datos!$A:$A,$B$5,Datos!$D:$D,">0")) -> 8.007 | J17: =IF(U17<2,"",_xlfn.MAXIFS(Datos!$F:$F,Datos!$B:$B,$C17,Datos!$A:$A,$B$5,Datos!$F:$F,">0")-_xlfn.MINIFS(Datos!$F:$F,Datos!$B:$B,$C17,Datos!$A:$A,$B$5,Datos!$F:$F,">0")) -> 29.144 | K17: =IF(H17="","",IF(F17>E17,H17/((F17-E17)*24),"")) -> 5.8437895 | L17: =IF(OR(H17="",J17=""),"",IF(J17>0,H17/J17,"")) -> 0.95244304 | M17: =IF(OR(H17="",I17=""),"",IF(H17>0,I17/H17,"")) -> 0.28845738 | N17: =IF(S17<2,"",_xlfn.MAXIFS(Datos!$H:$H,Datos!$B:$B,$C17,Datos!$A:$A,$B$5)) -> 6.776 | O17: =IF(N17="","",_xlfn.MINIFS(Datos!$G:$G,Datos!$B:$B,$C17,Datos!$A:$A,$B$5,Datos!$H:$H,N17)/1440) -> 0.58333333 | P17: =IF(OR(COUNTIFS(Datos!$B:$B,$C17,Datos!$A:$A,$B$5,Datos!$D:$D,">0",Datos!$G:$G,(HOUR($D$5)*60+MINUTE($D$5)))=0,COUNTIFS(Datos!$B:$B,$C17,Datos!$A:$A,$B$5-1,Datos!$D:$D,">0",Datos!$G:$G,(HOUR($D$5)*60+MINUTE($D$5)))=0),"",SUMIFS(Datos!$D:$D,Datos!$B:$B,$C17,Datos!$A:$A,$B$5,Datos!$D:$D,">0",Datos!$G:$G,(HOUR($D$5)*60+MINUTE($D$5)))-SUMIFS(Datos!$D:$D,Datos!$B:$B,$C17,Datos!$A:$A,$B$5-1,Datos!$D:$D,">0",Datos!$G:$G,(HOUR($D$5)*60+MINUTE($D$5)))) -> 104.231 | Q17: =IF(OR(K17="",V17=""),"",IF(V17>0,K17/V17-1,"")) -> -0.060197725 | R17: =IF(S17=0,"",_xlfn.MAXIFS(Datos!$D:$D,Datos!$B:$B,$C17,Datos!$A:$A,$B$5,Datos!$D:$D,">0")) -> 23462.465 | S17: =COUNTIFS(Datos!$B:$B,$C17,Datos!$A:$A,$B$5,Datos!$D:$D,">0") -> 20 | T17: =COUNTIFS(Datos!$B:$B,$C17,Datos!$A:$A,$B$5,Datos!$D:$D,0) -> 0 | U17: =COUNTIFS(Datos!$B:$B,$C17,Datos!$A:$A,$B$5,Datos!$F:$F,">0") -> 20 | V17: =IF(COUNTIFS(Datos!$B:$B,$C17,Datos!$A:$A,$B$5-1,Datos!$D:$D,">0")<2,"",IFERROR((_xlfn.MAXIFS(Datos!$D:$D,Datos!$B:$B,$C17,Datos!$A:$A,$B$5-1,Datos!$D:$D,">0")-_xlfn.MINIFS(Datos!$D:$D,Datos!$B:$B,$C17,Datos!$A:$A,$B$5-1,Datos!$D:$D,">0"))/((_xlfn.MAXIFS(Datos!$G:$G,Datos!$B:$B,$C17,Datos!$A:$A,$B$5-1,Datos!$D:$D,">0")-_xlfn.MINIFS(Datos!$G:$G,Datos!$B:$B,$C17,Datos!$A:$A,$B$5-1,Datos!$D:$D,">0"))/60),"")) -> 6.2181053 | W17: =IF(Medidores!C7="",1,IFERROR(IF(INDEX($H$12:$H$21,MATCH(Medidores!C7,$C$12:$C$21,0))="",1,0),1)) -> 0 | X17: =IF(Medidores!C7="",1,IFERROR(IF(INDEX($P$12:$P$21,MATCH(Medidores!C7,$C$12:$C$21,0))="",1,0),1)) -> 0
B18: =Medidores!B8 -> Estación planta | C18: =Medidores!A8 -> 192.168.50.8 | D18: =IF(S18<2,"Sin datos",IF(T18>0,"Lectura en cero",IF(U18<2,"Falta kVAh",IF(H18<=0.001,"Sin consumo",IF(AND(ISNUMBER(M18),M18>0.5),"Reactiva > 50 %","Normal"))))) -> Normal | E18: =IF(S18<2,"",_xlfn.MINIFS(Datos!$G:$G,Datos!$B:$B,$C18,Datos!$A:$A,$B$5,Datos!$D:$D,">0")/1440) -> 0.38541667 | F18: =IF(S18<2,"",_xlfn.MAXIFS(Datos!$G:$G,Datos!$B:$B,$C18,Datos!$A:$A,$B$5,Datos!$D:$D,">0")/1440) -> 0.58333333 | G18: =COUNTIFS(Datos!$B:$B,$C18,Datos!$A:$A,$B$5) -> 20 | H18: =IF(S18<2,"",_xlfn.MAXIFS(Datos!$D:$D,Datos!$B:$B,$C18,Datos!$A:$A,$B$5,Datos!$D:$D,">0")-_xlfn.MINIFS(Datos!$D:$D,Datos!$B:$B,$C18,Datos!$A:$A,$B$5,Datos!$D:$D,">0")) -> 127.946 | I18: =IF(S18<2,"",_xlfn.MAXIFS(Datos!$E:$E,Datos!$B:$B,$C18,Datos!$A:$A,$B$5,Datos!$D:$D,">0")-_xlfn.MINIFS(Datos!$E:$E,Datos!$B:$B,$C18,Datos!$A:$A,$B$5,Datos!$D:$D,">0")) -> 6.65 | J18: =IF(U18<2,"",_xlfn.MAXIFS(Datos!$F:$F,Datos!$B:$B,$C18,Datos!$A:$A,$B$5,Datos!$F:$F,">0")-_xlfn.MINIFS(Datos!$F:$F,Datos!$B:$B,$C18,Datos!$A:$A,$B$5,Datos!$F:$F,">0")) -> 128.148 | K18: =IF(H18="","",IF(F18>E18,H18/((F18-E18)*24),"")) -> 26.936 | L18: =IF(OR(H18="",J18=""),"",IF(J18>0,H18/J18,"")) -> 0.9984237 | M18: =IF(OR(H18="",I18=""),"",IF(H18>0,I18/H18,"")) -> 0.051975052 | N18: =IF(S18<2,"",_xlfn.MAXIFS(Datos!$H:$H,Datos!$B:$B,$C18,Datos!$A:$A,$B$5)) -> 29.876 | O18: =IF(N18="","",_xlfn.MINIFS(Datos!$G:$G,Datos!$B:$B,$C18,Datos!$A:$A,$B$5,Datos!$H:$H,N18)/1440) -> 0.42708333 | P18: =IF(OR(COUNTIFS(Datos!$B:$B,$C18,Datos!$A:$A,$B$5,Datos!$D:$D,">0",Datos!$G:$G,(HOUR($D$5)*60+MINUTE($D$5)))=0,COUNTIFS(Datos!$B:$B,$C18,Datos!$A:$A,$B$5-1,Datos!$D:$D,">0",Datos!$G:$G,(HOUR($D$5)*60+MINUTE($D$5)))=0),"",SUMIFS(Datos!$D:$D,Datos!$B:$B,$C18,Datos!$A:$A,$B$5,Datos!$D:$D,">0",Datos!$G:$G,(HOUR($D$5)*60+MINUTE($D$5)))-SUMIFS(Datos!$D:$D,Datos!$B:$B,$C18,Datos!$A:$A,$B$5-1,Datos!$D:$D,">0",Datos!$G:$G,(HOUR($D$5)*60+MINUTE($D$5)))) -> 476.008 | Q18: =IF(OR(K18="",V18=""),"",IF(V18>0,K18/V18-1,"")) -> -0.13737097 | R18: =IF(S18=0,"",_xlfn.MAXIFS(Datos!$D:$D,Datos!$B:$B,$C18,Datos!$A:$A,$B$5,Datos!$D:$D,">0")) -> 107913.1 | S18: =COUNTIFS(Datos!$B:$B,$C18,Datos!$A:$A,$B$5,Datos!$D:$D,">0") -> 20 | T18: =COUNTIFS(Datos!$B:$B,$C18,Datos!$A:$A,$B$5,Datos!$D:$D,0) -> 0 | U18: =COUNTIFS(Datos!$B:$B,$C18,Datos!$A:$A,$B$5,Datos!$F:$F,">0") -> 20 | V18: =IF(COUNTIFS(Datos!$B:$B,$C18,Datos!$A:$A,$B$5-1,Datos!$D:$D,">0")<2,"",IFERROR((_xlfn.MAXIFS(Datos!$D:$D,Datos!$B:$B,$C18,Datos!$A:$A,$B$5-1,Datos!$D:$D,">0")-_xlfn.MINIFS(Datos!$D:$D,Datos!$B:$B,$C18,Datos!$A:$A,$B$5-1,Datos!$D:$D,">0"))/((_xlfn.MAXIFS(Datos!$G:$G,Datos!$B:$B,$C18,Datos!$A:$A,$B$5-1,Datos!$D:$D,">0")-_xlfn.MINIFS(Datos!$G:$G,Datos!$B:$B,$C18,Datos!$A:$A,$B$5-1,Datos!$D:$D,">0"))/60),"")) -> 31.225474 | W18: =IF(Medidores!C8="",1,IFERROR(IF(INDEX($H$12:$H$21,MATCH(Medidores!C8,$C$12:$C$21,0))="",1,0),1)) -> 1 | X18: =IF(Medidores!C8="",1,IFERROR(IF(INDEX($P$12:$P$21,MATCH(Medidores!C8,$C$12:$C$21,0))="",1,0),1)) -> 1
B19: =Medidores!B9 -> Estación celda 3 | C19: =Medidores!A9 -> 192.168.50.9 | D19: =IF(S19<2,"Sin datos",IF(T19>0,"Lectura en cero",IF(U19<2,"Falta kVAh",IF(H19<=0.001,"Sin consumo",IF(AND(ISNUMBER(M19),M19>0.5),"Reactiva > 50 %","Normal"))))) -> Normal | E19: =IF(S19<2,"",_xlfn.MINIFS(Datos!$G:$G,Datos!$B:$B,$C19,Datos!$A:$A,$B$5,Datos!$D:$D,">0")/1440) -> 0.38541667 | F19: =IF(S19<2,"",_xlfn.MAXIFS(Datos!$G:$G,Datos!$B:$B,$C19,Datos!$A:$A,$B$5,Datos!$D:$D,">0")/1440) -> 0.58333333 | G19: =COUNTIFS(Datos!$B:$B,$C19,Datos!$A:$A,$B$5) -> 20 | H19: =IF(S19<2,"",_xlfn.MAXIFS(Datos!$D:$D,Datos!$B:$B,$C19,Datos!$A:$A,$B$5,Datos!$D:$D,">0")-_xlfn.MINIFS(Datos!$D:$D,Datos!$B:$B,$C19,Datos!$A:$A,$B$5,Datos!$D:$D,">0")) -> 341.219 | I19: =IF(S19<2,"",_xlfn.MAXIFS(Datos!$E:$E,Datos!$B:$B,$C19,Datos!$A:$A,$B$5,Datos!$D:$D,">0")-_xlfn.MINIFS(Datos!$E:$E,Datos!$B:$B,$C19,Datos!$A:$A,$B$5,Datos!$D:$D,">0")) -> 137.774 | J19: =IF(U19<2,"",_xlfn.MAXIFS(Datos!$F:$F,Datos!$B:$B,$C19,Datos!$A:$A,$B$5,Datos!$F:$F,">0")-_xlfn.MINIFS(Datos!$F:$F,Datos!$B:$B,$C19,Datos!$A:$A,$B$5,Datos!$F:$F,">0")) -> 368.25 | K19: =IF(H19="","",IF(F19>E19,H19/((F19-E19)*24),"")) -> 71.835579 | L19: =IF(OR(H19="",J19=""),"",IF(J19>0,H19/J19,"")) -> 0.92659606 | M19: =IF(OR(H19="",I19=""),"",IF(H19>0,I19/H19,"")) -> 0.40377001 | N19: =IF(S19<2,"",_xlfn.MAXIFS(Datos!$H:$H,Datos!$B:$B,$C19,Datos!$A:$A,$B$5)) -> 86.752 | O19: =IF(N19="","",_xlfn.MINIFS(Datos!$G:$G,Datos!$B:$B,$C19,Datos!$A:$A,$B$5,Datos!$H:$H,N19)/1440) -> 0.57291667 | P19: =IF(OR(COUNTIFS(Datos!$B:$B,$C19,Datos!$A:$A,$B$5,Datos!$D:$D,">0",Datos!$G:$G,(HOUR($D$5)*60+MINUTE($D$5)))=0,COUNTIFS(Datos!$B:$B,$C19,Datos!$A:$A,$B$5-1,Datos!$D:$D,">0",Datos!$G:$G,(HOUR($D$5)*60+MINUTE($D$5)))=0),"",SUMIFS(Datos!$D:$D,Datos!$B:$B,$C19,Datos!$A:$A,$B$5,Datos!$D:$D,">0",Datos!$G:$G,(HOUR($D$5)*60+MINUTE($D$5)))-SUMIFS(Datos!$D:$D,Datos!$B:$B,$C19,Datos!$A:$A,$B$5-1,Datos!$D:$D,">0",Datos!$G:$G,(HOUR($D$5)*60+MINUTE($D$5)))) -> 1117.938 | Q19: =IF(OR(K19="",V19=""),"",IF(V19>0,K19/V19-1,"")) -> 0.020849663 | R19: =IF(S19=0,"",_xlfn.MAXIFS(Datos!$D:$D,Datos!$B:$B,$C19,Datos!$A:$A,$B$5,Datos!$D:$D,">0")) -> 267912.5 | S19: =COUNTIFS(Datos!$B:$B,$C19,Datos!$A:$A,$B$5,Datos!$D:$D,">0") -> 20 | T19: =COUNTIFS(Datos!$B:$B,$C19,Datos!$A:$A,$B$5,Datos!$D:$D,0) -> 0 | U19: =COUNTIFS(Datos!$B:$B,$C19,Datos!$A:$A,$B$5,Datos!$F:$F,">0") -> 20 | V19: =IF(COUNTIFS(Datos!$B:$B,$C19,Datos!$A:$A,$B$5-1,Datos!$D:$D,">0")<2,"",IFERROR((_xlfn.MAXIFS(Datos!$D:$D,Datos!$B:$B,$C19,Datos!$A:$A,$B$5-1,Datos!$D:$D,">0")-_xlfn.MINIFS(Datos!$D:$D,Datos!$B:$B,$C19,Datos!$A:$A,$B$5-1,Datos!$D:$D,">0"))/((_xlfn.MAXIFS(Datos!$G:$G,Datos!$B:$B,$C19,Datos!$A:$A,$B$5-1,Datos!$D:$D,">0")-_xlfn.MINIFS(Datos!$G:$G,Datos!$B:$B,$C19,Datos!$A:$A,$B$5-1,Datos!$D:$D,">0"))/60),"")) -> 70.368421 | W19: =IF(Medidores!C9="",1,IFERROR(IF(INDEX($H$12:$H$21,MATCH(Medidores!C9,$C$12:$C$21,0))="",1,0),1)) -> 1 | X19: =IF(Medidores!C9="",1,IFERROR(IF(INDEX($P$12:$P$21,MATCH(Medidores!C9,$C$12:$C$21,0))="",1,0),1)) -> 1
B20: =Medidores!B10 -> Estación celda 2 | C20: =Medidores!A10 -> 192.168.50.10 | D20: =IF(S20<2,"Sin datos",IF(T20>0,"Lectura en cero",IF(U20<2,"Falta kVAh",IF(H20<=0.001,"Sin consumo",IF(AND(ISNUMBER(M20),M20>0.5),"Reactiva > 50 %","Normal"))))) -> Normal | E20: =IF(S20<2,"",_xlfn.MINIFS(Datos!$G:$G,Datos!$B:$B,$C20,Datos!$A:$A,$B$5,Datos!$D:$D,">0")/1440) -> 0.38541667 | F20: =IF(S20<2,"",_xlfn.MAXIFS(Datos!$G:$G,Datos!$B:$B,$C20,Datos!$A:$A,$B$5,Datos!$D:$D,">0")/1440) -> 0.58333333 | G20: =COUNTIFS(Datos!$B:$B,$C20,Datos!$A:$A,$B$5) -> 20 | H20: =IF(S20<2,"",_xlfn.MAXIFS(Datos!$D:$D,Datos!$B:$B,$C20,Datos!$A:$A,$B$5,Datos!$D:$D,">0")-_xlfn.MINIFS(Datos!$D:$D,Datos!$B:$B,$C20,Datos!$A:$A,$B$5,Datos!$D:$D,">0")) -> 427.343 | I20: =IF(S20<2,"",_xlfn.MAXIFS(Datos!$E:$E,Datos!$B:$B,$C20,Datos!$A:$A,$B$5,Datos!$D:$D,">0")-_xlfn.MINIFS(Datos!$E:$E,Datos!$B:$B,$C20,Datos!$A:$A,$B$5,Datos!$D:$D,">0")) -> 184.922 | J20: =IF(U20<2,"",_xlfn.MAXIFS(Datos!$F:$F,Datos!$B:$B,$C20,Datos!$A:$A,$B$5,Datos!$F:$F,">0")-_xlfn.MINIFS(Datos!$F:$F,Datos!$B:$B,$C20,Datos!$A:$A,$B$5,Datos!$F:$F,">0")) -> 465.718 | K20: =IF(H20="","",IF(F20>E20,H20/((F20-E20)*24),"")) -> 89.966947 | L20: =IF(OR(H20="",J20=""),"",IF(J20>0,H20/J20,"")) -> 0.91760035 | M20: =IF(OR(H20="",I20=""),"",IF(H20>0,I20/H20,"")) -> 0.432725 | N20: =IF(S20<2,"",_xlfn.MAXIFS(Datos!$H:$H,Datos!$B:$B,$C20,Datos!$A:$A,$B$5)) -> 100.252 | O20: =IF(N20="","",_xlfn.MINIFS(Datos!$G:$G,Datos!$B:$B,$C20,Datos!$A:$A,$B$5,Datos!$H:$H,N20)/1440) -> 0.57291667 | P20: =IF(OR(COUNTIFS(Datos!$B:$B,$C20,Datos!$A:$A,$B$5,Datos!$D:$D,">0",Datos!$G:$G,(HOUR($D$5)*60+MINUTE($D$5)))=0,COUNTIFS(Datos!$B:$B,$C20,Datos!$A:$A,$B$5-1,Datos!$D:$D,">0",Datos!$G:$G,(HOUR($D$5)*60+MINUTE($D$5)))=0),"",SUMIFS(Datos!$D:$D,Datos!$B:$B,$C20,Datos!$A:$A,$B$5,Datos!$D:$D,">0",Datos!$G:$G,(HOUR($D$5)*60+MINUTE($D$5)))-SUMIFS(Datos!$D:$D,Datos!$B:$B,$C20,Datos!$A:$A,$B$5-1,Datos!$D:$D,">0",Datos!$G:$G,(HOUR($D$5)*60+MINUTE($D$5)))) -> 1557.125 | Q20: =IF(OR(K20="",V20=""),"",IF(V20>0,K20/V20-1,"")) -> 0.018392612 | R20: =IF(S20=0,"",_xlfn.MAXIFS(Datos!$D:$D,Datos!$B:$B,$C20,Datos!$A:$A,$B$5,Datos!$D:$D,">0")) -> 436443.53 | S20: =COUNTIFS(Datos!$B:$B,$C20,Datos!$A:$A,$B$5,Datos!$D:$D,">0") -> 20 | T20: =COUNTIFS(Datos!$B:$B,$C20,Datos!$A:$A,$B$5,Datos!$D:$D,0) -> 0 | U20: =COUNTIFS(Datos!$B:$B,$C20,Datos!$A:$A,$B$5,Datos!$F:$F,">0") -> 20 | V20: =IF(COUNTIFS(Datos!$B:$B,$C20,Datos!$A:$A,$B$5-1,Datos!$D:$D,">0")<2,"",IFERROR((_xlfn.MAXIFS(Datos!$D:$D,Datos!$B:$B,$C20,Datos!$A:$A,$B$5-1,Datos!$D:$D,">0")-_xlfn.MINIFS(Datos!$D:$D,Datos!$B:$B,$C20,Datos!$A:$A,$B$5-1,Datos!$D:$D,">0"))/((_xlfn.MAXIFS(Datos!$G:$G,Datos!$B:$B,$C20,Datos!$A:$A,$B$5-1,Datos!$D:$D,">0")-_xlfn.MINIFS(Datos!$G:$G,Datos!$B:$B,$C20,Datos!$A:$A,$B$5-1,Datos!$D:$D,">0"))/60),"")) -> 88.342105 | W20: =IF(Medidores!C10="",1,IFERROR(IF(INDEX($H$12:$H$21,MATCH(Medidores!C10,$C$12:$C$21,0))="",1,0),1)) -> 1 | X20: =IF(Medidores!C10="",1,IFERROR(IF(INDEX($P$12:$P$21,MATCH(Medidores!C10,$C$12:$C$21,0))="",1,0),1)) -> 1
B21: =Medidores!B11 -> Estación celda 1 | C21: =Medidores!A11 -> 192.168.50.11 | D21: =IF(S21<2,"Sin datos",IF(T21>0,"Lectura en cero",IF(U21<2,"Falta kVAh",IF(H21<=0.001,"Sin consumo",IF(AND(ISNUMBER(M21),M21>0.5),"Reactiva > 50 %","Normal"))))) -> Reactiva > 50 % | E21: =IF(S21<2,"",_xlfn.MINIFS(Datos!$G:$G,Datos!$B:$B,$C21,Datos!$A:$A,$B$5,Datos!$D:$D,">0")/1440) -> 0.38541667 | F21: =IF(S21<2,"",_xlfn.MAXIFS(Datos!$G:$G,Datos!$B:$B,$C21,Datos!$A:$A,$B$5,Datos!$D:$D,">0")/1440) -> 0.58333333 | G21: =COUNTIFS(Datos!$B:$B,$C21,Datos!$A:$A,$B$5) -> 20 | H21: =IF(S21<2,"",_xlfn.MAXIFS(Datos!$D:$D,Datos!$B:$B,$C21,Datos!$A:$A,$B$5,Datos!$D:$D,">0")-_xlfn.MINIFS(Datos!$D:$D,Datos!$B:$B,$C21,Datos!$A:$A,$B$5,Datos!$D:$D,">0")) -> 430.219 | I21: =IF(S21<2,"",_xlfn.MAXIFS(Datos!$E:$E,Datos!$B:$B,$C21,Datos!$A:$A,$B$5,Datos!$D:$D,">0")-_xlfn.MINIFS(Datos!$E:$E,Datos!$B:$B,$C21,Datos!$A:$A,$B$5,Datos!$D:$D,">0")) -> 229.547 | J21: =IF(U21<2,"",_xlfn.MAXIFS(Datos!$F:$F,Datos!$B:$B,$C21,Datos!$A:$A,$B$5,Datos!$F:$F,">0")-_xlfn.MINIFS(Datos!$F:$F,Datos!$B:$B,$C21,Datos!$A:$A,$B$5,Datos!$F:$F,">0")) -> 495.062 | K21: =IF(H21="","",IF(F21>E21,H21/((F21-E21)*24),"")) -> 90.572421 | L21: =IF(OR(H21="",J21=""),"",IF(J21>0,H21/J21,"")) -> 0.86902045 | M21: =IF(OR(H21="",I21=""),"",IF(H21>0,I21/H21,"")) -> 0.53355849 | N21: =IF(S21<2,"",_xlfn.MAXIFS(Datos!$H:$H,Datos!$B:$B,$C21,Datos!$A:$A,$B$5)) -> 130.248 | O21: =IF(N21="","",_xlfn.MINIFS(Datos!$G:$G,Datos!$B:$B,$C21,Datos!$A:$A,$B$5,Datos!$H:$H,N21)/1440) -> 0.40625 | P21: =IF(OR(COUNTIFS(Datos!$B:$B,$C21,Datos!$A:$A,$B$5,Datos!$D:$D,">0",Datos!$G:$G,(HOUR($D$5)*60+MINUTE($D$5)))=0,COUNTIFS(Datos!$B:$B,$C21,Datos!$A:$A,$B$5-1,Datos!$D:$D,">0",Datos!$G:$G,(HOUR($D$5)*60+MINUTE($D$5)))=0),"",SUMIFS(Datos!$D:$D,Datos!$B:$B,$C21,Datos!$A:$A,$B$5,Datos!$D:$D,">0",Datos!$G:$G,(HOUR($D$5)*60+MINUTE($D$5)))-SUMIFS(Datos!$D:$D,Datos!$B:$B,$C21,Datos!$A:$A,$B$5-1,Datos!$D:$D,">0",Datos!$G:$G,(HOUR($D$5)*60+MINUTE($D$5)))) -> 1362.937 | Q21: =IF(OR(K21="",V21=""),"",IF(V21>0,K21/V21-1,"")) -> 0.12825684 | R21: =IF(S21=0,"",_xlfn.MAXIFS(Datos!$D:$D,Datos!$B:$B,$C21,Datos!$A:$A,$B$5,Datos!$D:$D,">0")) -> 331773.06 | S21: =COUNTIFS(Datos!$B:$B,$C21,Datos!$A:$A,$B$5,Datos!$D:$D,">0") -> 20 | T21: =COUNTIFS(Datos!$B:$B,$C21,Datos!$A:$A,$B$5,Datos!$D:$D,0) -> 0 | U21: =COUNTIFS(Datos!$B:$B,$C21,Datos!$A:$A,$B$5,Datos!$F:$F,">0") -> 20 | V21: =IF(COUNTIFS(Datos!$B:$B,$C21,Datos!$A:$A,$B$5-1,Datos!$D:$D,">0")<2,"",IFERROR((_xlfn.MAXIFS(Datos!$D:$D,Datos!$B:$B,$C21,Datos!$A:$A,$B$5-1,Datos!$D:$D,">0")-_xlfn.MINIFS(Datos!$D:$D,Datos!$B:$B,$C21,Datos!$A:$A,$B$5-1,Datos!$D:$D,">0"))/((_xlfn.MAXIFS(Datos!$G:$G,Datos!$B:$B,$C21,Datos!$A:$A,$B$5-1,Datos!$D:$D,">0")-_xlfn.MINIFS(Datos!$G:$G,Datos!$B:$B,$C21,Datos!$A:$A,$B$5-1,Datos!$D:$D,">0"))/60),"")) -> 80.276421 | W21: =IF(Medidores!C11="",1,IFERROR(IF(INDEX($H$12:$H$21,MATCH(Medidores!C11,$C$12:$C$21,0))="",1,0),1)) -> 1 | X21: =IF(Medidores!C11="",1,IFERROR(IF(INDEX($P$12:$P$21,MATCH(Medidores!C11,$C$12:$C$21,0))="",1,0),1)) -> 1
B23: Celdas amarillas: día y medidor se eligen de la lista; la hora de corte se escribe (ej. 11:00).
B24: kWh 24 h al corte = lectura del día a la hora de corte − lectura del día anterior a la misma hora. Requiere ambas lecturas.
B25: kVARh / kWh > 50 %: la línea consume mucha reactiva. EMCALI cobra según la frontera (hoja EMCALI), donde el banco de condensadores compensa.
B26: kW medio vs día anterior compara la demanda media del periodo registrado de cada día. Las lecturas en cero se excluyen.
B27: Totales: las líneas L14–L50 están dentro de Estación planta (hoja Medidores, columna Dentro de) y no se suman dos veces.

Sheet Datos
A1: Fecha | B1: IP | C1: Hora | D1: kWh | E1: kVARh | F1: kVAh | G1: Minuto | H1: kW intervalo | I1: Línea | J1: Hora en el medidor
A2: 46302 | B2: 192.168.1.168 | C2: 0.26041667 | D2: 23213.115 | E2: 5870.396 | F2: 24149.643 | G2: =HOUR(C2)*60+MINUTE(C2) -> 375 | H2: =IF(AND(B2=B1,A2=A1,D2>0,N(D1)>0,G2>N(G1)),(D2-D1)/((G2-G1)/60),"") | I2: =IFERROR(INDEX(Medidores!$B:$B,MATCH(B2,Medidores!$A:$A,0)),"") -> L22 | J2: 2026-10-07 11:15
A3: 46302 | B3: 192.168.1.168 | C3: 0.27083333 | D3: 23213.744 | E3: 5870.521 | F3: 24150.285 | G3: =HOUR(C3)*60+MINUTE(C3) -> 390 | H3: =IF(AND(B3=B2,A3=A2,D3>0,N(D2)>0,G3>N(G2)),(D3-D2)/((G3-G2)/60),"") -> 2.516 | I3: =IFERROR(INDEX(Medidores!$B:$B,MATCH(B3,Medidores!$A:$A,0)),"") -> L22 | J3: 2026-10-07 11:30
A4: 46302 | B4: 192.168.1.168 | C4: 0.28125 | D4: 23214.371 | E4: 5870.632 | F4: 24150.926 | G4: =HOUR(C4)*60+MINUTE(C4) -> 405 | H4: =IF(AND(B4=B3,A4=A3,D4>0,N(D3)>0,G4>N(G3)),(D4-D3)/((G4-G3)/60),"") -> 2.508 | I4: =IFERROR(INDEX(Medidores!$B:$B,MATCH(B4,Medidores!$A:$A,0)),"") -> L22 | J4: 2026-10-07 11:45
A5: 46302 | B5: 192.168.1.168 | C5: 0.29166667 | D5: 23215.045 | E5: 5870.742 | F5: 24151.609 | G5: =HOUR(C5)*60+MINUTE(C5) -> 420 | H5: =IF(AND(B5=B4,A5=A4,D5>0,N(D4)>0,G5>N(G4)),(D5-D4)/((G5-G4)/60),"") -> 2.696 | I5: =IFERROR(INDEX(Medidores!$B:$B,MATCH(B5,Medidores!$A:$A,0)),"") -> L22 | J5: 2026-10-07 12:00
A6: 46302 | B6: 192.168.1.168 | C6: 0.30208333 | D6: 23216.727 | E6: 5871.275 | F6: 24153.393 | G6: =HOUR(C6)*60+MINUTE(C6) -> 435 | H6: =IF(AND(B6=B5,A6=A5,D6>0,N(D5)>0,G6>N(G5)),(D6-D5)/((G6-G5)/60),"") -> 6.728 | I6: =IFERROR(INDEX(Medidores!$B:$B,MATCH(B6,Medidores!$A:$A,0)),"") -> L22 | J6: 2026-10-07 12:15
A7: 46302 | B7: 192.168.1.168 | C7: 0.3125 | D7: 23218.24 | E7: 5871.698 | F7: 24154.981 | G7: =HOUR(C7)*60+MINUTE(C7) -> 450 | H7: =IF(AND(B7=B6,A7=A6,D7>0,N(D6)>0,G7>N(G6)),(D7-D6)/((G7-G6)/60),"") -> 6.052 | I7: =IFERROR(INDEX(Medidores!$B:$B,MATCH(B7,Medidores!$A:$A,0)),"") -> L22 | J7: 2026-10-07 12:30
A8: 46302 | B8: 192.168.1.168 | C8: 0.32291667 | D8: 23219.891 | E8: 5872.194 | F8: 24156.713 | G8: =HOUR(C8)*60+MINUTE(C8) -> 465 | H8: =IF(AND(B8=B7,A8=A7,D8>0,N(D7)>0,G8>N(G7)),(D8-D7)/((G8-G7)/60),"") -> 6.604 | I8: =IFERROR(INDEX(Medidores!$B:$B,MATCH(B8,Medidores!$A:$A,0)),"") -> L22 | J8: 2026-10-07 12:45
A9: 46302 | B9: 192.168.1.168 | C9: 0.33333333 | D9: 23221.516 | E9: 5872.683 | F9: 24158.422 | G9: =HOUR(C9)*60+MINUTE(C9) -> 480 | H9: =IF(AND(B9=B8,A9=A8,D9>0,N(D8)>0,G9>N(G8)),(D9-D8)/((G9-G8)/60),"") -> 6.5 | I9: =IFERROR(INDEX(Medidores!$B:$B,MATCH(B9,Medidores!$A:$A,0)),"") -> L22 | J9: 2026-10-07 13:00
A10: 46302 | B10: 192.168.1.168 | C10: 0.34375 | D10: 23223.152 | E10: 5873.226 | F10: 24160.164 | G10: =HOUR(C10)*60+MINUTE(C10) -> 495 | H10: =IF(AND(B10=B9,A10=A9,D10>0,N(D9)>0,G10>N(G9)),(D10-D9)/((G10-G9)/60),"") -> 6.544 | I10: =IFERROR(INDEX(Medidores!$B:$B,MATCH(B10,Medidores!$A:$A,0)),"") -> L22 | J10: 2026-10-07 13:15
A11: 46302 | B11: 192.168.1.168 | C11: 0.35416667 | D11: 23224.775 | E11: 5873.71 | F11: 24161.877 | G11: =HOUR(C11)*60+MINUTE(C11) -> 510 | H11: =IF(AND(B11=B10,A11=A10,D11>0,N(D10)>0,G11>N(G10)),(D11-D10)/((G11-G10)/60),"") -> 6.492 | I11: =IFERROR(INDEX(Medidores!$B:$B,MATCH(B11,Medidores!$A:$A,0)),"") -> L22 | J11: 2026-10-07 13:30
A12: 46302 | B12: 192.168.1.168 | C12: 0.36458333 | D12: 23226.219 | E12: 5874.117 | F12: 24163.389 | G12: =HOUR(C12)*60+MINUTE(C12) -> 525 | H12: =IF(AND(B12=B11,A12=A11,D12>0,N(D11)>0,G12>N(G11)),(D12-D11)/((G12-G11)/60),"") -> 5.776 | I12: =IFERROR(INDEX(Medidores!$B:$B,MATCH(B12,Medidores!$A:$A,0)),"") -> L22 | J12: 2026-10-07 13:45
A13: 46302 | B13: 192.168.1.168 | C13: 0.375 | D13: 23227.84 | E13: 5874.638 | F13: 24165.106 | G13: =HOUR(C13)*60+MINUTE(C13) -> 540 | H13: =IF(AND(B13=B12,A13=A12,D13>0,N(D12)>0,G13>N(G12)),(D13-D12)/((G13-G12)/60),"") -> 6.484 | I13: =IFERROR(INDEX(Medidores!$B:$B,MATCH(B13,Medidores!$A:$A,0)),"") -> L22 | J13: 2026-10-07 14:00
... A121: 46302 | B121: 192.168.50.8 | C121: 0.35416667 | D121: 106818.85 | E121: 22790.152 | F121: 109776.4 | G121: =HOUR(C121)*60+MINUTE(C121) -> 510 | H121: =IF(AND(B121=B120,A121=A120,D121>0,N(D120)>0,G121>N(G120)),(D121-D120)/((G121-G120)/60),"") -> 27.188 | I121: =IFERROR(INDEX(Medidores!$B:$B,MATCH(B121,Medidores!$A:$A,0)),"") -> Estación planta | J121: 2026-10-07 13:30
A122: 46302 | B122: 192.168.50.9 | C122: 0.27083333 | D122: 265368.78 | E122: 109231.53 | G122: =HOUR(C122)*60+MINUTE(C122) -> 390 | H122: =IF(AND(B122=B121,A122=A121,D122>0,N(D121)>0,G122>N(G121)),(D122-D121)/((G122-G121)/60),"") | I122: =IFERROR(INDEX(Medidores!$B:$B,MATCH(B122,Medidores!$A:$A,0)),"") -> Estación celda 3 | J122: 2026-10-07 11:30
A123: 46302 | B123: 192.168.50.9 | C123: 0.28125 | D123: 265380.44 | E123: 109235.91 | G123: =HOUR(C123)*60+MINUTE(C123) -> 405 | H123: =IF(AND(B123=B122,A123=A122,D123>0,N(D122)>0,G123>N(G122)),(D123-D122)/((G123-G122)/60),"") -> 46.628 | I123: =IFERROR(INDEX(Medidores!$B:$B,MATCH(B123,Medidores!$A:$A,0)),"") -> Estación celda 3 | J123: 2026-10-07 11:45
A124: 46302 | B124: 192.168.50.9 | C124: 0.29166667 | D124: 265388.25 | E124: 109238.12 | G124: =HOUR(C124)*60+MINUTE(C124) -> 420 | H124: =IF(AND(B124=B123,A124=A123,D124>0,N(D123)>0,G124>N(G123)),(D124-D123)/((G124-G123)/60),"") -> 31.248 | I124: =IFERROR(INDEX(Medidores!$B:$B,MATCH(B124,Medidores!$A:$A,0)),"") -> Estación celda 3 | J124: 2026-10-07 12:00
A125: 46302 | B125: 192.168.50.9 | C125: 0.30208333 | D125: 265398.28 | E125: 109242.86 | G125: =HOUR(C125)*60+MINUTE(C125) -> 435 | H125: =IF(AND(B125=B124,A125=A124,D125>0,N(D124)>0,G125>N(G124)),(D125-D124)/((G125-G124)/60),"") -> 40.124 | I125: =IFERROR(INDEX(Medidores!$B:$B,MATCH(B125,Medidores!$A:$A,0)),"") -> Estación celda 3 | J125: 2026-10-07 12:15
A126: 46302 | B126: 192.168.50.9 | C126: 0.3125 | D126: 265411.91 | E126: 109250.34 | G126: =HOUR(C126)*60+MINUTE(C126) -> 450 | H126: =IF(AND(B126=B125,A126=A125,D126>0,N(D125)>0,G126>N(G125)),(D126-D125)/((G126-G125)/60),"") -> 54.5 | I126: =IFERROR(INDEX(Medidores!$B:$B,MATCH(B126,Medidores!$A:$A,0)),"") -> Estación celda 3 | J126: 2026-10-07 12:30
A127: 46302 | B127: 192.168.50.9 | C127: 0.32291667 | D127: 265423.62 | E127: 109256.3 | G127: =HOUR(C127)*60+MINUTE(C127) -> 465 | H127: =IF(AND(B127=B126,A127=A126,D127>0,N(D126)>0,G127>N(G126)),(D127-D126)/((G127-G126)/60),"") -> 46.876 | I127: =IFERROR(INDEX(Medidores!$B:$B,MATCH(B127,Medidores!$A:$A,0)),"") -> Estación celda 3 | J127: 2026-10-07 12:45
A128: 46302 | B128: 192.168.50.9 | C128: 0.33333333 | D128: 265435.47 | E128: 109262.2 | G128: =HOUR(C128)*60+MINUTE(C128) -> 480 | H128: =IF(AND(B128=B127,A128=A127,D128>0,N(D127)>0,G128>N(G127)),(D128-D127)/((G128-G127)/60),"") -> 47.376 | I128: =IFERROR(INDEX(Medidores!$B:$B,MATCH(B128,Medidores!$A:$A,0)),"") -> Estación celda 3 | J128: 2026-10-07 13:00
A129: 46302 | B129: 192.168.50.9 | C129: 0.34375 | D129: 265450.19 | E129: 109270.9 | G129: =HOUR(C129)*60+MINUTE(C129) -> 495 | H129: =IF(AND(B129=B128,A129=A128,D129>0,N(D128)>0,G129>N(G128)),(D129-D128)/((G129-G128)/60),"") -> 58.876 | I129: =IFERROR(INDEX(Medidores!$B:$B,MATCH(B129,Medidores!$A:$A,0)),"") -> Estación celda 3 | J129: 2026-10-07 13:15
A130: 46302 | B130: 192.168.50.9 | C130: 0.35416667 | D130: 265463.25 | E130: 109277.94 | G130: =HOUR(C130)*60+MINUTE(C130) -> 510 | H130: =IF(AND(B130=B129,A130=A129,D130>0,N(D129)>0,G130>N(G129)),(D130-D129)/((G130-G129)/60),"") -> 52.248 | I130: =IFERROR(INDEX(Medidores!$B:$B,MATCH(B130,Medidores!$A:$A,0)),"") -> Estación celda 3 | J130: 2026-10-07 13:30
A131: 46302 | B131: 192.168.50.9 | C131: 0.36458333 | D131: 265475.44 | E131: 109284.37 | G131: =HOUR(C131)*60+MINUTE(C131) -> 525 | H131: =IF(AND(B131=B130,A131=A130,D131>0,N(D130)>0,G131>N(G130)),(D131-D130)/((G131-G130)/60),"") -> 48.752 | I131: =IFERROR(INDEX(Medidores!$B:$B,MATCH(B131,Medidores!$A:$A,0)),"") -> Estación celda 3 | J131: 2026-10-07 13:45
A132: 46302 | B132: 192.168.50.9 | C132: 0.375 | D132: 265490.94 | E132: 109293.48 | G132: =HOUR(C132)*60+MINUTE(C132) -> 540 | H132: =IF(AND(B132=B131,A132=A131,D132>0,N(D131)>0,G132>N(G131)),(D132-D131)/((G132-G131)/60),"") -> 62 | I132: =IFERROR(INDEX(Medidores!$B:$B,MATCH(B132,Medidores!$A:$A,0)),"") -> Estación celda 3 | J132: 2026-10-07 14:00
A133: 46302 | B133: 192.168.50.9 | C133: 0.38541667 | D133: 265503.62 | E133: 109300.38 | G133: =HOUR(C133)*60+MINUTE(C133) -> 555 | H133: =IF(AND(B133=B132,A133=A132,D133>0,N(D132)>0,G133>N(G132)),(D133-D132)/((G133-G132)/60),"") -> 50.748 | I133: =IFERROR(INDEX(Medidores!$B:$B,MATCH(B133,Medidores!$A:$A,0)),"") -> Estación celda 3 | J133: 2026-10-07 14:15
... A141: 46302 | B141: 192.168.50.9 | C141: 0.46875 | D141: 265604.28 | E141: 109352.02 | G141: =HOUR(C141)*60+MINUTE(C141) -> 675 | H141: =IF(AND(B141=B140,A141=A140,D141>0,N(D140)>0,G141>N(G140)),(D141-D140)/((G141-G140)/60),"") -> 43.624 | I141: =IFERROR(INDEX(Medidores!$B:$B,MATCH(B141,Medidores!$A:$A,0)),"") -> Estación celda 3 | J141: 2026-10-07 16:15
A142: 46302 | B142: 192.168.50.10 | C142: 0.27083333 | D142: 432776.56 | E142: 172677.56 | F142: 467890.78 | G142: =HOUR(C142)*60+MINUTE(C142) -> 390 | H142: =IF(AND(B142=B141,A142=A141,D142>0,N(D141)>0,G142>N(G141)),(D142-D141)/((G142-G141)/60),"") | I142: =IFERROR(INDEX(Medidores!$B:$B,MATCH(B142,Medidores!$A:$A,0)),"") -> Estación celda 2 | J142: 2026-10-07 11:30
A143: 46302 | B143: 192.168.50.10 | C143: 0.28125 | D143: 432787.97 | E143: 172682.16 | F143: 467903.03 | G143: =HOUR(C143)*60+MINUTE(C143) -> 405 | H143: =IF(AND(B143=B142,A143=A142,D143>0,N(D142)>0,G143>N(G142)),(D143-D142)/((G143-G142)/60),"") -> 45.624 | I143: =IFERROR(INDEX(Medidores!$B:$B,MATCH(B143,Medidores!$A:$A,0)),"") -> Estación celda 2 | J143: 2026-10-07 11:45
A144: 46302 | B144: 192.168.50.10 | C144: 0.29166667 | D144: 432800.47 | E144: 172687.3 | F144: 467916.56 | G144: =HOUR(C144)*60+MINUTE(C144) -> 420 | H144: =IF(AND(B144=B143,A144=A143,D144>0,N(D143)>0,G144>N(G143)),(D144-D143)/((G144-G143)/60),"") -> 50 | I144: =IFERROR(INDEX(Medidores!$B:$B,MATCH(B144,Medidores!$A:$A,0)),"") -> Estación celda 2 | J144: 2026-10-07 12:00
A145: 46302 | B145: 192.168.50.10 | C145: 0.30208333 | D145: 432819.72 | E145: 172695.19 | F145: 467937.38 | G145: =HOUR(C145)*60+MINUTE(C145) -> 435 | H145: =IF(AND(B145=B144,A145=A144,D145>0,N(D144)>0,G145>N(G144)),(D145-D144)/((G145-G144)/60),"") -> 77 | I145: =IFERROR(INDEX(Medidores!$B:$B,MATCH(B145,Medidores!$A:$A,0)),"") -> Estación celda 2 | J145: 2026-10-07 12:15
A146: 46302 | B146: 192.168.50.10 | C146: 0.3125 | D146: 432841.81 | E146: 172703.61 | F146: 467961.03 | G146: =HOUR(C146)*60+MINUTE(C146) -> 450 | H146: =IF(AND(B146=B145,A146=A145,D146>0,N(D145)>0,G146>N(G145)),(D146-D145)/((G146-G145)/60),"") -> 88.376 | I146: =IFERROR(INDEX(Medidores!$B:$B,MATCH(B146,Medidores!$A:$A,0)),"") -> Estación celda 2 | J146: 2026-10-07 12:30
A147: 46302 | B147: 192.168.50.10 | C147: 0.32291667 | D147: 432863.78 | E147: 172712.64 | F147: 467984.81 | G147: =HOUR(C147)*60+MINUTE(C147) -> 465 | H147: =IF(AND(B147=B146,A147=A146,D147>0,N(D146)>0,G147>N(G146)),(D147-D146)/((G147-G146)/60),"") -> 87.872 | I147: =IFERROR(INDEX(Medidores!$B:$B,MATCH(B147,Medidores!$A:$A,0)),"") -> Estación celda 2 | J147: 2026-10-07 12:45
A148: 46302 | B148: 192.168.50.10 | C148: 0.33333333 | D148: 432885.47 | E148: 172721.91 | F148: 468008.38 | G148: =HOUR(C148)*60+MINUTE(C148) -> 480 | H148: =IF(AND(B148=B147,A148=A147,D148>0,N(D147)>0,G148>N(G147)),(D148-D147)/((G148-G147)/60),"") -> 86.752 | I148: =IFERROR(INDEX(Medidores!$B:$B,MATCH(B148,Medidores!$A:$A,0)),"") -> Estación celda 2 | J148: 2026-10-07 13:00
A149: 46302 | B149: 192.168.50.10 | C149: 0.34375 | D149: 432907.59 | E149: 172731.12 | F149: 468032.31 | G149: =HOUR(C149)*60+MINUTE(C149) -> 495 | H149: =IF(AND(B149=B148,A149=A148,D149>0,N(D148)>0,G149>N(G148)),(D149-D148)/((G149-G148)/60),"") -> 88.5 | I149: =IFERROR(INDEX(Medidores!$B:$B,MATCH(B149,Medidores!$A:$A,0)),"") -> Estación celda 2 | J149: 2026-10-07 13:15
A150: 46302 | B150: 192.168.50.10 | C150: 0.35416667 | D150: 432929.78 | E150: 172740.34 | F150: 468056.38 | G150: =HOUR(C150)*60+MINUTE(C150) -> 510 | H150: =IF(AND(B150=B149,A150=A149,D150>0,N(D149)>0,G150>N(G149)),(D150-D149)/((G150-G149)/60),"") -> 88.748 | I150: =IFERROR(INDEX(Medidores!$B:$B,MATCH(B150,Medidores!$A:$A,0)),"") -> Estación celda 2 | J150: 2026-10-07 13:30
A151: 46302 | B151: 192.168.50.10 | C151: 0.36458333 | D151: 432951.62 | E151: 172749.41 | F151: 468080 | G151: =HOUR(C151)*60+MINUTE(C151) -> 525 | H151: =IF(AND(B151=B150,A151=A150,D151>0,N(D150)>0,G151>N(G150)),(D151-D150)/((G151-G150)/60),"") -> 87.376 | I151: =IFERROR(INDEX(Medidores!$B:$B,MATCH(B151,Medidores!$A:$A,0)),"") -> Estación celda 2 | J151: 2026-10-07 13:45
A152: 46302 | B152: 192.168.50.10 | C152: 0.375 | D152: 432974.28 | E152: 172758.5 | F152: 468104.41 | G152: =HOUR(C152)*60+MINUTE(C152) -> 540 | H152: =IF(AND(B152=B151,A152=A151,D152>0,N(D151)>0,G152>N(G151)),(D152-D151)/((G152-G151)/60),"") -> 90.624 | I152: =IFERROR(INDEX(Medidores!$B:$B,MATCH(B152,Medidores!$A:$A,0)),"") -> Estación celda 2 | J152: 2026-10-07 14:00
A153: 46302 | B153: 192.168.50.10 | C153: 0.38541667 | D153: 432996.38 | E153: 172767.48 | F153: 468128.28 | G153: =HOUR(C153)*60+MINUTE(C153) -> 555 | H153: =IF(AND(B153=B152,A153=A152,D153>0,N(D152)>0,G153>N(G152)),(D153-D152)/((G153-G152)/60),"") -> 88.376 | I153: =IFERROR(INDEX(Medidores!$B:$B,MATCH(B153,Medidores!$A:$A,0)),"") -> Estación celda 2 | J153: 2026-10-07 14:15
... A580: 46304 | B580: 192.168.50.11 | C580: 0.57291667 | D580: 331749.5 | E580: 173394.28 | F580: 375737.78 | G580: =HOUR(C580)*60+MINUTE(C580) -> 825 | H580: =IF(AND(B580=B579,A580=A579,D580>0,N(D579)>0,G580>N(G579)),(D580-D579)/((G580-G579)/60),"") -> 94.124 | I580: =IFERROR(INDEX(Medidores!$B:$B,MATCH(B580,Medidores!$A:$A,0)),"") -> Estación celda 1 | J580: 2026-10-09 18:45
...

Sheet Medidores
A1: IP | B1: Nombre de la línea | C1: Dentro de (IP) | D1: Reloj del medidor | F1: Puedes cambiar los nombres de la columna B; el tablero se actualiza solo.
A2: 192.168.50.3 | B2: L50 | C2: 192.168.50.8 | D2: Hora Colombia | F2: Dentro de: medidor que ya incluye este consumo. No se suma dos veces en los totales, salvo que ese medidor no tenga dato.
A3: 192.168.50.4 | B3: L21 | C3: 192.168.50.8 | D3: UTC (−5 h)
A4: 192.168.50.5 | B4: L14 | C4: 192.168.50.8 | D4: Hora Colombia
A5: 192.168.50.6 | B5: L20 | C5: 192.168.50.8 | D5: UTC (−5 h)
A6: 192.168.50.7 | B6: L16 | C6: 192.168.50.8 | D6: UTC (−5 h)
A7: 192.168.1.168 | B7: L22 | C7: 192.168.50.8 | D7: UTC (−5 h)
A8: 192.168.50.8 | B8: Estación planta | D8: UTC (−5 h)
A9: 192.168.50.9 | B9: Estación celda 3 | D9: UTC (−5 h)
A10: 192.168.50.10 | B10: Estación celda 2 | D10: UTC (−5 h)
A11: 192.168.50.11 | B11: Estación celda 1 | D11: UTC (−5 h)

Sheet Calc
A1: Minuto fin | B1: Inicio | C1: kW | E1: Hoja auxiliar para la gráfica de 15 minutos. No hace falta editarla.
A2: 15 | B2: 00:00 | C2: =IF(COUNTIFS(Datos!$B:$B,Tablero!$I$5,Datos!$A:$A,Tablero!$B$5,Datos!$G:$G,$A2,Datos!$H:$H,">=0")=0,"",SUMIFS(Datos!$H:$H,Datos!$B:$B,Tablero!$I$5,Datos!$A:$A,Tablero!$B$5,Datos!$G:$G,$A2))
A3: 30 | B3: 00:15 | C3: =IF(COUNTIFS(Datos!$B:$B,Tablero!$I$5,Datos!$A:$A,Tablero!$B$5,Datos!$G:$G,$A3,Datos!$H:$H,">=0")=0,"",SUMIFS(Datos!$H:$H,Datos!$B:$B,Tablero!$I$5,Datos!$A:$A,Tablero!$B$5,Datos!$G:$G,$A3))
A4: 45 | B4: 00:30 | C4: =IF(COUNTIFS(Datos!$B:$B,Tablero!$I$5,Datos!$A:$A,Tablero!$B$5,Datos!$G:$G,$A4,Datos!$H:$H,">=0")=0,"",SUMIFS(Datos!$H:$H,Datos!$B:$B,Tablero!$I$5,Datos!$A:$A,Tablero!$B$5,Datos!$G:$G,$A4))
A5: 60 | B5: 00:45 | C5: =IF(COUNTIFS(Datos!$B:$B,Tablero!$I$5,Datos!$A:$A,Tablero!$B$5,Datos!$G:$G,$A5,Datos!$H:$H,">=0")=0,"",SUMIFS(Datos!$H:$H,Datos!$B:$B,Tablero!$I$5,Datos!$A:$A,Tablero!$B$5,Datos!$G:$G,$A5))
A6: 75 | B6: 01:00 | C6: =IF(COUNTIFS(Datos!$B:$B,Tablero!$I$5,Datos!$A:$A,Tablero!$B$5,Datos!$G:$G,$A6,Datos!$H:$H,">=0")=0,"",SUMIFS(Datos!$H:$H,Datos!$B:$B,Tablero!$I$5,Datos!$A:$A,Tablero!$B$5,Datos!$G:$G,$A6))
A7: 90 | B7: 01:15 | C7: =IF(COUNTIFS(Datos!$B:$B,Tablero!$I$5,Datos!$A:$A,Tablero!$B$5,Datos!$G:$G,$A7,Datos!$H:$H,">=0")=0,"",SUMIFS(Datos!$H:$H,Datos!$B:$B,Tablero!$I$5,Datos!$A:$A,Tablero!$B$5,Datos!$G:$G,$A7))
A8: 105 | B8: 01:30 | C8: =IF(COUNTIFS(Datos!$B:$B,Tablero!$I$5,Datos!$A:$A,Tablero!$B$5,Datos!$G:$G,$A8,Datos!$H:$H,">=0")=0,"",SUMIFS(Datos!$H:$H,Datos!$B:$B,Tablero!$I$5,Datos!$A:$A,Tablero!$B$5,Datos!$G:$G,$A8))
A9: 120 | B9: 01:45 | C9: =IF(COUNTIFS(Datos!$B:$B,Tablero!$I$5,Datos!$A:$A,Tablero!$B$5,Datos!$G:$G,$A9,Datos!$H:$H,">=0")=0,"",SUMIFS(Datos!$H:$H,Datos!$B:$B,Tablero!$I$5,Datos!$A:$A,Tablero!$B$5,Datos!$G:$G,$A9))
A10: 135 | B10: 02:00 | C10: =IF(COUNTIFS(Datos!$B:$B,Tablero!$I$5,Datos!$A:$A,Tablero!$B$5,Datos!$G:$G,$A10,Datos!$H:$H,">=0")=0,"",SUMIFS(Datos!$H:$H,Datos!$B:$B,Tablero!$I$5,Datos!$A:$A,Tablero!$B$5,Datos!$G:$G,$A10))
A11: 150 | B11: 02:15 | C11: =IF(COUNTIFS(Datos!$B:$B,Tablero!$I$5,Datos!$A:$A,Tablero!$B$5,Datos!$G:$G,$A11,Datos!$H:$H,">=0")=0,"",SUMIFS(Datos!$H:$H,Datos!$B:$B,Tablero!$I$5,Datos!$A:$A,Tablero!$B$5,Datos!$G:$G,$A11))
A12: 165 | B12: 02:30 | C12: =IF(COUNTIFS(Datos!$B:$B,Tablero!$I$5,Datos!$A:$A,Tablero!$B$5,Datos!$G:$G,$A12,Datos!$H:$H,">=0")=0,"",SUMIFS(Datos!$H:$H,Datos!$B:$B,Tablero!$I$5,Datos!$A:$A,Tablero!$B$5,Datos!$G:$G,$A12))
A13: 180 | B13: 02:45 | C13: =IF(COUNTIFS(Datos!$B:$B,Tablero!$I$5,Datos!$A:$A,Tablero!$B$5,Datos!$G:$G,$A13,Datos!$H:$H,">=0")=0,"",SUMIFS(Datos!$H:$H,Datos!$B:$B,Tablero!$I$5,Datos!$A:$A,Tablero!$B$5,Datos!$G:$G,$A13))
... A97: 1440 | B97: 23:45 | C97: =IF(COUNTIFS(Datos!$B:$B,Tablero!$I$5,Datos!$A:$A,Tablero!$B$5,Datos!$G:$G,$A97,Datos!$H:$H,">=0")=0,"",SUMIFS(Datos!$H:$H,Datos!$B:$B,Tablero!$I$5,Datos!$A:$A,Tablero!$B$5,Datos!$G:$G,$A97))

Sheet Histórico
A1: Consumo diario por medidor (kWh en el periodo registrado)
A2: Fecha | B2: L50 | C2: L21 | D2: L14 | E2: L20 | F2: L16 | G2: L22 | H2: Estación planta | I2: Estación celda 3 | J2: Estación celda 2 | K2: Estación celda 1 | L2: Total
A3: 46302 | B3: =IF(COUNTIFS(Datos!$B:$B,"192.168.50.3",Datos!$A:$A,$A3,Datos!$D:$D,">0")<2,"",_xlfn.MAXIFS(Datos!$D:$D,Datos!$B:$B,"192.168.50.3",Datos!$A:$A,$A3,Datos!$D:$D,">0")-_xlfn.MINIFS(Datos!$D:$D,Datos!$B:$B,"192.168.50.3",Datos!$A:$A,$A3,Datos!$D:$D,">0")) -> 2.552 | C3: =IF(COUNTIFS(Datos!$B:$B,"192.168.50.4",Datos!$A:$A,$A3,Datos!$D:$D,">0")<2,"",_xlfn.MAXIFS(Datos!$D:$D,Datos!$B:$B,"192.168.50.4",Datos!$A:$A,$A3,Datos!$D:$D,">0")-_xlfn.MINIFS(Datos!$D:$D,Datos!$B:$B,"192.168.50.4",Datos!$A:$A,$A3,Datos!$D:$D,">0")) -> 2.949 | D3: =IF(COUNTIFS(Datos!$B:$B,"192.168.50.5",Datos!$A:$A,$A3,Datos!$D:$D,">0")<2,"",_xlfn.MAXIFS(Datos!$D:$D,Datos!$B:$B,"192.168.50.5",Datos!$A:$A,$A3,Datos!$D:$D,">0")-_xlfn.MINIFS(Datos!$D:$D,Datos!$B:$B,"192.168.50.5",Datos!$A:$A,$A3,Datos!$D:$D,">0")) -> 14.985 | E3: =IF(COUNTIFS(Datos!$B:$B,"192.168.50.6",Datos!$A:$A,$A3,Datos!$D:$D,">0")<2,"",_xlfn.MAXIFS(Datos!$D:$D,Datos!$B:$B,"192.168.50.6",Datos!$A:$A,$A3,Datos!$D:$D,">0")-_xlfn.MINIFS(Datos!$D:$D,Datos!$B:$B,"192.168.50.6",Datos!$A:$A,$A3,Datos!$D:$D,">0")) -> 7.61 | F3: =IF(COUNTIFS(Datos!$B:$B,"192.168.50.7",Datos!$A:$A,$A3,Datos!$D:$D,">0")<2,"",_xlfn.MAXIFS(Datos!$D:$D,Datos!$B:$B,"192.168.50.7",Datos!$A:$A,$A3,Datos!$D:$D,">0")-_xlfn.MINIFS(Datos!$D:$D,Datos!$B:$B,"192.168.50.7",Datos!$A:$A,$A3,Datos!$D:$D,">0")) -> 0.56 | G3: =IF(COUNTIFS(Datos!$B:$B,"192.168.1.168",Datos!$A:$A,$A3,Datos!$D:$D,">0")<2,"",_xlfn.MAXIFS(Datos!$D:$D,Datos!$B:$B,"192.168.1.168",Datos!$A:$A,$A3,Datos!$D:$D,">0")-_xlfn.MINIFS(Datos!$D:$D,Datos!$B:$B,"192.168.1.168",Datos!$A:$A,$A3,Datos!$D:$D,">0")) -> 26.354 | H3: =IF(COUNTIFS(Datos!$B:$B,"192.168.50.8",Datos!$A:$A,$A3,Datos!$D:$D,">0")<2,"",_xlfn.MAXIFS(Datos!$D:$D,Datos!$B:$B,"192.168.50.8",Datos!$A:$A,$A3,Datos!$D:$D,">0")-_xlfn.MINIFS(Datos!$D:$D,Datos!$B:$B,"192.168.50.8",Datos!$A:$A,$A3,Datos!$D:$D,">0")) -> 13.125 | I3: =IF(COUNTIFS(Datos!$B:$B,"192.168.50.9",Datos!$A:$A,$A3,Datos!$D:$D,">0")<2,"",_xlfn.MAXIFS(Datos!$D:$D,Datos!$B:$B,"192.168.50.9",Datos!$A:$A,$A3,Datos!$D:$D,">0")-_xlfn.MINIFS(Datos!$D:$D,Datos!$B:$B,"192.168.50.9",Datos!$A:$A,$A3,Datos!$D:$D,">0")) -> 235.5 | J3: =IF(COUNTIFS(Datos!$B:$B,"192.168.50.10",Datos!$A:$A,$A3,Datos!$D:$D,">0")<2,"",_xlfn.MAXIFS(Datos!$D:$D,Datos!$B:$B,"192.168.50.10",Datos!$A:$A,$A3,Datos!$D:$D,">0")-_xlfn.MINIFS(Datos!$D:$D,Datos!$B:$B,"192.168.50.10",Datos!$A:$A,$A3,Datos!$D:$D,">0")) -> 401.968 | K3: =IF(COUNTIFS(Datos!$B:$B,"192.168.50.11",Datos!$A:$A,$A3,Datos!$D:$D,">0")<2,"",_xlfn.MAXIFS(Datos!$D:$D,Datos!$B:$B,"192.168.50.11",Datos!$A:$A,$A3,Datos!$D:$D,">0")-_xlfn.MINIFS(Datos!$D:$D,Datos!$B:$B,"192.168.50.11",Datos!$A:$A,$A3,Datos!$D:$D,">0")) -> 233.25 | L3: =IF(COUNT(B3:K3)=0,"",IF(ISNUMBER(H3),0,N(B3))+IF(ISNUMBER(H3),0,N(C3))+IF(ISNUMBER(H3),0,N(D3))+IF(ISNUMBER(H3),0,N(E3))+IF(ISNUMBER(H3),0,N(F3))+IF(ISNUMBER(H3),0,N(G3))+N(H3)+N(I3)+N(J3)+N(K3)) -> 883.843
A4: 46303 | B4: =IF(COUNTIFS(Datos!$B:$B,"192.168.50.3",Datos!$A:$A,$A4,Datos!$D:$D,">0")<2,"",_xlfn.MAXIFS(Datos!$D:$D,Datos!$B:$B,"192.168.50.3",Datos!$A:$A,$A4,Datos!$D:$D,">0")-_xlfn.MINIFS(Datos!$D:$D,Datos!$B:$B,"192.168.50.3",Datos!$A:$A,$A4,Datos!$D:$D,">0")) -> 3.184 | C4: =IF(COUNTIFS(Datos!$B:$B,"192.168.50.4",Datos!$A:$A,$A4,Datos!$D:$D,">0")<2,"",_xlfn.MAXIFS(Datos!$D:$D,Datos!$B:$B,"192.168.50.4",Datos!$A:$A,$A4,Datos!$D:$D,">0")-_xlfn.MINIFS(Datos!$D:$D,Datos!$B:$B,"192.168.50.4",Datos!$A:$A,$A4,Datos!$D:$D,">0")) -> 5.105 | D4: =IF(COUNTIFS(Datos!$B:$B,"192.168.50.5",Datos!$A:$A,$A4,Datos!$D:$D,">0")<2,"",_xlfn.MAXIFS(Datos!$D:$D,Datos!$B:$B,"192.168.50.5",Datos!$A:$A,$A4,Datos!$D:$D,">0")-_xlfn.MINIFS(Datos!$D:$D,Datos!$B:$B,"192.168.50.5",Datos!$A:$A,$A4,Datos!$D:$D,">0")) -> 17.699 | E4: =IF(COUNTIFS(Datos!$B:$B,"192.168.50.6",Datos!$A:$A,$A4,Datos!$D:$D,">0")<2,"",_xlfn.MAXIFS(Datos!$D:$D,Datos!$B:$B,"192.168.50.6",Datos!$A:$A,$A4,Datos!$D:$D,">0")-_xlfn.MINIFS(Datos!$D:$D,Datos!$B:$B,"192.168.50.6",Datos!$A:$A,$A4,Datos!$D:$D,">0")) -> 16.243 | F4: =IF(COUNTIFS(Datos!$B:$B,"192.168.50.7",Datos!$A:$A,$A4,Datos!$D:$D,">0")<2,"",_xlfn.MAXIFS(Datos!$D:$D,Datos!$B:$B,"192.168.50.7",Datos!$A:$A,$A4,Datos!$D:$D,">0")-_xlfn.MINIFS(Datos!$D:$D,Datos!$B:$B,"192.168.50.7",Datos!$A:$A,$A4,Datos!$D:$D,">0")) -> 0.741 | G4: =IF(COUNTIFS(Datos!$B:$B,"192.168.1.168",Datos!$A:$A,$A4,Datos!$D:$D,">0")<2,"",_xlfn.MAXIFS(Datos!$D:$D,Datos!$B:$B,"192.168.1.168",Datos!$A:$A,$A4,Datos!$D:$D,">0")-_xlfn.MINIFS(Datos!$D:$D,Datos!$B:$B,"192.168.1.168",Datos!$A:$A,$A4,Datos!$D:$D,">0")) -> 29.536 | H4: =IF(COUNTIFS(Datos!$B:$B,"192.168.50.8",Datos!$A:$A,$A4,Datos!$D:$D,">0")<2,"",_xlfn.MAXIFS(Datos!$D:$D,Datos!$B:$B,"192.168.50.8",Datos!$A:$A,$A4,Datos!$D:$D,">0")-_xlfn.MINIFS(Datos!$D:$D,Datos!$B:$B,"192.168.50.8",Datos!$A:$A,$A4,Datos!$D:$D,">0")) -> 148.321 | I4: =IF(COUNTIFS(Datos!$B:$B,"192.168.50.9",Datos!$A:$A,$A4,Datos!$D:$D,">0")<2,"",_xlfn.MAXIFS(Datos!$D:$D,Datos!$B:$B,"192.168.50.9",Datos!$A:$A,$A4,Datos!$D:$D,">0")-_xlfn.MINIFS(Datos!$D:$D,Datos!$B:$B,"192.168.50.9",Datos!$A:$A,$A4,Datos!$D:$D,">0")) -> 334.25 | J4: =IF(COUNTIFS(Datos!$B:$B,"192.168.50.10",Datos!$A:$A,$A4,Datos!$D:$D,">0")<2,"",_xlfn.MAXIFS(Datos!$D:$D,Datos!$B:$B,"192.168.50.10",Datos!$A:$A,$A4,Datos!$D:$D,">0")-_xlfn.MINIFS(Datos!$D:$D,Datos!$B:$B,"192.168.50.10",Datos!$A:$A,$A4,Datos!$D:$D,">0")) -> 419.625 | K4: =IF(COUNTIFS(Datos!$B:$B,"192.168.50.11",Datos!$A:$A,$A4,Datos!$D:$D,">0")<2,"",_xlfn.MAXIFS(Datos!$D:$D,Datos!$B:$B,"192.168.50.11",Datos!$A:$A,$A4,Datos!$D:$D,">0")-_xlfn.MINIFS(Datos!$D:$D,Datos!$B:$B,"192.168.50.11",Datos!$A:$A,$A4,Datos!$D:$D,">0")) -> 381.313 | L4: =IF(COUNT(B4:K4)=0,"",IF(ISNUMBER(H4),0,N(B4))+IF(ISNUMBER(H4),0,N(C4))+IF(ISNUMBER(H4),0,N(D4))+IF(ISNUMBER(H4),0,N(E4))+IF(ISNUMBER(H4),0,N(F4))+IF(ISNUMBER(H4),0,N(G4))+N(H4)+N(I4)+N(J4)+N(K4)) -> 1283.509
A5: 46304 | B5: =IF(COUNTIFS(Datos!$B:$B,"192.168.50.3",Datos!$A:$A,$A5,Datos!$D:$D,">0")<2,"",_xlfn.MAXIFS(Datos!$D:$D,Datos!$B:$B,"192.168.50.3",Datos!$A:$A,$A5,Datos!$D:$D,">0")-_xlfn.MINIFS(Datos!$D:$D,Datos!$B:$B,"192.168.50.3",Datos!$A:$A,$A5,Datos!$D:$D,">0")) -> 2.965 | C5: =IF(COUNTIFS(Datos!$B:$B,"192.168.50.4",Datos!$A:$A,$A5,Datos!$D:$D,">0")<2,"",_xlfn.MAXIFS(Datos!$D:$D,Datos!$B:$B,"192.168.50.4",Datos!$A:$A,$A5,Datos!$D:$D,">0")-_xlfn.MINIFS(Datos!$D:$D,Datos!$B:$B,"192.168.50.4",Datos!$A:$A,$A5,Datos!$D:$D,">0")) -> 2.958 | D5: =IF(COUNTIFS(Datos!$B:$B,"192.168.50.5",Datos!$A:$A,$A5,Datos!$D:$D,">0")<2,"",_xlfn.MAXIFS(Datos!$D:$D,Datos!$B:$B,"192.168.50.5",Datos!$A:$A,$A5,Datos!$D:$D,">0")-_xlfn.MINIFS(Datos!$D:$D,Datos!$B:$B,"192.168.50.5",Datos!$A:$A,$A5,Datos!$D:$D,">0")) -> 17.416 | E5: =IF(COUNTIFS(Datos!$B:$B,"192.168.50.6",Datos!$A:$A,$A5,Datos!$D:$D,">0")<2,"",_xlfn.MAXIFS(Datos!$D:$D,Datos!$B:$B,"192.168.50.6",Datos!$A:$A,$A5,Datos!$D:$D,">0")-_xlfn.MINIFS(Datos!$D:$D,Datos!$B:$B,"192.168.50.6",Datos!$A:$A,$A5,Datos!$D:$D,">0")) -> 16.199 | F5: =IF(COUNTIFS(Datos!$B:$B,"192.168.50.7",Datos!$A:$A,$A5,Datos!$D:$D,">0")<2,"",_xlfn.MAXIFS(Datos!$D:$D,Datos!$B:$B,"192.168.50.7",Datos!$A:$A,$A5,Datos!$D:$D,">0")-_xlfn.MINIFS(Datos!$D:$D,Datos!$B:$B,"192.168.50.7",Datos!$A:$A,$A5,Datos!$D:$D,">0")) -> 0.745 | G5: =IF(COUNTIFS(Datos!$B:$B,"192.168.1.168",Datos!$A:$A,$A5,Datos!$D:$D,">0")<2,"",_xlfn.MAXIFS(Datos!$D:$D,Datos!$B:$B,"192.168.1.168",Datos!$A:$A,$A5,Datos!$D:$D,">0")-_xlfn.MINIFS(Datos!$D:$D,Datos!$B:$B,"192.168.1.168",Datos!$A:$A,$A5,Datos!$D:$D,">0")) -> 27.758 | H5: =IF(COUNTIFS(Datos!$B:$B,"192.168.50.8",Datos!$A:$A,$A5,Datos!$D:$D,">0")<2,"",_xlfn.MAXIFS(Datos!$D:$D,Datos!$B:$B,"192.168.50.8",Datos!$A:$A,$A5,Datos!$D:$D,">0")-_xlfn.MINIFS(Datos!$D:$D,Datos!$B:$B,"192.168.50.8",Datos!$A:$A,$A5,Datos!$D:$D,">0")) -> 127.946 | I5: =IF(COUNTIFS(Datos!$B:$B,"192.168.50.9",Datos!$A:$A,$A5,Datos!$D:$D,">0")<2,"",_xlfn.MAXIFS(Datos!$D:$D,Datos!$B:$B,"192.168.50.9",Datos!$A:$A,$A5,Datos!$D:$D,">0")-_xlfn.MINIFS(Datos!$D:$D,Datos!$B:$B,"192.168.50.9",Datos!$A:$A,$A5,Datos!$D:$D,">0")) -> 341.219 | J5: =IF(COUNTIFS(Datos!$B:$B,"192.168.50.10",Datos!$A:$A,$A5,Datos!$D:$D,">0")<2,"",_xlfn.MAXIFS(Datos!$D:$D,Datos!$B:$B,"192.168.50.10",Datos!$A:$A,$A5,Datos!$D:$D,">0")-_xlfn.MINIFS(Datos!$D:$D,Datos!$B:$B,"192.168.50.10",Datos!$A:$A,$A5,Datos!$D:$D,">0")) -> 427.343 | K5: =IF(COUNTIFS(Datos!$B:$B,"192.168.50.11",Datos!$A:$A,$A5,Datos!$D:$D,">0")<2,"",_xlfn.MAXIFS(Datos!$D:$D,Datos!$B:$B,"192.168.50.11",Datos!$A:$A,$A5,Datos!$D:$D,">0")-_xlfn.MINIFS(Datos!$D:$D,Datos!$B:$B,"192.168.50.11",Datos!$A:$A,$A5,Datos!$D:$D,">0")) -> 430.219 | L5: =IF(COUNT(B5:K5)=0,"",IF(ISNUMBER(H5),0,N(B5))+IF(ISNUMBER(H5),0,N(C5))+IF(ISNUMBER(H5),0,N(D5))+IF(ISNUMBER(H5),0,N(E5))+IF(ISNUMBER(H5),0,N(F5))+IF(ISNUMBER(H5),0,N(G5))+N(H5)+N(I5)+N(J5)+N(K5)) -> 1326.727
A7: Consumo de 24 h al corte (kWh) · hora de corte en Tablero!D5
A8: Fecha | B8: L50 | C8: L21 | D8: L14 | E8: L20 | F8: L16 | G8: L22 | H8: Estación planta | I8: Estación celda 3 | J8: Estación celda 2 | K8: Estación celda 1 | L8: Total | M8: EMCALI | N8: Diferencia | O8: Diferencia %
